Workbook

Sheet CONTROL INBOUND
H1: KIOSCO | I1: =+SUMIFS(J6:J27,$C$6:$C$27,"KIOSCO") -> 1.5416667 | J1: =+I1+I2 -> 3.0416667 | K1: =+Adherencia_In!B10 -> Incompleto | L1: KIOSCO | M1: =+SUMIFS(N6:N27,$C$6:$C$27,"KIOSCO") -> 3.7708333 | N1: =+M1+M2 -> 7.1458333 | O1: =+Adherencia_In!C10 -> Completo | P1: KIOSCO | Q1: =+SUMIFS(R6:R27,$C$6:$C$27,"KIOSCO") -> 3.6666667 | R1: =+Q1+Q2 -> 6.875 | S1: =+Adherencia_In!D10 -> Completo | T1: KIOSCO | U1: =+SUMIFS(V6:V27,$C$6:$C$27,"KIOSCO") -> 3.2291667 | V1: =+U1+U2 -> 6.4375 | W1: =+Adherencia_In!E10 -> Completo | X1: KIOSCO | Y1: =+SUMIFS(Z6:Z27,$C$6:$C$27,"KIOSCO") -> 3.375 | Z1: =+Y1+Y2 -> 6.5833333 | AA1: =+Adherencia_In!F10 -> Completo | AB1: KIOSCO | AC1: =+SUMIFS(AD6:AD27,$C$6:$C$27,"KIOSCO") -> 3.4791667 | AD1: =+AC1+AC2 -> 6.7708333 | AE1: =+Adherencia_In!G10 -> Completo | AF1: KIOSCO | AG1: =+SUMIFS(AH6:AH27,$C$6:$C$27,"KIOSCO") -> 2.7916667 | AH1: =+AG1+AG2 -> 4.5833333 | AI1: =+Adherencia_In!H10 -> Incompleto | AJ1: KIOSCO | AK1: =+SUMIFS(AL6:AL27,$C$6:$C$27,"KIOSCO") -> 1.5833333 | AL1: =+AK1+AK2 -> 3.5 | AM1: =+Adherencia_In!I10 -> Incompleto | AN1: KIOSCO | AO1: =+SUMIFS(AP6:AP27,$C$6:$C$27,"KIOSCO") -> 0 | AP1: =+AO1+AO2 -> 0 | AQ1: =+Adherencia_In!J10 -> Incompleto | AR1: KIOSCO | AS1: =+SUMIFS(AT6:AT27,$C$6:$C$27,"KIOSCO") -> 0 | AT1: =+AS1+AS2 -> 0 | AU1: =+Adherencia_In!K10 -> Incompleto | AV1: KIOSCO | AW1: =+SUMIFS(AX6:AX27,$C$6:$C$27,"KIOSCO") -> 0 | AX1: =+AW1+AW2 -> 0 | AY1: =+Adherencia_In!L10 -> Incompleto | AZ1: KIOSCO | BA1: =+SUMIFS(BB6:BB27,$C$6:$C$27,"KIOSCO") -> 0 | BB1: =+BA1+BA2 -> 0 | BC1: =+Adherencia_In!M10 -> Incompleto | BD1: KIOSCO | BE1: =+SUMIFS(BF6:BF27,$C$6:$C$27,"KIOSCO") -> 0 | BF1: =+BE1+BE2 -> 0 | BG1: =+Adherencia_In!N10 -> Incompleto | BH1: KIOSCO | BI1: =+SUMIFS(BJ6:BJ27,$C$6:$C$27,"KIOSCO") -> 0 | BJ1: =+BI1+BI2 -> 0 | BK1: =+Adherencia_In!O10 -> Incompleto | BL1: KIOSCO | BM1: =+SUMIFS(BN6:BN27,$C$6:$C$27,"KIOSCO") -> 0 | BN1: =+BM1+BM2 -> 0 | BO1: =+Adherencia_In!P10 -> Incompleto | BP1: KIOSCO | BQ1: =+SUMIFS(BR6:BR27,$C$6:$C$27,"KIOSCO") -> 0 | BR1: =+BQ1+BQ2 -> 0 | BS1: =+Adherencia_In!Q10 -> Incompleto | BT1: KIOSCO | BU1: =+SUMIFS(BV6:BV27,$C$6:$C$27,"KIOSCO") -> 0 | BV1: =+BU1+BU2 -> 0 | BW1: =+Adherencia_In!R10 -> Incompleto | BX1: KIOSCO | BY1: =+SUMIFS(BZ6:BZ27,$C$6:$C$27,"KIOSCO") -> 0 | BZ1: =+BY1+BY2 -> 0 | CA1: =+Adherencia_In!S10 -> Incompleto | CB1: KIOSCO | CC1: =+SUMIFS(CD6:CD27,$C$6:$C$27,"KIOSCO") -> 0 | CD1: =+CC1+CC2 -> 0 | CE1: =+Adherencia_In!T10 -> Incompleto | CF1: KIOSCO | CG1: =+SUMIFS(CH6:CH27,$C$6:$C$27,"KIOSCO") -> 0 | CH1: =+CG1+CG2 -> 0 | CI1: =+Adherencia_In!U10 -> Incompleto | CJ1: KIOSCO | CK1: =+SUMIFS(CL6:CL27,$C$6:$C$27,"KIOSCO") -> 0 | CL1: =+CK1+CK2 -> 0 | CM1: =+Adherencia_In!V10 -> Incompleto | CN1: KIOSCO | CO1: =+SUMIFS(CP6:CP27,$C$6:$C$27,"KIOSCO") -> 0 | CP1: =+CO1+CO2 -> 0 | CQ1: =+Adherencia_In!W10 -> Incompleto | CR1: KIOSCO | CS1: =+SUMIFS(CT6:CT27,$C$6:$C$27,"KIOSCO") -> 0 | CT1: =+CS1+CS2 -> 0 | CU1: =+Adherencia_In!X10 -> Incompleto | CV1: KIOSCO | CW1: =+SUMIFS(CX6:CX27,$C$6:$C$27,"KIOSCO") -> 0 | CX1: =+CW1+CW2 -> 0 | CY1: =+Adherencia_In!Y10 -> Incompleto | CZ1: KIOSCO | DA1: =+SUMIFS(DB6:DB27,$C$6:$C$27,"KIOSCO") -> 0 | DB1: =+DA1+DA2 -> 0 | DC1: =+Adherencia_In!Z10 -> Incompleto | DD1: KIOSCO | DE1: =+SUMIFS(DF6:DF27,$C$6:$C$27,"KIOSCO") -> 0 | DF1: =+DE1+DE2 -> 0 | DG1: =+Adherencia_In!AA10 -> Incompleto | DH1: KIOSCO | DI1: =+SUMIFS(DJ6:DJ27,$C$6:$C$27,"KIOSCO") -> 0 | DJ1: =+DI1+DI2 -> 0 | DK1: =+Adherencia_In!AB10 -> Incompleto | DP1: KIOSCO | DQ1: =+SUMIFS(DZ6:DZ27,$C$6:$C$27,"KIOSCO") -> 0 | DR1: =+DQ1+DQ2 -> 0 | DS1: =+Adherencia_In!AC10 -> Incompleto
H2: VIDEO LLAMADA | I2: =+SUMIFS(J6:J27,$C$6:$C$27,"VIDEO LLAMADA") -> 1.5 | L2: VIDEO LLAMADA | M2: =+SUMIFS(N6:N27,$C$6:$C$27,"VIDEO LLAMADA") -> 3.375 | P2: VIDEO LLAMADA | Q2: =+SUMIFS(R6:R27,$C$6:$C$27,"VIDEO LLAMADA") -> 3.2083333 | T2: VIDEO LLAMADA | U2: =+SUMIFS(V6:V27,$C$6:$C$27,"VIDEO LLAMADA") -> 3.2083333 | X2: VIDEO LLAMADA | Y2: =+SUMIFS(Z6:Z27,$C$6:$C$27,"VIDEO LLAMADA") -> 3.2083333 | AB2: VIDEO LLAMADA | AC2: =+SUMIFS(AD6:AD27,$C$6:$C$27,"VIDEO LLAMADA") -> 3.2916667 | AF2: VIDEO LLAMADA | AG2: =+SUMIFS(AH6:AH27,$C$6:$C$27,"VIDEO LLAMADA") -> 1.7916667 | AJ2: VIDEO LLAMADA | AK2: =+SUMIFS(AL6:AL27,$C$6:$C$27,"VIDEO LLAMADA") -> 1.9166667 | AN2: VIDEO LLAMADA | AO2: =+SUMIFS(AP6:AP27,$C$6:$C$27,"VIDEO LLAMADA") -> 0 | AR2: VIDEO LLAMADA | AS2: =+SUMIFS(AT6:AT27,$C$6:$C$27,"VIDEO LLAMADA") -> 0 | AT2: =+Adherencia_In!K5 -> 97:00:00 | AV2: VIDEO LLAMADA | AW2: =+SUMIFS(AX6:AX27,$C$6:$C$27,"VIDEO LLAMADA") -> 0 | AZ2: VIDEO LLAMADA | BA2: =+SUMIFS(BB6:BB27,$C$6:$C$27,"VIDEO LLAMADA") -> 0 | BD2: VIDEO LLAMADA | BE2: =+SUMIFS(BF6:BF27,$C$6:$C$27,"VIDEO LLAMADA") -> 0 | BH2: VIDEO LLAMADA | BI2: =+SUMIFS(BJ6:BJ27,$C$6:$C$27,"VIDEO LLAMADA") -> 0 | BL2: VIDEO LLAMADA | BM2: =+SUMIFS(BN6:BN27,$C$6:$C$27,"VIDEO LLAMADA") -> 0 | BP2: VIDEO LLAMADA | BQ2: =+SUMIFS(BR6:BR27,$C$6:$C$27,"VIDEO LLAMADA") -> 0 | BT2: VIDEO LLAMADA | BU2: =+SUMIFS(BV6:BV27,$C$6:$C$27,"VIDEO LLAMADA") -> 0 | BX2: VIDEO LLAMADA | BY2: =+SUMIFS(BZ6:BZ27,$C$6:$C$27,"VIDEO LLAMADA") -> 0 | CB2: VIDEO LLAMADA | CC2: =+SUMIFS(CD6:CD27,$C$6:$C$27,"VIDEO LLAMADA") -> 0 | CF2: VIDEO LLAMADA | CG2: =+SUMIFS(CH6:CH27,$C$6:$C$27,"VIDEO LLAMADA") -> 0 | CJ2: VIDEO LLAMADA | CK2: =+SUMIFS(CL6:CL27,$C$6:$C$27,"VIDEO LLAMADA") -> 0 | CN2: VIDEO LLAMADA | CO2: =+SUMIFS(CP6:CP27,$C$6:$C$27,"VIDEO LLAMADA") -> 0 | CR2: VIDEO LLAMADA | CS2: =+SUMIFS(CT6:CT27,$C$6:$C$27,"VIDEO LLAMADA") -> 0 | CV2: VIDEO LLAMADA | CW2: =+SUMIFS(CX6:CX27,$C$6:$C$27,"VIDEO LLAMADA") -> 0 | CZ2: VIDEO LLAMADA | DA2: =+SUMIFS(DB6:DB27,$C$6:$C$27,"VIDEO LLAMADA") -> 0 | DD2: VIDEO LLAMADA | DE2: =+SUMIFS(DF6:DF27,$C$6:$C$27,"VIDEO LLAMADA") -> 0 | DH2: VIDEO LLAMADA | DI2: =+SUMIFS(DJ6:DJ27,$C$6:$C$27,"VIDEO LLAMADA") -> 0 | DP2: VIDEO LLAMADA | DQ2: =+SUMIFS(DZ6:DZ27,$C$6:$C$27,"VIDEO LLAMADA") -> 0
H3: =+H4 -> 46082 | L3: =+L4 -> 46083 | P3: =+P4 -> 46084 | T3: =+T4 -> 46085 | X3: =+X4 -> 46086 | AB3: =+AB4 -> 46087 | AF3: =+AF4 -> 46088 | AJ3: =+AJ4 -> 46089 | AN3: =+AN4 -> 46090 | AR3: =+AR4 -> 46091 | AV3: =+AV4 -> 46092 | AZ3: =+AZ4 -> 46093 | BD3: =+BD4 -> 46094 | BH3: =+BH4 -> 46095 | BL3: =+BL4 -> 46096 | BP3: =+BP4 -> 46097 | BT3: =+BT4 -> 46098 | BX3: =+BX4 -> 46099 | CB3: =+CB4 -> 46100 | CF3: =+CF4 -> 46101 | CJ3: =+CJ4 -> 46102 | CN3: =+CN4 -> 46103 | CR3: =+CR4 -> 46104 | CV3: =+CV4 -> 46105 | CZ3: =+CZ4 -> 46106 | DD3: =+DD4 -> 46107 | DH3: =+DH4 -> 46108 | DL3: =+DL4 -> 46109 | DP3: =+DP4 -> 46110 | DT3: =+DT4 -> 46111 | DX3: =+DX4 -> 46112 | ED3: NO CUMPLE | EE3: CUMPLE | EF3: 7.125 | EH3: Kiosco | EI3: =482/171 -> 2.8187135
H4: 46082 | L4: 46083 | P4: 46084 | T4: 46085 | X4: 46086 | AB4: 46087 | AF4: 46088 | AJ4: 46089 | AN4: 46090 | AR4: 46091 | AV4: 46092 | AZ4: 46093 | BD4: 46094 | BH4: 46095 | BL4: 46096 | BP4: 46097 | BT4: 46098 | BX4: 46099 | CB4: 46100 | CF4: 46101 | CJ4: 46102 | CN4: 46103 | CR4: 46104 | CV4: 46105 | CZ4: 46106 | DD4: 46107 | DH4: 46108 | DL4: 46109 | DP4: 46110 | DT4: 46111 | DX4: 46112 | EF4: 7.125 | EH4: Video | EI4: =482/171 -> 2.8187135
A5: NOMBRE | B5: CEDULA | C5: CAMPAÑA | D5: USUARIO CIC | E5: CORREO | F5: CARGO | G5: MODALIDAD | H5: CAMPAÑA | I5: HORARIO | J5: N° HORAS TRABAJADAS | K5: NOMENCLATURA | L5: CAMPAÑA | M5: HORARIO | N5: N° HORAS TRABAJADAS | O5: NOMENCLATURA | P5: CAMPAÑA | Q5: HORARIO | R5: N° HORAS TRABAJADAS | S5: NOMENCLATURA | T5: CAMPAÑA | U5: HORARIO | V5: N° HORAS TRABAJADAS | W5: NOMENCLATURA | X5: CAMPAÑA | Y5: HORARIO | Z5: N° HORAS TRABAJADAS | AA5: NOMENCLATURA | AB5: CAMPAÑA | AC5: HORARIO | AD5: N° HORAS TRABAJADAS | AE5: NOMENCLATURA | AF5: CAMPAÑA | AG5: HORARIO | AH5: N° HORAS TRABAJADAS | AI5: NOMENCLATURA | AJ5: CAMPAÑA | AK5: HORARIO | AL5: N° HORAS TRABAJADAS | AM5: NOMENCLATURA | AN5: CAMPAÑA | AO5: HORARIO | AP5: N° HORAS TRABAJADAS | AQ5: NOMENCLATURA | AR5: CAMPAÑA | AS5: HORARIO | AT5: N° HORAS TRABAJADAS | AU5: NOMENCLATURA | AV5: CAMPAÑA | AW5: HORARIO | AX5: N° HORAS TRABAJADAS | AY5: NOMENCLATURA | AZ5: CAMPAÑA | BA5: HORARIO | BB5: N° HORAS TRABAJADAS | BC5: NOMENCLATURA | BD5: CAMPAÑA | BE5: HORARIO | BF5: N° HORAS TRABAJADAS | BG5: NOMENCLATURA | BH5: CAMPAÑA | BI5: HORARIO | BJ5: N° HORAS TRABAJADAS | BK5: NOMENCLATURA | BL5: CAMPAÑA | BM5: HORARIO | BN5: N° HORAS TRABAJADAS | BO5: NOMENCLATURA | BP5: CAMPAÑA | BQ5: HORARIO | BR5: N° HORAS TRABAJADAS | BS5: NOMENCLATURA | BT5: CAMPAÑA | BU5: HORARIO | BV5: N° HORAS TRABAJADAS | BW5: NOMENCLATURA | BX5: CAMPAÑA | BY5: HORARIO | BZ5: N° HORAS TRABAJADAS | CA5: NOMENCLATURA | CB5: CAMPAÑA | CC5: HORARIO | CD5: N° HORAS TRABAJADAS | CE5: NOMENCLATURA | CF5: CAMPAÑA | CG5: HORARIO | CH5: N° HORAS TRABAJADAS | CI5: NOMENCLATURA | CJ5: CAMPAÑA | CK5: HORARIO | CL5: N° HORAS TRABAJADAS | CM5: NOMENCLATURA | CN5: CAMPAÑA | CO5: HORARIO | CP5: N° HORAS TRABAJADAS | CQ5: NOMENCLATURA | CR5: CAMPAÑA | CS5: HORARIO | CT5: N° HORAS TRABAJADAS | CU5: NOMENCLATURA | CV5: CAMPAÑA | CW5: HORARIO | CX5: N° HORAS TRABAJADAS | CY5: NOMENCLATURA | CZ5: CAMPAÑA | DA5: HORARIO | DB5: N° HORAS TRABAJADAS | DC5: NOMENCLATURA | DD5: CAMPAÑA | DE5: HORARIO | DF5: N° HORAS TRABAJADAS | DG5: NOMENCLATURA | DH5: CAMPAÑA | DI5: HORARIO | DJ5: N° HORAS TRABAJADAS | DK5: NOMENCLATURA | DL5: CAMPAÑA | DM5: HORARIO | DN5: N° HORAS TRABAJADAS | DO5: NOMENCLATURA | DP5: CAMPAÑA | DQ5: HORARIO | DR5: N° HORAS TRABAJADAS | DS5: NOMENCLATURA | DT5: CAMPAÑA | DU5: HORARIO | DV5: N° HORAS TRABAJADAS | DW5: NOMENCLATURA | DX5: CAMPAÑA | DY5: HORARIO | DZ5: N° HORAS TRABAJADAS | EA5: NOMENCLATURA | EB5: HORAS TOTALES A LA FECHA | EC5: ATRASOS | ED5: FALTAS INJUSTIFICADAS | EE5: VACACIONES | EF5: CUMPLIMIENTO | EG5: META | EH5: FALTAN | EI5: $$ Dolars | EJ5: ACTUAL
A6: HERRERA RIOS JOSUE SEBASTIAN | B6: 1804744736 | C6: KIOSCO | F6: AGENTE | G6: PRESENCIAL | H6: KIOSCO | I6: 0 | J6: 0 | K6: 0 | L6: KIOSCO | M6: 10:00 - 17:00 | N6: 0.27083333 | O6: A | P6: KIOSCO | Q6: 10:00 - 20:00 | R6: 0.375 | S6: A | T6: KIOSCO | U6: 11:00 - 20:00 | V6: 0.33333333 | W6: A | X6: KIOSCO | Y6: 10:00 - 17:00 | Z6: 0.27083333 | AA6: A | AB6: KIOSCO | AC6: 11:00 - 17:00 | AD6: 0.25 | AE6: A | AF6: KIOSCO | AG6: 10:00 - 17:00 | AH6: 0.27083333 | AI6: A | AJ6: KIOSCO | AK6: 10:00 - 17:00 | AL6: 0.25 | AM6: AT | AN6: KIOSCO | AR6: KIOSCO | AV6: KIOSCO | AZ6: KIOSCO | BD6: KIOSCO | BH6: KIOSCO | BL6: KIOSCO | BP6: KIOSCO | BT6: KIOSCO | BX6: KIOSCO | CB6: KIOSCO | CF6: KIOSCO | CJ6: KIOSCO | CN6: KIOSCO | CR6: KIOSCO | CV6: KIOSCO | CZ6: KIOSCO | DD6: KIOSCO | DH6: KIOSCO | DL6: KIOSCO | DP6: KIOSCO | DT6: KIOSCO | DX6: KIOSCO | EB6: =+SUM(J6,N6,R6,V6,Z6,AD6,AH6,AL6,AP6,AT6,AX6,BB6,BF6,BJ6,BN6,BR6,BV6,BZ6,CD6,CH6,CL6,CP6,CT6,CX6,DB6,DF6,DJ6,DV6,DN6,DR6,DZ6) -> 2.0208333 | EC6: =COUNTIF(H6:EA6,"AT") -> 1 | ED6: =SUM(COUNTIF(K6,"FI"), COUNTIF(O6,"FI"), COUNTIF(S6,"FI"), COUNTIF(W6,"FI"), COUNTIF(AA6,"FI"), COUNTIF(AE6,"FI"), COUNTIF(AI6,"FI"), COUNTIF(AM6,"FI"), COUNTIF(AQ6,"FI"), COUNTIF(AU6,"FI"), COUNTIF(AY6,"FI"), COUNTIF(BC6,"FI"), COUNTIF(BG6,"FI"), COUNTIF(BK6,"FI"), COUNTIF(BO6,"FI"), COUNTIF(BS6,"FI"), COUNTIF(BW6,"FI"), COUNTIF(CA6,"FI"), COUNTIF(CE6,"FI"), COUNTIF(CI6,"FI"), COUNTIF(CM6,"FI"), COUNTIF(CQ6,"FI"), COUNTIF(CU6,"FI"), COUNTIF(CY6,"FI"), COUNTIF(DC6,"FI"), COUNTIF(DG6,"FI"), COUNTIF(DK6,"FI"), COUNTIF(EA6,"FI")) -> 0 | EE6: =SUM(COUNTIF(K6,"V"), COUNTIF(O6,"V"), COUNTIF(S6,"V"), COUNTIF(W6,"V"), COUNTIF(AA6,"V"), COUNTIF(AE6,"V"), COUNTIF(AI6,"V"), COUNTIF(AM6,"V"), COUNTIF(AQ6,"V"), COUNTIF(AU6,"V"), COUNTIF(AY6,"V"), COUNTIF(BC6,"V"), COUNTIF(BG6,"V"), COUNTIF(BK6,"V"), COUNTIF(BO6,"V"), COUNTIF(BS6,"V"), COUNTIF(BW6,"V"), COUNTIF(CA6,"V"), COUNTIF(CE6,"V"), COUNTIF(CI6,"V"), COUNTIF(CM6,"V"), COUNTIF(CQ6,"V"), COUNTIF(CU6,"V"), COUNTIF(CY6,"V"), COUNTIF(DC6,"V"), COUNTIF(DG6,"V"), COUNTIF(DK6,"V"), COUNTIF(EA6,"V")) -> 0 | EF6: =+EB6/$EF$3 -> 0.28362573 | EG6: =+$EF$3 -> 7.125 | EH6: =+$EF$3-EB6 -> 5.1041667 | EI6: =+EB6*$EI$3 -> 5.6961501 | EJ6: =+EB6+$EG$3 -> 2.0208333
A7: ARMAS MEJIA JUDITH MARCELA | B7: 1717668501 | C7: KIOSCO | F7: AGENTE | G7: PRESENCIAL | H7: KIOSCO | I7: 10:00 - 20:00 | J7: 0.375 | K7: A | L7: KIOSCO | M7: 10:00 - 17:00 | N7: 0.27083333 | O7: A | P7: KIOSCO | Q7: 10:00 - 17:00 | R7: 0.27083333 | S7: A | T7: KIOSCO | U7: 10:00 - 17:00 | V7: 0.25 | W7: A | X7: KIOSCO | Y7: 10:00 - 17:00 | Z7: 0.27083333 | AA7: A | AB7: KIOSCO | AC7: 10:00 - 17:00 | AD7: 0.27083333 | AE7: A | AF7: KIOSCO | AG7: 10:00 - 17:00 | AH7: 0.27083333 | AI7: A | AJ7: KIOSCO | AK7: 0 | AL7: 0 | AM7: 0 | AN7: KIOSCO | AR7: KIOSCO | AV7: KIOSCO | AZ7: KIOSCO | BD7: KIOSCO | BH7: KIOSCO | BL7: KIOSCO | BP7: KIOSCO | BT7: KIOSCO | BX7: KIOSCO | CB7: KIOSCO | CF7: KIOSCO | CJ7: KIOSCO | CN7: KIOSCO | CR7: KIOSCO | CV7: KIOSCO | CZ7: KIOSCO | DD7: KIOSCO | DH7: KIOSCO | DL7: KIOSCO | DP7: KIOSCO | DT7: KIOSCO | DX7: KIOSCO | EB7: =+SUM(J7,N7,R7,V7,Z7,AD7,AH7,AL7,AP7,AT7,AX7,BB7,BF7,BJ7,BN7,BR7,BV7,BZ7,CD7,CH7,CL7,CP7,CT7,CX7,DB7,DF7,DJ7,DV7,DN7,DR7,DZ7) -> 1.9791667 | EC7: =COUNTIF(H7:EA7,"AT") -> 0 | ED7: =SUM(COUNTIF(K7,"FI"), COUNTIF(O7,"FI"), COUNTIF(S7,"FI"), COUNTIF(W7,"FI"), COUNTIF(AA7,"FI"), COUNTIF(AE7,"FI"), COUNTIF(AI7,"FI"), COUNTIF(AM7,"FI"), COUNTIF(AQ7,"FI"), COUNTIF(AU7,"FI"), COUNTIF(AY7,"FI"), COUNTIF(BC7,"FI"), COUNTIF(BG7,"FI"), COUNTIF(BK7,"FI"), COUNTIF(BO7,"FI"), COUNTIF(BS7,"FI"), COUNTIF(BW7,"FI"), COUNTIF(CA7,"FI"), COUNTIF(CE7,"FI"), COUNTIF(CI7,"FI"), COUNTIF(CM7,"FI"), COUNTIF(CQ7,"FI"), COUNTIF(CU7,"FI"), COUNTIF(CY7,"FI"), COUNTIF(DC7,"FI"), COUNTIF(DG7,"FI"), COUNTIF(DK7,"FI"), COUNTIF(EA7,"FI")) -> 0 | EE7: =SUM(COUNTIF(K7,"V"), COUNTIF(O7,"V"), COUNTIF(S7,"V"), COUNTIF(W7,"V"), COUNTIF(AA7,"V"), COUNTIF(AE7,"V"), COUNTIF(AI7,"V"), COUNTIF(AM7,"V"), COUNTIF(AQ7,"V"), COUNTIF(AU7,"V"), COUNTIF(AY7,"V"), COUNTIF(BC7,"V"), COUNTIF(BG7,"V"), COUNTIF(BK7,"V"), COUNTIF(BO7,"V"), COUNTIF(BS7,"V"), COUNTIF(BW7,"V"), COUNTIF(CA7,"V"), COUNTIF(CE7,"V"), COUNTIF(CI7,"V"), COUNTIF(CM7,"V"), COUNTIF(CQ7,"V"), COUNTIF(CU7,"V"), COUNTIF(CY7,"V"), COUNTIF(DC7,"V"), COUNTIF(DG7,"V"), COUNTIF(DK7,"V"), COUNTIF(EA7,"V")) -> 0 | EF7: =+EB7/$EF$3 -> 0.27777778 | EG7: =+$EF$3 -> 7.125 | EH7: =+$EF$3-EB7 -> 5.1458333 | EI7: =+EB7*$EI$3 -> 5.5787037 | EJ7: =+EB7+$EG$3 -> 1.9791667
A8: SÁNCHEZ PINARGOTE MATEO IGNACIO | B8: 1752920445 | C8: KIOSCO | F8: AGENTE | G8: PRESENCIAL | H8: KIOSCO | I8: 0 | J8: 0 | K8: 0 | L8: KIOSCO | M8: 10:00 - 20:00 | N8: 0.375 | O8: A | P8: KIOSCO | Q8: 10:00 - 17:00 | R8: 0.27083333 | S8: A | T8: KIOSCO | U8: 10:00 - 17:00 | V8: 0.27083333 | W8: AT | X8: KIOSCO | Y8: 10:00 - 17:00 | Z8: 0.27083333 | AA8: A | AB8: KIOSCO | AC8: 10:00 - 17:00 | AD8: 0.27083333 | AE8: A | AF8: KIOSCO | AG8: 0 | AH8: 0 | AI8: 0 | AJ8: KIOSCO | AK8: 11:00 - 17:00 | AL8: 0.22916667 | AM8: AT | AN8: KIOSCO | AR8: KIOSCO | AV8: KIOSCO | AZ8: KIOSCO | BD8: KIOSCO | BH8: KIOSCO | BL8: KIOSCO | BP8: KIOSCO | BT8: KIOSCO | BX8: KIOSCO | CB8: KIOSCO | CF8: KIOSCO | CJ8: KIOSCO | CN8: KIOSCO | CR8: KIOSCO | CV8: KIOSCO | CZ8: KIOSCO | DD8: KIOSCO | DH8: KIOSCO | DL8: KIOSCO | DP8: KIOSCO | DT8: KIOSCO | DX8: KIOSCO | EB8: =+SUM(J8,N8,R8,V8,Z8,AD8,AH8,AL8,AP8,AT8,AX8,BB8,BF8,BJ8,BN8,BR8,BV8,BZ8,CD8,CH8,CL8,CP8,CT8,CX8,DB8,DF8,DJ8,DV8,DN8,DR8,DZ8) -> 1.6875 | EC8: =COUNTIF(H8:EA8,"AT") -> 2 | ED8: =SUM(COUNTIF(K8,"FI"), COUNTIF(O8,"FI"), COUNTIF(S8,"FI"), COUNTIF(W8,"FI"), COUNTIF(AA8,"FI"), COUNTIF(AE8,"FI"), COUNTIF(AI8,"FI"), COUNTIF(AM8,"FI"), COUNTIF(AQ8,"FI"), COUNTIF(AU8,"FI"), COUNTIF(AY8,"FI"), COUNTIF(BC8,"FI"), COUNTIF(BG8,"FI"), COUNTIF(BK8,"FI"), COUNTIF(BO8,"FI"), COUNTIF(BS8,"FI"), COUNTIF(BW8,"FI"), COUNTIF(CA8,"FI"), COUNTIF(CE8,"FI"), COUNTIF(CI8,"FI"), COUNTIF(CM8,"FI"), COUNTIF(CQ8,"FI"), COUNTIF(CU8,"FI"), COUNTIF(CY8,"FI"), COUNTIF(DC8,"FI"), COUNTIF(DG8,"FI"), COUNTIF(DK8,"FI"), COUNTIF(EA8,"FI")) -> 0 | EE8: =SUM(COUNTIF(K8,"V"), COUNTIF(O8,"V"), COUNTIF(S8,"V"), COUNTIF(W8,"V"), COUNTIF(AA8,"V"), COUNTIF(AE8,"V"), COUNTIF(AI8,"V"), COUNTIF(AM8,"V"), COUNTIF(AQ8,"V"), COUNTIF(AU8,"V"), COUNTIF(AY8,"V"), COUNTIF(BC8,"V"), COUNTIF(BG8,"V"), COUNTIF(BK8,"V"), COUNTIF(BO8,"V"), COUNTIF(BS8,"V"), COUNTIF(BW8,"V"), COUNTIF(CA8,"V"), COUNTIF(CE8,"V"), COUNTIF(CI8,"V"), COUNTIF(CM8,"V"), COUNTIF(CQ8,"V"), COUNTIF(CU8,"V"), COUNTIF(CY8,"V"), COUNTIF(DC8,"V"), COUNTIF(DG8,"V"), COUNTIF(DK8,"V"), COUNTIF(EA8,"V")) -> 0 | EF8: =+EB8/$EF$3 -> 0.23684211 | EG8: =+$EF$3 -> 7.125 | EH8: =+$EF$3-EB8 -> 5.4375 | EI8: =+EB8*$EI$3 -> 4.7565789 | EJ8: =+EB8+$EG$3 -> 1.6875
A9: BERMUDEZ MOREIRA CAROLINA MASIE | B9: 803489277 | C9: KIOSCO | H9: KIOSCO | I9: 12:00 - 17:00 | J9: 0.1875 | K9: A | L9: KIOSCO | M9: 10:00 - 17:00 | N9: 0.27083333 | O9: A | P9: KIOSCO | Q9: 10:00 - 17:00 | R9: 0.27083333 | S9: A | T9: KIOSCO | U9: 10:00 - 17:00 | V9: 0.27083333 | W9: A | X9: KIOSCO | Y9: 10:00 - 17:00 | Z9: 0.27083333 | AA9: A | AB9: KIOSCO | AC9: 10:00 - 17:00 | AD9: 0.27083333 | AE9: A | AF9: KIOSCO | AG9: 10:00 - 19:00 | AH9: 0.33333333 | AI9: A | AJ9: KIOSCO | AK9: 0 | AL9: 0 | AM9: 0 | AN9: KIOSCO | AR9: KIOSCO | AV9: KIOSCO | AZ9: KIOSCO | BD9: KIOSCO | BH9: KIOSCO | BL9: KIOSCO | BP9: KIOSCO | BT9: KIOSCO | BX9: KIOSCO | CB9: KIOSCO | CF9: KIOSCO | CJ9: KIOSCO | CN9: KIOSCO | CR9: KIOSCO | CV9: KIOSCO | CZ9: KIOSCO | DD9: KIOSCO | DH9: KIOSCO | DL9: KIOSCO | DP9: KIOSCO | DT9: KIOSCO | DX9: KIOSCO | EB9: =+SUM(J9,N9,R9,V9,Z9,AD9,AH9,AL9,AP9,AT9,AX9,BB9,BF9,BJ9,BN9,BR9,BV9,BZ9,CD9,CH9,CL9,CP9,CT9,CX9,DB9,DF9,DJ9,DV9,DN9,DR9,DZ9) -> 1.875 | EC9: =COUNTIF(H9:EA9,"AT") -> 0 | ED9: =SUM(COUNTIF(K9,"FI"), COUNTIF(O9,"FI"), COUNTIF(S9,"FI"), COUNTIF(W9,"FI"), COUNTIF(AA9,"FI"), COUNTIF(AE9,"FI"), COUNTIF(AI9,"FI"), COUNTIF(AM9,"FI"), COUNTIF(AQ9,"FI"), COUNTIF(AU9,"FI"), COUNTIF(AY9,"FI"), COUNTIF(BC9,"FI"), COUNTIF(BG9,"FI"), COUNTIF(BK9,"FI"), COUNTIF(BO9,"FI"), COUNTIF(BS9,"FI"), COUNTIF(BW9,"FI"), COUNTIF(CA9,"FI"), COUNTIF(CE9,"FI"), COUNTIF(CI9,"FI"), COUNTIF(CM9,"FI"), COUNTIF(CQ9,"FI"), COUNTIF(CU9,"FI"), COUNTIF(CY9,"FI"), COUNTIF(DC9,"FI"), COUNTIF(DG9,"FI"), COUNTIF(DK9,"FI"), COUNTIF(EA9,"FI")) -> 0 | EE9: =SUM(COUNTIF(K9,"V"), COUNTIF(O9,"V"), COUNTIF(S9,"V"), COUNTIF(W9,"V"), COUNTIF(AA9,"V"), COUNTIF(AE9,"V"), COUNTIF(AI9,"V"), COUNTIF(AM9,"V"), COUNTIF(AQ9,"V"), COUNTIF(AU9,"V"), COUNTIF(AY9,"V"), COUNTIF(BC9,"V"), COUNTIF(BG9,"V"), COUNTIF(BK9,"V"), COUNTIF(BO9,"V"), COUNTIF(BS9,"V"), COUNTIF(BW9,"V"), COUNTIF(CA9,"V"), COUNTIF(CE9,"V"), COUNTIF(CI9,"V"), COUNTIF(CM9,"V"), COUNTIF(CQ9,"V"), COUNTIF(CU9,"V"), COUNTIF(CY9,"V"), COUNTIF(DC9,"V"), COUNTIF(DG9,"V"), COUNTIF(DK9,"V"), COUNTIF(EA9,"V")) -> 0 | EF9: =+EB9/$EF$3 -> 0.26315789 | EG9: =+$EF$3 -> 7.125 | EH9: =+$EF$3-EB9 -> 5.25 | EI9: =+EB9*$EI$3 -> 5.2850877 | EJ9: =+EB9+$EG$3 -> 1.875
A10: DIAZ SANDRA | B10: 1761530391 | C10: KIOSCO | H10: KIOSCO | I10: 0 | J10: 0 | K10: 0 | L10: KIOSCO | M10: 10:00 - 20:00 | N10: 0.375 | O10: A | P10: KIOSCO | Q10: 10:00 - 20:00 | R10: 0.375 | S10: A | T10: KIOSCO | U10: 10:00 - 20:00 | V10: 0.375 | W10: A | X10: KIOSCO | Y10: 10:00 - 20:00 | Z10: 0.3125 | AA10: A | AB10: KIOSCO | AC10: 10:00 - 17:00 | AD10: 0.27083333 | AE10: A | AF10: KIOSCO | AG10: 10:00 - 17:00 | AH10: 0.27083333 | AI10: A | AJ10: KIOSCO | AK10: 10:00 - 20:00 | AL10: 0.375 | AM10: A | AN10: KIOSCO | AR10: KIOSCO | AV10: KIOSCO | AZ10: KIOSCO | BD10: KIOSCO | BH10: KIOSCO | BL10: KIOSCO | BP10: KIOSCO | BT10: KIOSCO | BX10: KIOSCO | CB10: KIOSCO | CF10: KIOSCO | CJ10: KIOSCO | CN10: KIOSCO | CR10: KIOSCO | CV10: KIOSCO | CZ10: KIOSCO | DD10: KIOSCO | DH10: KIOSCO | DL10: KIOSCO | DP10: KIOSCO | DT10: KIOSCO | DX10: KIOSCO | EB10: =+SUM(J10,N10,R10,V10,Z10,AD10,AH10,AL10,AP10,AT10,AX10,BB10,BF10,BJ10,BN10,BR10,BV10,BZ10,CD10,CH10,CL10,CP10,CT10,CX10,DB10,DF10,DJ10,DV10,DN10,DR10,DZ10) -> 2.3541667 | EC10: =COUNTIF(H10:EA10,"AT") -> 0 | ED10: =SUM(COUNTIF(K10,"FI"), COUNTIF(O10,"FI"), COUNTIF(S10,"FI"), COUNTIF(W10,"FI"), COUNTIF(AA10,"FI"), COUNTIF(AE10,"FI"), COUNTIF(AI10,"FI"), COUNTIF(AM10,"FI"), COUNTIF(AQ10,"FI"), COUNTIF(AU10,"FI"), COUNTIF(AY10,"FI"), COUNTIF(BC10,"FI"), COUNTIF(BG10,"FI"), COUNTIF(BK10,"FI"), COUNTIF(BO10,"FI"), COUNTIF(BS10,"FI"), COUNTIF(BW10,"FI"), COUNTIF(CA10,"FI"), COUNTIF(CE10,"FI"), COUNTIF(CI10,"FI"), COUNTIF(CM10,"FI"), COUNTIF(CQ10,"FI"), COUNTIF(CU10,"FI"), COUNTIF(CY10,"FI"), COUNTIF(DC10,"FI"), COUNTIF(DG10,"FI"), COUNTIF(DK10,"FI"), COUNTIF(EA10,"FI")) -> 0 | EE10: =SUM(COUNTIF(K10,"V"), COUNTIF(O10,"V"), COUNTIF(S10,"V"), COUNTIF(W10,"V"), COUNTIF(AA10,"V"), COUNTIF(AE10,"V"), COUNTIF(AI10,"V"), COUNTIF(AM10,"V"), COUNTIF(AQ10,"V"), COUNTIF(AU10,"V"), COUNTIF(AY10,"V"), COUNTIF(BC10,"V"), COUNTIF(BG10,"V"), COUNTIF(BK10,"V"), COUNTIF(BO10,"V"), COUNTIF(BS10,"V"), COUNTIF(BW10,"V"), COUNTIF(CA10,"V"), COUNTIF(CE10,"V"), COUNTIF(CI10,"V"), COUNTIF(CM10,"V"), COUNTIF(CQ10,"V"), COUNTIF(CU10,"V"), COUNTIF(CY10,"V"), COUNTIF(DC10,"V"), COUNTIF(DG10,"V"), COUNTIF(DK10,"V"), COUNTIF(EA10,"V")) -> 0 | EF10: =+EB10/$EF$3 -> 0.33040936 | EG10: =+$EF$3 -> 7.125 | EH10: =+$EF$3-EB10 -> 4.7708333 | EI10: =+EB10*$EI$3 -> 6.6357212 | EJ10: =+EB10+$EG$3 -> 2.3541667
A11: GONZALES GONZALES GEOVANNA PATRICIA | B11: 1723503452 | C11: KIOSCO | H11: KIOSCO | I11: 0 | J11: 0 | K11: 0 | L11: KIOSCO | M11: 10:00 - 17:00 | N11: 0.27083333 | O11: A | P11: KIOSCO | Q11: 10:00 - 17:00 | R11: 0.27083333 | S11: A | T11: KIOSCO | U11: 10:00 - 17:00 | V11: 0.27083333 | W11: A | X11: KIOSCO | Y11: 10:00 - 17:00 | Z11: 0.25 | AA11: A | AB11: KIOSCO | AC11: 10:00 - 17:00 | AD11: 0.27083333 | AE11: A | AF11: KIOSCO | AG11: 10:00 - 17:00 | AH11: 0.25 | AI11: A | AJ11: KIOSCO | AK11: 10:00 - 17:00 | AL11: 0.25 | AM11: A | AN11: KIOSCO | AR11: KIOSCO | AV11: KIOSCO | AZ11: KIOSCO | BD11: KIOSCO | BH11: KIOSCO | BL11: KIOSCO | BP11: KIOSCO | BT11: KIOSCO | BX11: KIOSCO | CB11: KIOSCO | CF11: KIOSCO | CJ11: KIOSCO | CN11: KIOSCO | CR11: KIOSCO | CV11: KIOSCO | CZ11: KIOSCO | DD11: KIOSCO | DH11: KIOSCO | DL11: KIOSCO | DP11: KIOSCO | DT11: KIOSCO | DX11: KIOSCO | EB11: =+SUM(J11,N11,R11,V11,Z11,AD11,AH11,AL11,AP11,AT11,AX11,BB11,BF11,BJ11,BN11,BR11,BV11,BZ11,CD11,CH11,CL11,CP11,CT11,CX11,DB11,DF11,DJ11,DV11,DN11,DR11,DZ11) -> 1.8333333 | EC11: =COUNTIF(H11:EA11,"AT") -> 0 | ED11: =SUM(COUNTIF(K11,"FI"), COUNTIF(O11,"FI"), COUNTIF(S11,"FI"), COUNTIF(W11,"FI"), COUNTIF(AA11,"FI"), COUNTIF(AE11,"FI"), COUNTIF(AI11,"FI"), COUNTIF(AM11,"FI"), COUNTIF(AQ11,"FI"), COUNTIF(AU11,"FI"), COUNTIF(AY11,"FI"), COUNTIF(BC11,"FI"), COUNTIF(BG11,"FI"), COUNTIF(BK11,"FI"), COUNTIF(BO11,"FI"), COUNTIF(BS11,"FI"), COUNTIF(BW11,"FI"), COUNTIF(CA11,"FI"), COUNTIF(CE11,"FI"), COUNTIF(CI11,"FI"), COUNTIF(CM11,"FI"), COUNTIF(CQ11,"FI"), COUNTIF(CU11,"FI"), COUNTIF(CY11,"FI"), COUNTIF(DC11,"FI"), COUNTIF(DG11,"FI"), COUNTIF(DK11,"FI"), COUNTIF(EA11,"FI")) -> 0 | EE11: =SUM(COUNTIF(K11,"V"), COUNTIF(O11,"V"), COUNTIF(S11,"V"), COUNTIF(W11,"V"), COUNTIF(AA11,"V"), COUNTIF(AE11,"V"), COUNTIF(AI11,"V"), COUNTIF(AM11,"V"), COUNTIF(AQ11,"V"), COUNTIF(AU11,"V"), COUNTIF(AY11,"V"), COUNTIF(BC11,"V"), COUNTIF(BG11,"V"), COUNTIF(BK11,"V"), COUNTIF(BO11,"V"), COUNTIF(BS11,"V"), COUNTIF(BW11,"V"), COUNTIF(CA11,"V"), COUNTIF(CE11,"V"), COUNTIF(CI11,"V"), COUNTIF(CM11,"V"), COUNTIF(CQ11,"V"), COUNTIF(CU11,"V"), COUNTIF(CY11,"V"), COUNTIF(DC11,"V"), COUNTIF(DG11,"V"), COUNTIF(DK11,"V"), COUNTIF(EA11,"V")) -> 0 | EF11: =+EB11/$EF$3 -> 0.25730994 | EG11: =+$EF$3 -> 7.125 | EH11: =+$EF$3-EB11 -> 5.2916667 | EI11: =+EB11*$EI$3 -> 5.1676413 | EJ11: =+EB11+$EG$3 -> 1.8333333
A12: OCHOA CANTOS ROCIO ZORAIDA | B12: 1725280067 | C12: KIOSCO | H12: KIOSCO | I12: 0 | J12: 0 | K12: 0 | L12: KIOSCO | M12: 10:00 - 17:00 | N12: 0.27083333 | O12: A | P12: KIOSCO | Q12: 10:00 - 17:00 | R12: 0.27083333 | S12: A | T12: KIOSCO | U12: 13:00 - 17:00 | V12: 0.16666667 | W12: A | X12: KIOSCO | Y12: 10:00 - 17:00 | Z12: 0.27083333 | AA12: A | AB12: KIOSCO | AC12: 10:00 - 17:00 | AD12: 0.27083333 | AE12: A | AF12: KIOSCO | AG12: 0 | AH12: 0 | AI12: 0 | AJ12: KIOSCO | AK12: 10:00 - 18:00 | AL12: 0.29166667 | AM12: A | AN12: KIOSCO | AR12: KIOSCO | AV12: KIOSCO | AZ12: KIOSCO | BD12: KIOSCO | BH12: KIOSCO | BL12: KIOSCO | BP12: KIOSCO | BT12: KIOSCO | BX12: KIOSCO | CB12: KIOSCO | CF12: KIOSCO | CJ12: KIOSCO | CN12: KIOSCO | CR12: KIOSCO | CV12: KIOSCO | CZ12: KIOSCO | DD12: KIOSCO | DH12: KIOSCO | DL12: KIOSCO | DP12: KIOSCO | DT12: KIOSCO | DX12: KIOSCO | EB12: =+SUM(J12,N12,R12,V12,Z12,AD12,AH12,AL12,AP12,AT12,AX12,BB12,BF12,BJ12,BN12,BR12,BV12,BZ12,CD12,CH12,CL12,CP12,CT12,CX12,DB12,DF12,DJ12,DV12,DN12,DR12,DZ12) -> 1.5416667 | EC12: =COUNTIF(H12:EA12,"AT") -> 0 | ED12: =SUM(COUNTIF(K12,"FI"), COUNTIF(O12,"FI"), COUNTIF(S12,"FI"), COUNTIF(W12,"FI"), COUNTIF(AA12,"FI"), COUNTIF(AE12,"FI"), COUNTIF(AI12,"FI"), COUNTIF(AM12,"FI"), COUNTIF(AQ12,"FI"), COUNTIF(AU12,"FI"), COUNTIF(AY12,"FI"), COUNTIF(BC12,"FI"), COUNTIF(BG12,"FI"), COUNTIF(BK12,"FI"), COUNTIF(BO12,"FI"), COUNTIF(BS12,"FI"), COUNTIF(BW12,"FI"), COUNTIF(CA12,"FI"), COUNTIF(CE12,"FI"), COUNTIF(CI12,"FI"), COUNTIF(CM12,"FI"), COUNTIF(CQ12,"FI"), COUNTIF(CU12,"FI"), COUNTIF(CY12,"FI"), COUNTIF(DC12,"FI"), COUNTIF(DG12,"FI"), COUNTIF(DK12,"FI"), COUNTIF(EA12,"FI")) -> 0 | EE12: =SUM(COUNTIF(K12,"V"), COUNTIF(O12,"V"), COUNTIF(S12,"V"), COUNTIF(W12,"V"), COUNTIF(AA12,"V"), COUNTIF(AE12,"V"), COUNTIF(AI12,"V"), COUNTIF(AM12,"V"), COUNTIF(AQ12,"V"), COUNTIF(AU12,"V"), COUNTIF(AY12,"V"), COUNTIF(BC12,"V"), COUNTIF(BG12,"V"), COUNTIF(BK12,"V"), COUNTIF(BO12,"V"), COUNTIF(BS12,"V"), COUNTIF(BW12,"V"), COUNTIF(CA12,"V"), COUNTIF(CE12,"V"), COUNTIF(CI12,"V"), COUNTIF(CM12,"V"), COUNTIF(CQ12,"V"), COUNTIF(CU12,"V"), COUNTIF(CY12,"V"), COUNTIF(DC12,"V"), COUNTIF(DG12,"V"), COUNTIF(DK12,"V"), COUNTIF(EA12,"V")) -> 0 | EF12: =+EB12/$EF$3 -> 0.21637427 | EG12: =+$EF$3 -> 7.125 | EH12: =+$EF$3-EB12 -> 5.5833333 | EI12: =+EB12*$EI$3 -> 4.3455166 | EJ12: =+EB12+$EG$3 -> 1.5416667
A13: PULLUPAXI PANTA RODY XAVIER | B13: 1724242761 | C13: KIOSCO | H13: KIOSCO | I13: 11:00 - 17:00 | J13: 0.20833333 | K13: AT | L13: KIOSCO | M13: 10:00 - 17:00 | N13: 0.27083333 | O13: A | P13: KIOSCO | Q13: 10:00 - 17:00 | R13: 0.27083333 | S13: A | T13: KIOSCO | U13: 10:00 - 17:00 | V13: 0.27083333 | W13: A | X13: KIOSCO | Y13: 10:00 - 17:00 | Z13: 0.27083333 | AA13: A | AB13: KIOSCO | AC13: 10:00 - 20:00 | AD13: 0.39583333 | AE13: A | AF13: KIOSCO | AG13: 10:00 - 20:00 | AH13: 0.375 | AI13: AT | AJ13: KIOSCO | AK13: 0 | AL13: 0 | AM13: 0 | AN13: KIOSCO | AR13: KIOSCO | AV13: KIOSCO | AZ13: KIOSCO | BD13: KIOSCO | BH13: KIOSCO | BL13: KIOSCO | BP13: KIOSCO | BT13: KIOSCO | BX13: KIOSCO | CB13: KIOSCO | CF13: KIOSCO | CJ13: KIOSCO | CN13: KIOSCO | CR13: KIOSCO | CV13: KIOSCO | CZ13: KIOSCO | DD13: KIOSCO | DH13: KIOSCO | DL13: KIOSCO | DP13: KIOSCO | DT13: KIOSCO | DX13: KIOSCO | EB13: =+SUM(J13,N13,R13,V13,Z13,AD13,AH13,AL13,AP13,AT13,AX13,BB13,BF13,BJ13,BN13,BR13,BV13,BZ13,CD13,CH13,CL13,CP13,CT13,CX13,DB13,DF13,DJ13,DV13,DN13,DR13,DZ13) -> 2.0625 | EC13: =COUNTIF(H13:EA13,"AT") -> 2 | ED13: =SUM(COUNTIF(K13,"FI"), COUNTIF(O13,"FI"), COUNTIF(S13,"FI"), COUNTIF(W13,"FI"), COUNTIF(AA13,"FI"), COUNTIF(AE13,"FI"), COUNTIF(AI13,"FI"), COUNTIF(AM13,"FI"), COUNTIF(AQ13,"FI"), COUNTIF(AU13,"FI"), COUNTIF(AY13,"FI"), COUNTIF(BC13,"FI"), COUNTIF(BG13,"FI"), COUNTIF(BK13,"FI"), COUNTIF(BO13,"FI"), COUNTIF(BS13,"FI"), COUNTIF(BW13,"FI"), COUNTIF(CA13,"FI"), COUNTIF(CE13,"FI"), COUNTIF(CI13,"FI"), COUNTIF(CM13,"FI"), COUNTIF(CQ13,"FI"), COUNTIF(CU13,"FI"), COUNTIF(CY13,"FI"), COUNTIF(DC13,"FI"), COUNTIF(DG13,"FI"), COUNTIF(DK13,"FI"), COUNTIF(EA13,"FI")) -> 0 | EE13: =SUM(COUNTIF(K13,"V"), COUNTIF(O13,"V"), COUNTIF(S13,"V"), COUNTIF(W13,"V"), COUNTIF(AA13,"V"), COUNTIF(AE13,"V"), COUNTIF(AI13,"V"), COUNTIF(AM13,"V"), COUNTIF(AQ13,"V"), COUNTIF(AU13,"V"), COUNTIF(AY13,"V"), COUNTIF(BC13,"V"), COUNTIF(BG13,"V"), COUNTIF(BK13,"V"), COUNTIF(BO13,"V"), COUNTIF(BS13,"V"), COUNTIF(BW13,"V"), COUNTIF(CA13,"V"), COUNTIF(CE13,"V"), COUNTIF(CI13,"V"), COUNTIF(CM13,"V"), COUNTIF(CQ13,"V"), COUNTIF(CU13,"V"), COUNTIF(CY13,"V"), COUNTIF(DC13,"V"), COUNTIF(DG13,"V"), COUNTIF(DK13,"V"), COUNTIF(EA13,"V")) -> 0 | EF13: =+EB13/$EF$3 -> 0.28947368 | EG13: =+$EF$3 -> 7.125 | EH13: =+$EF$3-EB13 -> 5.0625 | EI13: =+EB13*$EI$3 -> 5.8135965 | EJ13: =+EB13+$EG$3 -> 2.0625
A14: MOSQUERA BUSTOS MARCOS SEBASTIAN | B14: 0804296044 | C14: KIOSCO | H14: KIOSCO | I14: 10:00 - 17:00 | J14: 0.25 | K14: A | L14: KIOSCO | M14: 10:00 - 17:00 | N14: 0.27083333 | O14: A | P14: KIOSCO | Q14: 10:00 - 17:00 | R14: 0.27083333 | S14: A | T14: KIOSCO | U14: 10:00 - 17:00 | V14: 0.25 | W14: A | X14: KIOSCO | Y14: 10:00 - 17:00 | Z14: 0.27083333 | AA14: A | AB14: KIOSCO | AC14: 10:00 - 20:00 | AD14: 0.39583333 | AE14: A | AF14: KIOSCO | AG14: 10:00 - 17:00 | AH14: 0.27083333 | AI14: AT | AJ14: KIOSCO | AK14: 0 | AL14: 0 | AM14: 0 | AN14: KIOSCO | AR14: KIOSCO | AV14: KIOSCO | AZ14: KIOSCO | BD14: KIOSCO | BH14: KIOSCO | BL14: KIOSCO | BP14: KIOSCO | BT14: KIOSCO | BX14: KIOSCO | CB14: KIOSCO | CF14: KIOSCO | CJ14: KIOSCO | CN14: KIOSCO | CR14: KIOSCO | CV14: KIOSCO | CZ14: KIOSCO | DD14: KIOSCO | DH14: KIOSCO | DL14: KIOSCO | DP14: KIOSCO | DT14: KIOSCO | DX14: KIOSCO | EB14: =+SUM(J14,N14,R14,V14,Z14,AD14,AH14,AL14,AP14,AT14,AX14,BB14,BF14,BJ14,BN14,BR14,BV14,BZ14,CD14,CH14,CL14,CP14,CT14,CX14,DB14,DF14,DJ14,DV14,DN14,DR14,DZ14) -> 1.9791667 | EC14: =COUNTIF(H14:EA14,"AT") -> 1 | ED14: =SUM(COUNTIF(K14,"FI"), COUNTIF(O14,"FI"), COUNTIF(S14,"FI"), COUNTIF(W14,"FI"), COUNTIF(AA14,"FI"), COUNTIF(AE14,"FI"), COUNTIF(AI14,"FI"), COUNTIF(AM14,"FI"), COUNTIF(AQ14,"FI"), COUNTIF(AU14,"FI"), COUNTIF(AY14,"FI"), COUNTIF(BC14,"FI"), COUNTIF(BG14,"FI"), COUNTIF(BK14,"FI"), COUNTIF(BO14,"FI"), COUNTIF(BS14,"FI"), COUNTIF(BW14,"FI"), COUNTIF(CA14,"FI"), COUNTIF(CE14,"FI"), COUNTIF(CI14,"FI"), COUNTIF(CM14,"FI"), COUNTIF(CQ14,"FI"), COUNTIF(CU14,"FI"), COUNTIF(CY14,"FI"), COUNTIF(DC14,"FI"), COUNTIF(DG14,"FI"), COUNTIF(DK14,"FI"), COUNTIF(EA14,"FI")) -> 0 | EE14: =SUM(COUNTIF(K14,"V"), COUNTIF(O14,"V"), COUNTIF(S14,"V"), COUNTIF(W14,"V"), COUNTIF(AA14,"V"), COUNTIF(AE14,"V"), COUNTIF(AI14,"V"), COUNTIF(AM14,"V"), COUNTIF(AQ14,"V"), COUNTIF(AU14,"V"), COUNTIF(AY14,"V"), COUNTIF(BC14,"V"), COUNTIF(BG14,"V"), COUNTIF(BK14,"V"), COUNTIF(BO14,"V"), COUNTIF(BS14,"V"), COUNTIF(BW14,"V"), COUNTIF(CA14,"V"), COUNTIF(CE14,"V"), COUNTIF(CI14,"V"), COUNTIF(CM14,"V"), COUNTIF(CQ14,"V"), COUNTIF(CU14,"V"), COUNTIF(CY14,"V"), COUNTIF(DC14,"V"), COUNTIF(DG14,"V"), COUNTIF(DK14,"V"), COUNTIF(EA14,"V")) -> 0 | EF14: =+EB14/$EF$3 -> 0.27777778 | EG14: =+$EF$3 -> 7.125 | EH14: =+$EF$3-EB14 -> 5.1458333 | EI14: =+EB14*$EI$3 -> 5.5787037 | EJ14: =+EB14+$EG$3 -> 1.9791667
A15: CEVALLO GOMEZ LUIS ANTONIO | B15: 926324534 | C15: KIOSCO | H15: KIOSCO | I15: 10:00 - 17:00 | J15: 0.27083333 | K15: A | L15: KIOSCO | M15: 10:00 - 17:00 | N15: 0.27083333 | O15: A | P15: KIOSCO | Q15: 10:00 - 17:00 | R15: 0.27083333 | S15: A | T15: KIOSCO | U15: 10:00 - 17:00 | V15: 0.25 | W15: A | X15: KIOSCO | Y15: 10:00 - 17:00 | Z15: 0.27083333 | AA15: A | AB15: KIOSCO | AC15: 10:00 - 17:00 | AD15: 0.27083333 | AE15: A | AF15: KIOSCO | AG15: 10:00 - 17:00 | AH15: 0.27083333 | AI15: AT | AJ15: KIOSCO | AK15: 0 | AL15: 0 | AM15: 0 | AN15: KIOSCO | AR15: KIOSCO | AV15: KIOSCO | AZ15: KIOSCO | BD15: KIOSCO | BH15: KIOSCO | BL15: KIOSCO | BP15: KIOSCO | BT15: KIOSCO | BX15: KIOSCO | CB15: KIOSCO | CF15: KIOSCO | CJ15: KIOSCO | CN15: KIOSCO | CR15: KIOSCO | CV15: KIOSCO | CZ15: KIOSCO | DD15: KIOSCO | DH15: KIOSCO | DL15: KIOSCO | DP15: KIOSCO | DT15: KIOSCO | DX15: KIOSCO | EB15: =+SUM(J15,N15,R15,V15,Z15,AD15,AH15,AL15,AP15,AT15,AX15,BB15,BF15,BJ15,BN15,BR15,BV15,BZ15,CD15,CH15,CL15,CP15,CT15,CX15,DB15,DF15,DJ15,DV15,DN15,DR15,DZ15) -> 1.875 | EC15: =COUNTIF(H15:EA15,"AT") -> 1 | ED15: =SUM(COUNTIF(K15,"FI"), COUNTIF(O15,"FI"), COUNTIF(S15,"FI"), COUNTIF(W15,"FI"), COUNTIF(AA15,"FI"), COUNTIF(AE15,"FI"), COUNTIF(AI15,"FI"), COUNTIF(AM15,"FI"), COUNTIF(AQ15,"FI"), COUNTIF(AU15,"FI"), COUNTIF(AY15,"FI"), COUNTIF(BC15,"FI"), COUNTIF(BG15,"FI"), COUNTIF(BK15,"FI"), COUNTIF(BO15,"FI"), COUNTIF(BS15,"FI"), COUNTIF(BW15,"FI"), COUNTIF(CA15,"FI"), COUNTIF(CE15,"FI"), COUNTIF(CI15,"FI"), COUNTIF(CM15,"FI"), COUNTIF(CQ15,"FI"), COUNTIF(CU15,"FI"), COUNTIF(CY15,"FI"), COUNTIF(DC15,"FI"), COUNTIF(DG15,"FI"), COUNTIF(DK15,"FI"), COUNTIF(EA15,"FI")) -> 0 | EE15: =SUM(COUNTIF(K15,"V"), COUNTIF(O15,"V"), COUNTIF(S15,"V"), COUNTIF(W15,"V"), COUNTIF(AA15,"V"), COUNTIF(AE15,"V"), COUNTIF(AI15,"V"), COUNTIF(AM15,"V"), COUNTIF(AQ15,"V"), COUNTIF(AU15,"V"), COUNTIF(AY15,"V"), COUNTIF(BC15,"V"), COUNTIF(BG15,"V"), COUNTIF(BK15,"V"), COUNTIF(BO15,"V"), COUNTIF(BS15,"V"), COUNTIF(BW15,"V"), COUNTIF(CA15,"V"), COUNTIF(CE15,"V"), COUNTIF(CI15,"V"), COUNTIF(CM15,"V"), COUNTIF(CQ15,"V"), COUNTIF(CU15,"V"), COUNTIF(CY15,"V"), COUNTIF(DC15,"V"), COUNTIF(DG15,"V"), COUNTIF(DK15,"V"), COUNTIF(EA15,"V")) -> 0 | EF15: =+EB15/$EF$3 -> 0.26315789 | EG15: =+$EF$3 -> 7.125 | EH15: =+$EF$3-EB15 -> 5.25 | EI15: =+EB15*$EI$3 -> 5.2850877 | EJ15: =+EB15+$EG$3 -> 1.875
A16: CASTILLO TIPANTASI JOSUANY ISABEL | B16: 1723040950 | C16: KIOSCO | H16: KIOSCO | I16: 0 | J16: 0 | K16: 0 | L16: KIOSCO | M16: 10:00 - 17:00 | N16: 0.27083333 | O16: A | P16: KIOSCO | Q16: 10:00 - 17:00 | R16: 0.25 | S16: A | T16: KIOSCO | U16: FI | V16: 0 | W16: FI | X16: KIOSCO | Y16: 0 | Z16: 0 | AA16: 0 | AB16: KIOSCO | AC16: 0 | AD16: 0 | AE16: FI | AF16: KIOSCO | AG16: 0 | AH16: 0 | AI16: 0 | AJ16: KIOSCO | AK16: 0 | AL16: 0 | AM16: 0 | AN16: KIOSCO | AR16: KIOSCO | AV16: KIOSCO | AZ16: KIOSCO | BD16: KIOSCO | BH16: KIOSCO | BL16: KIOSCO | BP16: KIOSCO | BT16: KIOSCO | BX16: KIOSCO | CB16: KIOSCO | CF16: KIOSCO | CJ16: KIOSCO | CN16: KIOSCO | CR16: KIOSCO | CV16: KIOSCO | CZ16: KIOSCO | DD16: KIOSCO | DH16: KIOSCO | DL16: KIOSCO | DP16: KIOSCO | DT16: KIOSCO | DX16: KIOSCO | EB16: =+SUM(J16,N16,R16,V16,Z16,AD16,AH16,AL16,AP16,AT16,AX16,BB16,BF16,BJ16,BN16,BR16,BV16,BZ16,CD16,CH16,CL16,CP16,CT16,CX16,DB16,DF16,DJ16,DV16,DN16,DR16,DZ16) -> 0.52083333 | EC16: =COUNTIF(H16:EA16,"AT") -> 0 | ED16: =SUM(COUNTIF(K16,"FI"), COUNTIF(O16,"FI"), COUNTIF(S16,"FI"), COUNTIF(W16,"FI"), COUNTIF(AA16,"FI"), COUNTIF(AE16,"FI"), COUNTIF(AI16,"FI"), COUNTIF(AM16,"FI"), COUNTIF(AQ16,"FI"), COUNTIF(AU16,"FI"), COUNTIF(AY16,"FI"), COUNTIF(BC16,"FI"), COUNTIF(BG16,"FI"), COUNTIF(BK16,"FI"), COUNTIF(BO16,"FI"), COUNTIF(BS16,"FI"), COUNTIF(BW16,"FI"), COUNTIF(CA16,"FI"), COUNTIF(CE16,"FI"), COUNTIF(CI16,"FI"), COUNTIF(CM16,"FI"), COUNTIF(CQ16,"FI"), COUNTIF(CU16,"FI"), COUNTIF(CY16,"FI"), COUNTIF(DC16,"FI"), COUNTIF(DG16,"FI"), COUNTIF(DK16,"FI"), COUNTIF(EA16,"FI")) -> 2 | EE16: =SUM(COUNTIF(K16,"V"), COUNTIF(O16,"V"), COUNTIF(S16,"V"), COUNTIF(W16,"V"), COUNTIF(AA16,"V"), COUNTIF(AE16,"V"), COUNTIF(AI16,"V"), COUNTIF(AM16,"V"), COUNTIF(AQ16,"V"), COUNTIF(AU16,"V"), COUNTIF(AY16,"V"), COUNTIF(BC16,"V"), COUNTIF(BG16,"V"), COUNTIF(BK16,"V"), COUNTIF(BO16,"V"), COUNTIF(BS16,"V"), COUNTIF(BW16,"V"), COUNTIF(CA16,"V"), COUNTIF(CE16,"V"), COUNTIF(CI16,"V"), COUNTIF(CM16,"V"), COUNTIF(CQ16,"V"), COUNTIF(CU16,"V"), COUNTIF(CY16,"V"), COUNTIF(DC16,"V"), COUNTIF(DG16,"V"), COUNTIF(DK16,"V"), COUNTIF(EA16,"V")) -> 0 | EF16: =+EB16/$EF$3 -> 0.073099415 | EG16: =+$EF$3 -> 7.125 | EH16: =+$EF$3-EB16 -> 6.6041667 | EI16: =+EB16*$EI$3 -> 1.4680799 | EJ16: =+EB16+$EG$3 -> 0.52083333
A17: ESTUPIÑAN SAAVEDRA JUAN DAVID | B17: 2200107536 | C17: KIOSCO | H17: KIOSCO | I17: 10:00 - 17:00 | J17: 0.25 | K17: A | L17: KIOSCO | M17: 10:00 - 17:00 | N17: 0.27083333 | O17: A | P17: KIOSCO | Q17: 10:00 - 17:00 | R17: 0.25 | S17: A | T17: KIOSCO | U17: 10:00 - 17:00 | V17: 0.27083333 | W17: A | X17: KIOSCO | Y17: 10:00 - 17:00 | Z17: 0.27083333 | AA17: A | AB17: KIOSCO | AC17: 10:00 - 17:00 | AD17: 0.27083333 | AE17: A | AF17: KIOSCO | AG17: 10:00 - 16:00 | AH17: 0.22916667 | AI17: A | AJ17: KIOSCO | AK17: 0 | AL17: 0 | AM17: 0 | AN17: KIOSCO | AR17: KIOSCO | AV17: KIOSCO | AZ17: KIOSCO | BD17: KIOSCO | BH17: KIOSCO | BL17: KIOSCO | BP17: KIOSCO | BT17: KIOSCO | BX17: KIOSCO | CB17: KIOSCO | CF17: KIOSCO | CJ17: KIOSCO | CN17: KIOSCO | CR17: KIOSCO | CV17: KIOSCO | CZ17: KIOSCO | DD17: KIOSCO | DH17: KIOSCO | DL17: KIOSCO | DP17: KIOSCO | DT17: KIOSCO | DX17: KIOSCO | EB17: =+SUM(J17,N17,R17,V17,Z17,AD17,AH17,AL17,AP17,AT17,AX17,BB17,BF17,BJ17,BN17,BR17,BV17,BZ17,CD17,CH17,CL17,CP17,CT17,CX17,DB17,DF17,DJ17,DV17,DN17,DR17,DZ17) -> 1.8125 | EC17: =COUNTIF(H17:EA17,"AT") -> 0 | ED17: =SUM(COUNTIF(K17,"FI"), COUNTIF(O17,"FI"), COUNTIF(S17,"FI"), COUNTIF(W17,"FI"), COUNTIF(AA17,"FI"), COUNTIF(AE17,"FI"), COUNTIF(AI17,"FI"), COUNTIF(AM17,"FI"), COUNTIF(AQ17,"FI"), COUNTIF(AU17,"FI"), COUNTIF(AY17,"FI"), COUNTIF(BC17,"FI"), COUNTIF(BG17,"FI"), COUNTIF(BK17,"FI"), COUNTIF(BO17,"FI"), COUNTIF(BS17,"FI"), COUNTIF(BW17,"FI"), COUNTIF(CA17,"FI"), COUNTIF(CE17,"FI"), COUNTIF(CI17,"FI"), COUNTIF(CM17,"FI"), COUNTIF(CQ17,"FI"), COUNTIF(CU17,"FI"), COUNTIF(CY17,"FI"), COUNTIF(DC17,"FI"), COUNTIF(DG17,"FI"), COUNTIF(DK17,"FI"), COUNTIF(EA17,"FI")) -> 0 | EE17: =SUM(COUNTIF(K17,"V"), COUNTIF(O17,"V"), COUNTIF(S17,"V"), COUNTIF(W17,"V"), COUNTIF(AA17,"V"), COUNTIF(AE17,"V"), COUNTIF(AI17,"V"), COUNTIF(AM17,"V"), COUNTIF(AQ17,"V"), COUNTIF(AU17,"V"), COUNTIF(AY17,"V"), COUNTIF(BC17,"V"), COUNTIF(BG17,"V"), COUNTIF(BK17,"V"), COUNTIF(BO17,"V"), COUNTIF(BS17,"V"), COUNTIF(BW17,"V"), COUNTIF(CA17,"V"), COUNTIF(CE17,"V"), COUNTIF(CI17,"V"), COUNTIF(CM17,"V"), COUNTIF(CQ17,"V"), COUNTIF(CU17,"V"), COUNTIF(CY17,"V"), COUNTIF(DC17,"V"), COUNTIF(DG17,"V"), COUNTIF(DK17,"V"), COUNTIF(EA17,"V")) -> 0 | EF17: =+EB17/$EF$3 -> 0.25438596 | EG17: =+$EF$3 -> 7.125 | EH17: =+$EF$3-EB17 -> 5.3125 | EI17: =+EB17*$EI$3 -> 5.1089181 | EJ17: =+EB17+$EG$3 -> 1.8125
A18: MORALES MARTINEZ JOSUE JAVIER | B18: 1720635547 | C18: KIOSCO | H18: KIOSCO | I18: 0 | J18: 0 | K18: 0 | L18: KIOSCO | M18: 10:00 - 18:00 | N18: 0.3125 | O18: A | P18: KIOSCO | Q18: 10:00 - 17:00 | R18: 0.25 | S18: A | T18: KIOSCO | U18: 10:00 - 17:00 | V18: 0.25 | W18: A | X18: KIOSCO | Y18: 10:00 - 20:00 | Z18: 0.375 | AA18: A | AB18: KIOSCO | AC18: 10:00 - 17:00 | AD18: 0.27083333 | AE18: A | AF18: KIOSCO | AG18: 10:00 - 17:00 | AH18: 0.25 | AI18: A | AJ18: KIOSCO | AK18: 12:00 - 17:00 | AL18: 0.1875 | AM18: AT | AN18: KIOSCO | AR18: KIOSCO | AV18: KIOSCO | AZ18: KIOSCO | BD18: KIOSCO | BH18: KIOSCO | BL18: KIOSCO | BP18: KIOSCO | BT18: KIOSCO | BX18: KIOSCO | CB18: KIOSCO | CF18: KIOSCO | CJ18: KIOSCO | CN18: KIOSCO | CR18: KIOSCO | CV18: KIOSCO | CZ18: KIOSCO | DD18: KIOSCO | DH18: KIOSCO | DL18: KIOSCO | DP18: KIOSCO | DT18: KIOSCO | DX18: KIOSCO | EB18: =+SUM(J18,N18,R18,V18,Z18,AD18,AH18,AL18,AP18,AT18,AX18,BB18,BF18,BJ18,BN18,BR18,BV18,BZ18,CD18,CH18,CL18,CP18,CT18,CX18,DB18,DF18,DJ18,DV18,DN18,DR18,DZ18) -> 1.8958333 | EC18: =COUNTIF(H18:EA18,"AT") -> 1 | ED18: =SUM(COUNTIF(K18,"FI"), COUNTIF(O18,"FI"), COUNTIF(S18,"FI"), COUNTIF(W18,"FI"), COUNTIF(AA18,"FI"), COUNTIF(AE18,"FI"), COUNTIF(AI18,"FI"), COUNTIF(AM18,"FI"), COUNTIF(AQ18,"FI"), COUNTIF(AU18,"FI"), COUNTIF(AY18,"FI"), COUNTIF(BC18,"FI"), COUNTIF(BG18,"FI"), COUNTIF(BK18,"FI"), COUNTIF(BO18,"FI"), COUNTIF(BS18,"FI"), COUNTIF(BW18,"FI"), COUNTIF(CA18,"FI"), COUNTIF(CE18,"FI"), COUNTIF(CI18,"FI"), COUNTIF(CM18,"FI"), COUNTIF(CQ18,"FI"), COUNTIF(CU18,"FI"), COUNTIF(CY18,"FI"), COUNTIF(DC18,"FI"), COUNTIF(DG18,"FI"), COUNTIF(DK18,"FI"), COUNTIF(EA18,"FI")) -> 0 | EE18: =SUM(COUNTIF(K18,"V"), COUNTIF(O18,"V"), COUNTIF(S18,"V"), COUNTIF(W18,"V"), COUNTIF(AA18,"V"), COUNTIF(AE18,"V"), COUNTIF(AI18,"V"), COUNTIF(AM18,"V"), COUNTIF(AQ18,"V"), COUNTIF(AU18,"V"), COUNTIF(AY18,"V"), COUNTIF(BC18,"V"), COUNTIF(BG18,"V"), COUNTIF(BK18,"V"), COUNTIF(BO18,"V"), COUNTIF(BS18,"V"), COUNTIF(BW18,"V"), COUNTIF(CA18,"V"), COUNTIF(CE18,"V"), COUNTIF(CI18,"V"), COUNTIF(CM18,"V"), COUNTIF(CQ18,"V"), COUNTIF(CU18,"V"), COUNTIF(CY18,"V"), COUNTIF(DC18,"V"), COUNTIF(DG18,"V"), COUNTIF(DK18,"V"), COUNTIF(EA18,"V")) -> 0 | EF18: =+EB18/$EF$3 -> 0.26608187 | EG18: =+$EF$3 -> 7.125 | EH18: =+$EF$3-EB18 -> 5.2291667 | EI18: =+EB18*$EI$3 -> 5.3438109 | EJ18: =+EB18+$EG$3 -> 1.8958333
A19: VALERO ENDARA DIANA LEOLENA | B19: 1759772500 | C19: VIDEO LLAMADA | F19: AGENTE | G19: PRESENCIAL | H19: VIDEO LLAMADA | I19: 09:00 - 15:00 | J19: 0.25 | K19: A | L19: VIDEO LLAMADA | M19: 08:00 -22:00 | N19: 0.54166667 | O19: A | P19: VIDEO LLAMADA | Q19: 10:00 - 22:00 | R19: 0.5 | S19: A | T19: VIDEO LLAMADA | U19: 10:00 - 23:00 | V19: 0.54166667 | W19: A | X19: VIDEO LLAMADA | Y19: 10:00 - 22:00 | Z19: 0.41666667 | AA19: A | AB19: VIDEO LLAMADA | AC19: 10:00 - 21:00 | AD19: 0.45833333 | AE19: A | AF19: VIDEO LLAMADA | AG19: 11:00 - 00:00 | AH19: 0.5 | AI19: A | AJ19: VIDEO LLAMADA | AK19: 0 | AL19: 0 | AM19: 0 | AN19: VIDEO LLAMADA | AR19: VIDEO LLAMADA | AV19: VIDEO LLAMADA | AZ19: VIDEO LLAMADA | BD19: VIDEO LLAMADA | BH19: VIDEO LLAMADA | BL19: VIDEO LLAMADA | BP19: VIDEO LLAMADA | BT19: VIDEO LLAMADA | BX19: VIDEO LLAMADA | CB19: VIDEO LLAMADA | CF19: VIDEO LLAMADA | CJ19: VIDEO LLAMADA | CN19: VIDEO LLAMADA | CR19: VIDEO LLAMADA | CV19: VIDEO LLAMADA | CZ19: VIDEO LLAMADA | DD19: VIDEO LLAMADA | DH19: VIDEO LLAMADA | DL19: VIDEO LLAMADA | DP19: VIDEO LLAMADA | DT19: VIDEO LLAMADA | DX19: VIDEO LLAMADA | EB19: =+SUM(J19,N19,R19,V19,Z19,AD19,AH19,AL19,AP19,AT19,AX19,BB19,BF19,BJ19,BN19,BR19,BV19,BZ19,CD19,CH19,CL19,CP19,CT19,CX19,DB19,DF19,DJ19,DV19,DN19,DR19,DZ19) -> 3.2083333 | EC19: =COUNTIF(H19:EA19,"AT") -> 0 | ED19: =SUM(COUNTIF(K19,"FI"), COUNTIF(O19,"FI"), COUNTIF(S19,"FI"), COUNTIF(W19,"FI"), COUNTIF(AA19,"FI"), COUNTIF(AE19,"FI"), COUNTIF(AI19,"FI"), COUNTIF(AM19,"FI"), COUNTIF(AQ19,"FI"), COUNTIF(AU19,"FI"), COUNTIF(AY19,"FI"), COUNTIF(BC19,"FI"), COUNTIF(BG19,"FI"), COUNTIF(BK19,"FI"), COUNTIF(BO19,"FI"), COUNTIF(BS19,"FI"), COUNTIF(BW19,"FI"), COUNTIF(CA19,"FI"), COUNTIF(CE19,"FI"), COUNTIF(CI19,"FI"), COUNTIF(CM19,"FI"), COUNTIF(CQ19,"FI"), COUNTIF(CU19,"FI"), COUNTIF(CY19,"FI"), COUNTIF(DC19,"FI"), COUNTIF(DG19,"FI"), COUNTIF(DK19,"FI"), COUNTIF(EA19,"FI")) -> 0 | EE19: =SUM(COUNTIF(K19,"V"), COUNTIF(O19,"V"), COUNTIF(S19,"V"), COUNTIF(W19,"V"), COUNTIF(AA19,"V"), COUNTIF(AE19,"V"), COUNTIF(AI19,"V"), COUNTIF(AM19,"V"), COUNTIF(AQ19,"V"), COUNTIF(AU19,"V"), COUNTIF(AY19,"V"), COUNTIF(BC19,"V"), COUNTIF(BG19,"V"), COUNTIF(BK19,"V"), COUNTIF(BO19,"V"), COUNTIF(BS19,"V"), COUNTIF(BW19,"V"), COUNTIF(CA19,"V"), COUNTIF(CE19,"V"), COUNTIF(CI19,"V"), COUNTIF(CM19,"V"), COUNTIF(CQ19,"V"), COUNTIF(CU19,"V"), COUNTIF(CY19,"V"), COUNTIF(DC19,"V"), COUNTIF(DG19,"V"), COUNTIF(DK19,"V"), COUNTIF(EA19,"V")) -> 0 | EF19: =+EB19/$EF$3 -> 0.4502924 | EG19: =$EF$4 -> 7.125 | EH19: =+$EF$4-EB19 -> 3.9166667 | EI19: =+EB19*$EI$3 -> 9.0433723 | EJ19: =+EB19+$EG$3 -> 3.2083333
A20: LEON DE LA CRUZ ANA LUCIA | B20: 1723878433 | C20: VIDEO LLAMADA | F20: AGENTE | G20: PRESENCIAL | H20: VIDEO LLAMADA | I20: 0 | J20: 0 | K20: 0 | L20: VIDEO LLAMADA | M20: 10:00 - 23:00 | N20: 0.54166667 | O20: A | P20: VIDEO LLAMADA | Q20: 10:00 - 22:00 | R20: 0.5 | S20: A | T20: VIDEO LLAMADA | U20: 07:00 - 22:00 | V20: 0.54166667 | W20: A | X20: VIDEO LLAMADA | Y20: 07:00 - 22:00 | Z20: 0.41666667 | AA20: A | AB20: VIDEO LLAMADA | AC20: 07:00 - 22:00 | AD20: 0.41666667 | AE20: A | AF20: VIDEO LLAMADA | AG20: 09:00 - 00:00 | AH20: 0.45833333 | AI20: A | AJ20: VIDEO LLAMADA | AK20: 0 | AL20: 0 | AM20: 0 | AN20: VIDEO LLAMADA | AR20: VIDEO LLAMADA | AV20: VIDEO LLAMADA | AZ20: VIDEO LLAMADA | BD20: VIDEO LLAMADA | BH20: VIDEO LLAMADA | BL20: VIDEO LLAMADA | BP20: VIDEO LLAMADA | BT20: VIDEO LLAMADA | BX20: VIDEO LLAMADA | CB20: VIDEO LLAMADA | CF20: VIDEO LLAMADA | CJ20: VIDEO LLAMADA | CN20: VIDEO LLAMADA | CR20: VIDEO LLAMADA | CV20: VIDEO LLAMADA | CZ20: VIDEO LLAMADA | DD20: VIDEO LLAMADA | DH20: VIDEO LLAMADA | DL20: VIDEO LLAMADA | DP20: VIDEO LLAMADA | DT20: VIDEO LLAMADA | DX20: VIDEO LLAMADA | EB20: =+SUM(J20,N20,R20,V20,Z20,AD20,AH20,AL20,AP20,AT20,AX20,BB20,BF20,BJ20,BN20,BR20,BV20,BZ20,CD20,CH20,CL20,CP20,CT20,CX20,DB20,DF20,DJ20,DV20,DN20,DR20,DZ20) -> 2.875 | EC20: =COUNTIF(H20:EA20,"AT") -> 0 | ED20: =SUM(COUNTIF(K20,"FI"), COUNTIF(O20,"FI"), COUNTIF(S20,"FI"), COUNTIF(W20,"FI"), COUNTIF(AA20,"FI"), COUNTIF(AE20,"FI"), COUNTIF(AI20,"FI"), COUNTIF(AM20,"FI"), COUNTIF(AQ20,"FI"), COUNTIF(AU20,"FI"), COUNTIF(AY20,"FI"), COUNTIF(BC20,"FI"), COUNTIF(BG20,"FI"), COUNTIF(BK20,"FI"), COUNTIF(BO20,"FI"), COUNTIF(BS20,"FI"), COUNTIF(BW20,"FI"), COUNTIF(CA20,"FI"), COUNTIF(CE20,"FI"), COUNTIF(CI20,"FI"), COUNTIF(CM20,"FI"), COUNTIF(CQ20,"FI"), COUNTIF(CU20,"FI"), COUNTIF(CY20,"FI"), COUNTIF(DC20,"FI"), COUNTIF(DG20,"FI"), COUNTIF(DK20,"FI"), COUNTIF(EA20,"FI")) -> 0 | EE20: =SUM(COUNTIF(K20,"V"), COUNTIF(O20,"V"), COUNTIF(S20,"V"), COUNTIF(W20,"V"), COUNTIF(AA20,"V"), COUNTIF(AE20,"V"), COUNTIF(AI20,"V"), COUNTIF(AM20,"V"), COUNTIF(AQ20,"V"), COUNTIF(AU20,"V"), COUNTIF(AY20,"V"), COUNTIF(BC20,"V"), COUNTIF(BG20,"V"), COUNTIF(BK20,"V"), COUNTIF(BO20,"V"), COUNTIF(BS20,"V"), COUNTIF(BW20,"V"), COUNTIF(CA20,"V"), COUNTIF(CE20,"V"), COUNTIF(CI20,"V"), COUNTIF(CM20,"V"), COUNTIF(CQ20,"V"), COUNTIF(CU20,"V"), COUNTIF(CY20,"V"), COUNTIF(DC20,"V"), COUNTIF(DG20,"V"), COUNTIF(DK20,"V"), COUNTIF(EA20,"V")) -> 0 | EF20: =+EB20/$EF$3 -> 0.40350877 | EG20: =$EF$4 -> 7.125 | EH20: =+$EF$4-EB20 -> 4.25 | EI20: =+EB20*$EI$3 -> 8.1038012 | EJ20: =+EB20+$EG$3 -> 2.875
A21: AMAGUA PANTOJA ARACELY PILAR | B21: 1755840962 | C21: VIDEO LLAMADA | F21: AGENTE | G21: PRESENCIAL | H21: VIDEO LLAMADA | I21: 14:00 - 21:00 | J21: 0.29166667 | K21: A | L21: VIDEO LLAMADA | M21: 07:00 - 19:00 | N21: 0.5 | O21: A | P21: VIDEO LLAMADA | Q21: 08:00 - 00:00 | R21: 0.5 | S21: A | T21: VIDEO LLAMADA | U21: 09:00 - 19:00 | V21: 0.41666667 | W21: A | X21: VIDEO LLAMADA | Y21: 09:00 - 19:00 | Z21: 0.41666667 | AA21: A | AB21: VIDEO LLAMADA | AC21: 14:00 - 00:00 | AD21: 0.41666667 | AE21: A | AF21: VIDEO LLAMADA | AG21: 0 | AH21: 0 | AI21: 0 | AJ21: VIDEO LLAMADA | AK21: 09:00 - 21:00 | AL21: 0.5 | AM21: A | AN21: VIDEO LLAMADA | AR21: VIDEO LLAMADA | AV21: VIDEO LLAMADA | AZ21: VIDEO LLAMADA | BD21: VIDEO LLAMADA | BH21: VIDEO LLAMADA | BL21: VIDEO LLAMADA | BP21: VIDEO LLAMADA | BT21: VIDEO LLAMADA | BX21: VIDEO LLAMADA | CB21: VIDEO LLAMADA | CF21: VIDEO LLAMADA | CJ21: VIDEO LLAMADA | CN21: VIDEO LLAMADA | CR21: VIDEO LLAMADA | CV21: VIDEO LLAMADA | CZ21: VIDEO LLAMADA | DD21: VIDEO LLAMADA | DH21: VIDEO LLAMADA | DL21: VIDEO LLAMADA | DP21: VIDEO LLAMADA | DT21: VIDEO LLAMADA | DX21: VIDEO LLAMADA | EB21: =+SUM(J21,N21,R21,V21,Z21,AD21,AH21,AL21,AP21,AT21,AX21,BB21,BF21,BJ21,BN21,BR21,BV21,BZ21,CD21,CH21,CL21,CP21,CT21,CX21,DB21,DF21,DJ21,DV21,DN21,DR21,DZ21) -> 3.0416667 | EC21: =COUNTIF(H21:EA21,"AT") -> 0 | ED21: =SUM(COUNTIF(K21,"FI"), COUNTIF(O21,"FI"), COUNTIF(S21,"FI"), COUNTIF(W21,"FI"), COUNTIF(AA21,"FI"), COUNTIF(AE21,"FI"), COUNTIF(AI21,"FI"), COUNTIF(AM21,"FI"), COUNTIF(AQ21,"FI"), COUNTIF(AU21,"FI"), COUNTIF(AY21,"FI"), COUNTIF(BC21,"FI"), COUNTIF(BG21,"FI"), COUNTIF(BK21,"FI"), COUNTIF(BO21,"FI"), COUNTIF(BS21,"FI"), COUNTIF(BW21,"FI"), COUNTIF(CA21,"FI"), COUNTIF(CE21,"FI"), COUNTIF(CI21,"FI"), COUNTIF(CM21,"FI"), COUNTIF(CQ21,"FI"), COUNTIF(CU21,"FI"), COUNTIF(CY21,"FI"), COUNTIF(DC21,"FI"), COUNTIF(DG21,"FI"), COUNTIF(DK21,"FI"), COUNTIF(EA21,"FI")) -> 0 | EE21: =SUM(COUNTIF(K21,"V"), COUNTIF(O21,"V"), COUNTIF(S21,"V"), COUNTIF(W21,"V"), COUNTIF(AA21,"V"), COUNTIF(AE21,"V"), COUNTIF(AI21,"V"), COUNTIF(AM21,"V"), COUNTIF(AQ21,"V"), COUNTIF(AU21,"V"), COUNTIF(AY21,"V"), COUNTIF(BC21,"V"), COUNTIF(BG21,"V"), COUNTIF(BK21,"V"), COUNTIF(BO21,"V"), COUNTIF(BS21,"V"), COUNTIF(BW21,"V"), COUNTIF(CA21,"V"), COUNTIF(CE21,"V"), COUNTIF(CI21,"V"), COUNTIF(CM21,"V"), COUNTIF(CQ21,"V"), COUNTIF(CU21,"V"), COUNTIF(CY21,"V"), COUNTIF(DC21,"V"), COUNTIF(DG21,"V"), COUNTIF(DK21,"V"), COUNTIF(EA21,"V")) -> 0 | EF21: =+EB21/$EF$3 -> 0.42690058 | EG21: =$EF$4 -> 7.125 | EH21: =+$EF$4-EB21 -> 4.0833333 | EI21: =+EB21*$EI$3 -> 8.5735867 | EJ21: =+EB21+$EG$3 -> 3.0416667
A22: RODRIGUEZ BUSTAMANTE MARY ELIZA | B22: 1727104927 | C22: VIDEO LLAMADA | F22: AGENTE | G22: PRESENCIAL | H22: VIDEO LLAMADA | I22: 00:00 - 00:00 | J22: 0.375 | K22: A | L22: VIDEO LLAMADA | M22: 00:00 - 00:00 | N22: 0.375 | O22: A | P22: VIDEO LLAMADA | Q22: 0:00:00 - 00:00 | R22: 0.375 | S22: A | T22: VIDEO LLAMADA | U22: 00:00 - 00:00 | V22: 0.375 | W22: A | X22: VIDEO LLAMADA | Y22: 00:00 - 00:00 | Z22: 0.375 | AA22: A | AB22: VIDEO LLAMADA | AC22: 00:00 - 00:00 | AD22: 0.375 | AE22: A | AF22: VIDEO LLAMADA | AG22: 00:00 - 08:00 | AH22: 0.33333333 | AI22: A | AJ22: VIDEO LLAMADA | AK22: 0 | AL22: 0 | AM22: 0 | AN22: VIDEO LLAMADA | AR22: VIDEO LLAMADA | AV22: VIDEO LLAMADA | AZ22: VIDEO LLAMADA | BD22: VIDEO LLAMADA | BH22: VIDEO LLAMADA | BL22: VIDEO LLAMADA | BP22: VIDEO LLAMADA | BT22: VIDEO LLAMADA | BX22: VIDEO LLAMADA | CB22: VIDEO LLAMADA | CF22: VIDEO LLAMADA | CJ22: VIDEO LLAMADA | CN22: VIDEO LLAMADA | CR22: VIDEO LLAMADA | CV22: VIDEO LLAMADA | CZ22: VIDEO LLAMADA | DD22: VIDEO LLAMADA | DH22: VIDEO LLAMADA | DL22: VIDEO LLAMADA | DP22: VIDEO LLAMADA | DT22: VIDEO LLAMADA | DX22: VIDEO LLAMADA | EB22: =+SUM(J22,N22,R22,V22,Z22,AD22,AH22,AL22,AP22,AT22,AX22,BB22,BF22,BJ22,BN22,BR22,BV22,BZ22,CD22,CH22,CL22,CP22,CT22,CX22,DB22,DF22,DJ22,DV22,DN22,DR22,DZ22) -> 2.5833333 | EC22: =COUNTIF(H22:EA22,"AT") -> 0 | ED22: =SUM(COUNTIF(K22,"FI"), COUNTIF(O22,"FI"), COUNTIF(S22,"FI"), COUNTIF(W22,"FI"), COUNTIF(AA22,"FI"), COUNTIF(AE22,"FI"), COUNTIF(AI22,"FI"), COUNTIF(AM22,"FI"), COUNTIF(AQ22,"FI"), COUNTIF(AU22,"FI"), COUNTIF(AY22,"FI"), COUNTIF(BC22,"FI"), COUNTIF(BG22,"FI"), COUNTIF(BK22,"FI"), COUNTIF(BO22,"FI"), COUNTIF(BS22,"FI"), COUNTIF(BW22,"FI"), COUNTIF(CA22,"FI"), COUNTIF(CE22,"FI"), COUNTIF(CI22,"FI"), COUNTIF(CM22,"FI"), COUNTIF(CQ22,"FI"), COUNTIF(CU22,"FI"), COUNTIF(CY22,"FI"), COUNTIF(DC22,"FI"), COUNTIF(DG22,"FI"), COUNTIF(DK22,"FI"), COUNTIF(EA22,"FI")) -> 0 | EE22: =SUM(COUNTIF(K22,"V"), COUNTIF(O22,"V"), COUNTIF(S22,"V"), COUNTIF(W22,"V"), COUNTIF(AA22,"V"), COUNTIF(AE22,"V"), COUNTIF(AI22,"V"), COUNTIF(AM22,"V"), COUNTIF(AQ22,"V"), COUNTIF(AU22,"V"), COUNTIF(AY22,"V"), COUNTIF(BC22,"V"), COUNTIF(BG22,"V"), COUNTIF(BK22,"V"), COUNTIF(BO22,"V"), COUNTIF(BS22,"V"), COUNTIF(BW22,"V"), COUNTIF(CA22,"V"), COUNTIF(CE22,"V"), COUNTIF(CI22,"V"), COUNTIF(CM22,"V"), COUNTIF(CQ22,"V"), COUNTIF(CU22,"V"), COUNTIF(CY22,"V"), COUNTIF(DC22,"V"), COUNTIF(DG22,"V"), COUNTIF(DK22,"V"), COUNTIF(EA22,"V")) -> 0 | EF22: =+EB22/$EF$3 -> 0.3625731 | EG22: =$EF$4 -> 7.125 | EH22: =+$EF$4-EB22 -> 4.5416667 | EI22: =+EB22*$EI$3 -> 7.2816764 | EJ22: =+EB22+$EG$3 -> 2.5833333
A23: CASA SANCHEZ GENESIS ALEJANDRA | B23: 1728879139 | C23: VIDEO LLAMADA | F23: AGENTE | G23: PRESENCIAL | H23: VIDEO LLAMADA | I23: 07:00 - 14:00 | J23: 0.29166667 | K23: A | L23: VIDEO LLAMADA | M23: 10:00 - 22:00 | N23: 0.5 | O23: A | P23: VIDEO LLAMADA | Q23: 07:00 - 18:00 | R23: 0.45833333 | S23: A | T23: VIDEO LLAMADA | U23: 10:00 - 00:00 | V23: 0.5 | W23: A | X23: VIDEO LLAMADA | Y23: 10:00 - 00:00 | Z23: 0.41666667 | AA23: A | AB23: VIDEO LLAMADA | AC23: 10:00 - 20:00 | AD23: 0.41666667 | AE23: A | AF23: VIDEO LLAMADA | AG23: 0 | AH23: 0 | AI23: 0 | AJ23: VIDEO LLAMADA | AK23: 00:00 - 00:00 | AL23: 0.41666667 | AM23: A | AN23: VIDEO LLAMADA | AR23: VIDEO LLAMADA | AV23: VIDEO LLAMADA | AZ23: VIDEO LLAMADA | BD23: VIDEO LLAMADA | BH23: VIDEO LLAMADA | BL23: VIDEO LLAMADA | BP23: VIDEO LLAMADA | BT23: VIDEO LLAMADA | BX23: VIDEO LLAMADA | CB23: VIDEO LLAMADA | CF23: VIDEO LLAMADA | CJ23: VIDEO LLAMADA | CN23: VIDEO LLAMADA | CR23: VIDEO LLAMADA | CV23: VIDEO LLAMADA | CZ23: VIDEO LLAMADA | DD23: VIDEO LLAMADA | DH23: VIDEO LLAMADA | DL23: VIDEO LLAMADA | DP23: VIDEO LLAMADA | DT23: VIDEO LLAMADA | DX23: VIDEO LLAMADA | EB23: =+SUM(J23,N23,R23,V23,Z23,AD23,AH23,AL23,AP23,AT23,AX23,BB23,BF23,BJ23,BN23,BR23,BV23,BZ23,CD23,CH23,CL23,CP23,CT23,CX23,DB23,DF23,DJ23,DV23,DN23,DR23,DZ23) -> 3 | EC23: =COUNTIF(H23:EA23,"AT") -> 0 | ED23: =SUM(COUNTIF(K23,"FI"), COUNTIF(O23,"FI"), COUNTIF(S23,"FI"), COUNTIF(W23,"FI"), COUNTIF(AA23,"FI"), COUNTIF(AE23,"FI"), COUNTIF(AI23,"FI"), COUNTIF(AM23,"FI"), COUNTIF(AQ23,"FI"), COUNTIF(AU23,"FI"), COUNTIF(AY23,"FI"), COUNTIF(BC23,"FI"), COUNTIF(BG23,"FI"), COUNTIF(BK23,"FI"), COUNTIF(BO23,"FI"), COUNTIF(BS23,"FI"), COUNTIF(BW23,"FI"), COUNTIF(CA23,"FI"), COUNTIF(CE23,"FI"), COUNTIF(CI23,"FI"), COUNTIF(CM23,"FI"), COUNTIF(CQ23,"FI"), COUNTIF(CU23,"FI"), COUNTIF(CY23,"FI"), COUNTIF(DC23,"FI"), COUNTIF(DG23,"FI"), COUNTIF(DK23,"FI"), COUNTIF(EA23,"FI")) -> 0 | EE23: =SUM(COUNTIF(K23,"V"), COUNTIF(O23,"V"), COUNTIF(S23,"V"), COUNTIF(W23,"V"), COUNTIF(AA23,"V"), COUNTIF(AE23,"V"), COUNTIF(AI23,"V"), COUNTIF(AM23,"V"), COUNTIF(AQ23,"V"), COUNTIF(AU23,"V"), COUNTIF(AY23,"V"), COUNTIF(BC23,"V"), COUNTIF(BG23,"V"), COUNTIF(BK23,"V"), COUNTIF(BO23,"V"), COUNTIF(BS23,"V"), COUNTIF(BW23,"V"), COUNTIF(CA23,"V"), COUNTIF(CE23,"V"), COUNTIF(CI23,"V"), COUNTIF(CM23,"V"), COUNTIF(CQ23,"V"), COUNTIF(CU23,"V"), COUNTIF(CY23,"V"), COUNTIF(DC23,"V"), COUNTIF(DG23,"V"), COUNTIF(DK23,"V"), COUNTIF(EA23,"V")) -> 0 | EF23: =+EB23/$EF$3 -> 0.42105263 | EG23: =$EF$4 -> 7.125 | EH23: =+$EF$4-EB23 -> 4.125 | EI23: =+EB23*$EI$3 -> 8.4561404 | EJ23: =+EB23+$EG$3 -> 3
A24: ANDREA JACQUELINE QUIJIJE QUIJIJE | B24: 1751400308 | C24: VIDEO LLAMADA | H24: VIDEO LLAMADA | I24: 15:00 - 22:00 | J24: 0.29166667 | K24: 0 | L24: VIDEO LLAMADA | M24: 07:00 - 00:00 | N24: 0.54166667 | O24: A | P24: VIDEO LLAMADA | Q24: 07:00 - 22:00 | R24: 0.5 | S24: A | T24: VIDEO LLAMADA | U24: 07:00 - 21:00 | V24: 0.45833333 | W24: A | X24: VIDEO LLAMADA | Y24: 07:00 - 21:00 | Z24: 0.45833333 | AA24: A | AB24: VIDEO LLAMADA | AC24: 07:00 - 22:00 | AD24: 0.41666667 | AE24: A | AF24: VIDEO LLAMADA | AG24: 0 | AH24: 0 | AI24: 0 | AJ24: VIDEO LLAMADA | AK24: 10:00 - 22:00 | AL24: 0.5 | AM24: A | AN24: VIDEO LLAMADA | AR24: VIDEO LLAMADA | AV24: VIDEO LLAMADA | AZ24: VIDEO LLAMADA | BD24: VIDEO LLAMADA | BH24: VIDEO LLAMADA | BL24: VIDEO LLAMADA | BP24: VIDEO LLAMADA | BT24: VIDEO LLAMADA | BX24: VIDEO LLAMADA | CB24: VIDEO LLAMADA | CF24: VIDEO LLAMADA | CJ24: VIDEO LLAMADA | CN24: VIDEO LLAMADA | CR24: VIDEO LLAMADA | CV24: VIDEO LLAMADA | CZ24: VIDEO LLAMADA | DD24: VIDEO LLAMADA | DH24: VIDEO LLAMADA | DL24: VIDEO LLAMADA | DP24: VIDEO LLAMADA | DT24: VIDEO LLAMADA | DX24: VIDEO LLAMADA | EB24: =+SUM(J24,N24,R24,V24,Z24,AD24,AH24,AL24,AP24,AT24,AX24,BB24,BF24,BJ24,BN24,BR24,BV24,BZ24,CD24,CH24,CL24,CP24,CT24,CX24,DB24,DF24,DJ24,DV24,DN24,DR24,DZ24) -> 3.1666667 | EC24: =COUNTIF(H24:EA24,"AT") -> 0 | ED24: =SUM(COUNTIF(K24,"FI"), COUNTIF(O24,"FI"), COUNTIF(S24,"FI"), COUNTIF(W24,"FI"), COUNTIF(AA24,"FI"), COUNTIF(AE24,"FI"), COUNTIF(AI24,"FI"), COUNTIF(AM24,"FI"), COUNTIF(AQ24,"FI"), COUNTIF(AU24,"FI"), COUNTIF(AY24,"FI"), COUNTIF(BC24,"FI"), COUNTIF(BG24,"FI"), COUNTIF(BK24,"FI"), COUNTIF(BO24,"FI"), COUNTIF(BS24,"FI"), COUNTIF(BW24,"FI"), COUNTIF(CA24,"FI"), COUNTIF(CE24,"FI"), COUNTIF(CI24,"FI"), COUNTIF(CM24,"FI"), COUNTIF(CQ24,"FI"), COUNTIF(CU24,"FI"), COUNTIF(CY24,"FI"), COUNTIF(DC24,"FI"), COUNTIF(DG24,"FI"), COUNTIF(DK24,"FI"), COUNTIF(EA24,"FI")) -> 0 | EE24: =SUM(COUNTIF(K24,"V"), COUNTIF(O24,"V"), COUNTIF(S24,"V"), COUNTIF(W24,"V"), COUNTIF(AA24,"V"), COUNTIF(AE24,"V"), COUNTIF(AI24,"V"), COUNTIF(AM24,"V"), COUNTIF(AQ24,"V"), COUNTIF(AU24,"V"), COUNTIF(AY24,"V"), COUNTIF(BC24,"V"), COUNTIF(BG24,"V"), COUNTIF(BK24,"V"), COUNTIF(BO24,"V"), COUNTIF(BS24,"V"), COUNTIF(BW24,"V"), COUNTIF(CA24,"V"), COUNTIF(CE24,"V"), COUNTIF(CI24,"V"), COUNTIF(CM24,"V"), COUNTIF(CQ24,"V"), COUNTIF(CU24,"V"), COUNTIF(CY24,"V"), COUNTIF(DC24,"V"), COUNTIF(DG24,"V"), COUNTIF(DK24,"V"), COUNTIF(EA24,"V")) -> 0 | EF24: =+EB24/$EF$3 -> 0.44444444 | EG24: =$EF$4 -> 7.125 | EH24: =+$EF$4-EB24 -> 3.9583333 | EI24: =+EB24*$EI$3 -> 8.9259259 | EJ24: =+EB24+$EG$3 -> 3.1666667
A25: GARCIA LOOR VANESSA LISBETH | B25: 1315686541 | C25: VIDEO LLAMADA | H25: VIDEO LLAMADA | I25: 0 | J25: 0 | K25: 0 | L25: VIDEO LLAMADA | M25: 09:00 - 18:00 | N25: 0.375 | O25: A | P25: VIDEO LLAMADA | Q25: 09:00 - 18:00 | R25: 0.375 | S25: A | T25: VIDEO LLAMADA | U25: 09:00 - 18:00 | V25: 0.375 | W25: A | X25: VIDEO LLAMADA | Y25: 09:00 - 18:00 | Z25: 0.375 | AA25: A | AB25: VIDEO LLAMADA | AC25: 09:00 - 18:00 | AD25: 0.375 | AE25: A | AF25: VIDEO LLAMADA | AG25: 0 | AH25: 0 | AI25: 0 | AJ25: VIDEO LLAMADA | AK25: 0 | AL25: 0 | AM25: 0 | AN25: VIDEO LLAMADA | AR25: VIDEO LLAMADA | AV25: VIDEO LLAMADA | AZ25: VIDEO LLAMADA | BD25: VIDEO LLAMADA | BH25: VIDEO LLAMADA | BL25: VIDEO LLAMADA | BP25: VIDEO LLAMADA | BT25: VIDEO LLAMADA | BX25: VIDEO LLAMADA | CB25: VIDEO LLAMADA | CF25: VIDEO LLAMADA | CJ25: VIDEO LLAMADA | CN25: VIDEO LLAMADA | CR25: VIDEO LLAMADA | CV25: VIDEO LLAMADA | CZ25: VIDEO LLAMADA | DD25: VIDEO LLAMADA | DH25: VIDEO LLAMADA | DL25: VIDEO LLAMADA | DP25: VIDEO LLAMADA | DT25: VIDEO LLAMADA | DX25: VIDEO LLAMADA | EB25: =+SUM(J25,N25,R25,V25,Z25,AD25,AH25,AL25,AP25,AT25,AX25,BB25,BF25,BJ25,BN25,BR25,BV25,BZ25,CD25,CH25,CL25,CP25,CT25,CX25,DB25,DF25,DJ25,DV25,DN25,DR25,DZ25) -> 1.875 | EC25: =COUNTIF(H25:EA25,"AT") -> 0 | ED25: =SUM(COUNTIF(K25,"FI"), COUNTIF(O25,"FI"), COUNTIF(S25,"FI"), COUNTIF(W25,"FI"), COUNTIF(AA25,"FI"), COUNTIF(AE25,"FI"), COUNTIF(AI25,"FI"), COUNTIF(AM25,"FI"), COUNTIF(AQ25,"FI"), COUNTIF(AU25,"FI"), COUNTIF(AY25,"FI"), COUNTIF(BC25,"FI"), COUNTIF(BG25,"FI"), COUNTIF(BK25,"FI"), COUNTIF(BO25,"FI"), COUNTIF(BS25,"FI"), COUNTIF(BW25,"FI"), COUNTIF(CA25,"FI"), COUNTIF(CE25,"FI"), COUNTIF(CI25,"FI"), COUNTIF(CM25,"FI"), COUNTIF(CQ25,"FI"), COUNTIF(CU25,"FI"), COUNTIF(CY25,"FI"), COUNTIF(DC25,"FI"), COUNTIF(DG25,"FI"), COUNTIF(DK25,"FI"), COUNTIF(EA25,"FI")) -> 0 | EE25: =SUM(COUNTIF(K25,"V"), COUNTIF(O25,"V"), COUNTIF(S25,"V"), COUNTIF(W25,"V"), COUNTIF(AA25,"V"), COUNTIF(AE25,"V"), COUNTIF(AI25,"V"), COUNTIF(AM25,"V"), COUNTIF(AQ25,"V"), COUNTIF(AU25,"V"), COUNTIF(AY25,"V"), COUNTIF(BC25,"V"), COUNTIF(BG25,"V"), COUNTIF(BK25,"V"), COUNTIF(BO25,"V"), COUNTIF(BS25,"V"), COUNTIF(BW25,"V"), COUNTIF(CA25,"V"), COUNTIF(CE25,"V"), COUNTIF(CI25,"V"), COUNTIF(CM25,"V"), COUNTIF(CQ25,"V"), COUNTIF(CU25,"V"), COUNTIF(CY25,"V"), COUNTIF(DC25,"V"), COUNTIF(DG25,"V"), COUNTIF(DK25,"V"), COUNTIF(EA25,"V")) -> 0 | EF25: =+EB25/$EF$3 -> 0.26315789 | EG25: =$EF$4 -> 7.125 | EH25: =+$EF$4-EB25 -> 5.25 | EI25: =+EB25*$EI$3 -> 5.2850877 | EJ25: =+EB25+$EG$3 -> 1.875
