Workbook
Name janet: #REF!

Sheet 26
A1: Nomenclatura
A2: ATRASO | B2: REPOSO
A3: FALTA | B3: PAGO POR SOPORTE O ADICIONAL | D3: VIERNES
A4: VACACIONES | B4: CAPACITACIÓN | E4: DIMENSIONAMIENTO | G4: 4 | H4: 3 | I4: 3 | J4: 3 | K4: 3 | L4: 3 | M4: 10 | N4: 20 | O4: 27 | P4: 29 | Q4: 30 | R4: 30 | S4: 30 | T4: 20 | U4: 23 | V4: 28 | W4: 28 | X4: 33 | Y4: 26 | Z4: 18 | AA4: 11 | AB4: 8 | AC4: 6 | AD4: 4 | AE4: =SUM(G4:AD4) -> 400 | AF4: =AE4/9 -> 44.444444
E5: 26 | G5: 00:00 - 01:00 | H5: 01:00 - 02:00 | I5: 02:00 - 03:00 | J5: 03:00 - 04:00 | K5: 04:00 - 05:00 | L5: 05:00 - 06:00 | M5: 06:00 - 07:00 | N5: 07:00 - 08:00 | O5: 08:00 - 09:00 | P5: 09:00 - 10:00 | Q5: 10:00 - 11:00 | R5: 11:00 - 12:00 | S5: 12:00 - 13:00 | T5: 13:00 - 14:00 | U5: 14:00 - 15:00 | V5: 15:00 - 16:00 | W5: 16:00 - 17:00 | X5: 17:00 - 18:00 | Y5: 18:00 - 19:00 | Z5: 19:00 - 20:00 | AA5: 20:00 - 21:00 | AB5: 21:00 - 22:00 | AC5: 22:00 - 23:00 | AD5: 23:00 - 00:00
G6: =G7-G4 -> 0 | H6: =H7-H4 -> 0 | I6: =I7-I4 -> 0 | J6: =J7-J4 -> 0 | K6: =K7-K4 -> 0 | L6: =L7-L4 -> 0 | M6: =M7-M4 -> 0 | N6: =N7-N4 -> 0 | ... AD6: =AD7-AD4 -> 0 | AE6: =SUM(G6:AD6) -> 0
A7: GESTIÓN | B7: USUARIO | C7: CONTACTO | D7: N° | E7: ASESORES | F7: HT | G7: =SUM(G8:G54) -> 4 | H7: =SUM(H8:H54) -> 3 | I7: =SUM(I8:I54) -> 3 | J7: =SUM(J8:J54) -> 3 | K7: =SUM(K8:K54) -> 3 | L7: =SUM(L8:L54) -> 3 | M7: =SUM(M8:M54) -> 10 | N7: =SUM(N8:N54) -> 20 | ... AD7: =SUM(AD8:AD54) -> 4 | AE7: =SUM(G7:AD7) -> 400 | AF7: HORARIO ASISTENCIA | AG7: FECHA
A8: UNIFICADA | B8: NTGLQUIS | D8: 0 | E8: QUISHPE SIERRA JOSE LUIS | F8: =SUM(G8:AD8) -> 4 | Y8: 1 | Z8: 1 | AA8: 1 | AB8: 1 | AE8: =SUM(G8:AD8) -> 4 | AF8: 18:00 A 22:00 | AG8: VIERNES 26 DE DICIEMBRE
A9: UNIFICADA | B9: NTGBACUC | C9: 999600729 | D9: 1 | E9: ACUÑA CAISAGUANO BYRON DANILO | F9: =SUM(G9:AD9) -> 11 | P9: 1 | Q9: 1 | R9: 1 | S9: 1 | X9: 1 | Y9: 1 | Z9: 1 | AA9: 1 | AB9: 1 | AC9: 1 | AD9: 1 | AE9: =SUM(G9:AD9) -> 11 | AF9: 09:00 A 13:00 - 17:00 A 00:00 | AG9: VIERNES 26 DE DICIEMBRE
A10: UNIFICADA | B10: NTGBALED | C10: 984098910 | D10: 2 | E10: ALENCASTRO DELGADO BRIGITTE SCARLET | F10: =SUM(G10:AD10) -> 13 | G10: 1 | H10: 1 | I10: 1 | J10: 1 | K10: 1 | L10: 1 | X10: 1 | Y10: 1 | Z10: 1 | AA10: 1 | AB10: 1 | AC10: 1 | AD10: 1 | AE10: =SUM(G10:AD10) -> 13 | AF10: 00:00 A 06:00 - 17:00 A 00:00 | AG10: VIERNES 26 DE DICIEMBRE
A11: UNIFICADA | B11: NTGBALEE | C11: 987983128 | D11: 3 | E11: ALENCASTRO DELGADO BRITANY SAMANTA | F11: =SUM(G11:AD11) -> 12 | O11: 1 | P11: 1 | Q11: 1 | R11: 1 | S11: 1 | U11: 1 | V11: 1 | W11: 1 | X11: 1 | Y11: 1 | Z11: 1 | AA11: 1 | AE11: =SUM(G11:AD11) -> 12 | AF11: 08:00 A 13:00 - 14:00 A 21:00 | AG11: VIERNES 26 DE DICIEMBRE
A12: UNIFICADA | B12: NTGOAQUO | D12: 4 | E12: AQUINO ORELLANA OTILDA FRANCISCA | F12: =SUM(G12:AD12) -> 12 | O12: 1 | P12: 1 | Q12: 1 | R12: 1 | S12: 1 | T12: 1 | V12: 1 | W12: 1 | X12: 1 | Y12: 1 | Z12: 1 | AA12: 1 | AE12: =SUM(G12:AD12) -> 12 | AF12: 08:00 A 14:00 - 15:00 A 21:00 | AG12: VIERNES 26 DE DICIEMBRE
A13: UNIFICADA | B13: NTGAARIF | C13: 998223732 | D13: 5 | E13: ARIAS FARINANGO ARIEL FERNANDO | F13: =SUM(G13:AD13) -> 12 | N13: 1 | O13: 1 | P13: 1 | Q13: 1 | R13: 1 | S13: 1 | U13: 1 | V13: 1 | W13: 1 | X13: 1 | Y13: 1 | Z13: 1 | AE13: =SUM(G13:AD13) -> 12 | AF13: 07:00 A 13:00 - 14:00 A 20:00 | AG13: VIERNES 26 DE DICIEMBRE
A14: UNIFICADA | B14: NTGIARIN | D14: 6 | E14: ARIAS NARVAEZ ISIS ESCARLETH | F14: =SUM(G14:AD14) -> 12 | M14: 1 | N14: 1 | O14: 1 | P14: 1 | Q14: 1 | R14: 1 | S14: 1 | U14: 1 | V14: 1 | W14: 1 | X14: 1 | Y14: 1 | AE14: =SUM(G14:AD14) -> 12 | AF14: 06:00 A 13:00 - 14:00 A 19:00 | AG14: VIERNES 26 DE DICIEMBRE
A15: UNIFICADA | B15: NTGJBELL | C15: 979044107 | D15: 7 | E15: BELTRAN VILLALBA JENNIFER MIGREY | F15: =SUM(G15:AD15) -> 12 | M15: 1 | N15: 1 | O15: 1 | P15: 1 | Q15: 1 | R15: 1 | S15: 1 | U15: 1 | V15: 1 | W15: 1 | X15: 1 | Y15: 1 | AE15: =SUM(G15:AD15) -> 12 | AF15: 06:00 A 13:00 - 14:00 A 19:00 | AG15: VIERNES 26 DE DICIEMBRE
A16: UNIFICADA | B16: NTGJBEND_1 | C16: 995545886 | D16: 8 | E16: BENALCAZAR DUARTE JEANNETH GISSELA | F16: =SUM(G16:AD16) -> 11 | N16: 1 | O16: 1 | P16: 1 | Q16: 1 | R16: 1 | S16: 1 | U16: 1 | V16: 1 | W16: 1 | X16: 1 | Y16: 1 | AE16: =SUM(G16:AD16) -> 11 | AF16: 07:00 A 13:00 - 14:00 A 19:00 | AG16: VIERNES 26 DE DICIEMBRE
A17: UNIFICADA | B17: NTGJBERO | C17: 968594141 | D17: 9 | E17: BERMEJO MALDONADO JONATHAN MAURICIO | F17: =SUM(G17:AD17) -> 12 | Q17: 1 | R17: 1 | S17: 1 | T17: 1 | U17: 1 | W17: 1 | X17: 1 | Y17: 1 | Z17: 1 | AA17: 1 | AB17: 1 | AC17: 1 | AE17: =SUM(G17:AD17) -> 12 | AF17: 10:00 A 15:00 - 16:00 A 23:00 | AG17: VIERNES 26 DE DICIEMBRE
A18: UNIFICADA | B18: NTGMCABU | D18: 10 | E18: CABASCANGO BUSE MARITZA ELIZABETH | F18: =SUM(G18:AD18) -> 11 | M18: 1 | N18: 1 | O18: 1 | P18: 1 | Q18: 1 | R18: 1 | S18: 1 | U18: 1 | V18: 1 | W18: 1 | X18: 1 | AE18: =SUM(G18:AD18) -> 11 | AF18: 06:00 A 13:00 - 14:00 A 18:00 | AG18: VIERNES 26 DE DICIEMBRE
A19: UNIFICADA | B19: NTGMCAR9 | C19: 989533877 | D19: 11 | E19: CARVAJAL RENGEL MARIA BELEN | F19: =SUM(G19:AD19) -> 0 | G19: V | H19: V | I19: V | J19: V | K19: V | L19: V | M19: V | N19: V | O19: V | P19: V | Q19: V | R19: V | S19: V | T19: V | U19: V | V19: V | W19: V | X19: V | Y19: V | Z19: V | AA19: V | AB19: V | AC19: V | AD19: V | AE19: =SUM(G19:AD19) -> 0 | AF19: VACACIONES | AG19: VIERNES 26 DE DICIEMBRE
A20: UNIFICADA | B20: NTGTCHII | C20: 997829699 | D20: 12 | E20: CHINGA PITIUR TATIANA LIZBETH | F20: =SUM(G20:AD20) -> 12 | R20: 1 | S20: 1 | T20: 1 | U20: 1 | V20: 1 | W20: 1 | X20: 1 | Y20: 1 | Z20: 1 | AA20: 1 | AB20: 1 | AC20: 1 | AE20: =SUM(G20:AD20) -> 12 | AF20: 11:00 A 23:00 | AG20: VIERNES 26 DE DICIEMBRE
A21: UNIFICADA | B21: NTGCCOLT | D21: 13 | E21: COLCHA TOAPANTA CINTHYA VANESSA | F21: =SUM(G21:AD21) -> 7 | G21: 1 | Y21: 1 | Z21: 1 | AA21: 1 | AB21: 1 | AC21: 1 | AD21: 1 | AE21: =SUM(G21:AD21) -> 7 | AF21: 00:00 A 01:00 - 18:00 A 00:00 | AG21: VIERNES 26 DE DICIEMBRE
A22: UNIFICADA | B22: NTGADELN | C22: 996303208 | D22: 14 | E22: DEL CASTILLO MANCHENO ANDRES DARIO | F22: =SUM(G22:AD22) -> 11 | M22: 1 | N22: 1 | O22: 1 | P22: 1 | Q22: 1 | R22: 1 | T22: 1 | U22: 1 | V22: 1 | W22: 1 | X22: 1 | AE22: =SUM(G22:AD22) -> 11 | AF22: 06:00 A 12:00 - 13:00 A 18:00 | AG22: VIERNES 26 DE DICIEMBRE
A23: UNIFICADA | B23: NTGYGOMR | C23: 991837641 | D23: 15 | E23: GOMEZ ROSALES YANINA BELEN | F23: =SUM(G23:AD23) -> 6 | N23: 1 | O23: 1 | P23: 1 | Q23: 1 | R23: 1 | S23: 1 | AE23: =SUM(G23:AD23) -> 6 | AF23: 07:00 A 13:00 | AG23: VIERNES 26 DE DICIEMBRE
A24: UNIFICADA | B24: NTGCGUAH | C24: 985570860 | D24: 16 | E24: GUANOLUISA REMACHE CHRISTIAN ALEXANDER | F24: =SUM(G24:AD24) -> 11 | O24: 1 | P24: 1 | Q24: 1 | R24: 1 | S24: 1 | T24: 1 | U24: 1 | V24: 1 | X24: 1 | Y24: 1 | Z24: 1 | AE24: =SUM(G24:AD24) -> 11 | AF24: 08:00 A 16:00 - 17:00 A 20:00 | AG24: VIERNES 26 DE DICIEMBRE
A25: UNIFICADA | B25: NTGLJACC | C25: 961816449 | D25: 17 | E25: JACOME CAMACHO LUIS HUMBERTO | F25: =SUM(G25:AD25) -> 11 | M25: 1 | N25: 1 | O25: 1 | P25: 1 | Q25: 1 | R25: 1 | S25: 1 | U25: 1 | V25: 1 | W25: 1 | X25: 1 | AE25: =SUM(G25:AD25) -> 11 | AF25: 06:00 A 13:00 - 14:00 A 18:00 | AG25: VIERNES 26 DE DICIEMBRE
A26: UNIFICADA | B26: NTGMJIM0 | C26: 989858490 | D26: 18 | E26: JIMENEZ SILVA MIRIAN PAMELA | F26: =SUM(G26:AD26) -> 11 | M26: 1 | N26: 1 | O26: 1 | P26: 1 | Q26: 1 | R26: 1 | S26: 1 | T26: 1 | U26: 1 | W26: 1 | X26: 1 | AE26: =SUM(G26:AD26) -> 11 | AF26: 06:00 A 15:00 - 16:00 A 18:00 | AG26: VIERNES 26 DE DICIEMBRE
A27: UNIFICADA | B27: C | C27: 988957267 | D27: 19 | E27: LECHON SANDOVAL ERICK FERNANDO | F27: =SUM(G27:AD27) -> 11 | O27: 1 | P27: 1 | Q27: 1 | R27: 1 | S27: 1 | T27: 1 | U27: 1 | V27: 1 | X27: 1 | Y27: 1 | Z27: 1 | AE27: =SUM(G27:AD27) -> 11 | AF27: 08:00 A 16:00 - 17:00 A 20:00 | AG27: VIERNES 26 DE DICIEMBRE
A28: UNIFICADA | B28: NTGJMEN13 | D28: 20 | E28: MENDOZA PALACIOS JHON HENRY | F28: =SUM(G28:AD28) -> 11 | N28: 1 | O28: 1 | P28: 1 | Q28: 1 | R28: 1 | S28: 1 | T28: 1 | V28: 1 | W28: 1 | X28: 1 | Y28: 1 | AE28: =SUM(G28:AD28) -> 11 | AF28: 07:00 A 14:00 - 15:00 A 19:00 | AG28: VIERNES 26 DE DICIEMBRE
A29: UNIFICADA | B29: NTGJMOR53 | D29: 21 | E29: MORALES MARTINEZ JOSUE JAVIER | F29: =SUM(G29:AD29) -> 8 | T29: 1 | U29: 1 | V29: 1 | W29: 1 | X29: 1 | Y29: 1 | Z29: 1 | AA29: 1 | AE29: =SUM(G29:AD29) -> 8 | AF29: 13:00 A 21:00 | AG29: VIERNES 26 DE DICIEMBRE
A30: UNIFICADA | B30: NTGJMOR48 | C30: 962757006 | D30: 22 | E30: MORENO NORIEGA JORGE OSVALDO | F30: =SUM(G30:AD30) -> 12 | N30: 1 | O30: 1 | P30: 1 | Q30: 1 | R30: 1 | S30: 1 | T30: 1 | U30: 1 | V30: 1 | X30: 1 | Y30: 1 | Z30: 1 | AE30: =SUM(G30:AD30) -> 12 | AF30: 07:00 A 16:00 - 17:00 A 20:00 | AG30: VIERNES 26 DE DICIEMBRE
A31: UNIFICADA | B31: NTGTMORC | D31: 23 | E31: MOROCHO CALDERON TANIA DENISSE | F31: =SUM(G31:AD31) -> 11 | O31: 1 | P31: 1 | Q31: 1 | R31: 1 | T31: 1 | U31: 1 | V31: 1 | W31: 1 | X31: 1 | Y31: 1 | Z31: 1 | AE31: =SUM(G31:AD31) -> 11 | AF31: 08:00 A 12:00 - 13:00 A 20:00 | AG31: VIERNES 26 DE DICIEMBRE
A32: UNIFICADA | B32: NTGKNARM | C32: 995055956 | D32: 24 | E32: NARVAEZ MALDONADO KARLA JULIET | F32: =SUM(G32:AD32) -> 12 | N32: 1 | O32: 1 | P32: 1 | Q32: 1 | R32: 1 | S32: 1 | U32: 1 | V32: 1 | W32: 1 | X32: 1 | Y32: 1 | Z32: 1 | AE32: =SUM(G32:AD32) -> 12 | AF32: 07:00 A 13:00 - 14:00 A 20:00 | AG32: VIERNES 26 DE DICIEMBRE
A33: UNIFICADA | B33: NTGMPALR | D33: 25 | E33: PALOMO RAMIREZ MAYERLI RAQUEL | F33: =SUM(G33:AD33) -> 6 | N33: 1 | O33: 1 | P33: 1 | Q33: 1 | R33: 1 | S33: 1 | AE33: =SUM(G33:AD33) -> 6 | AF33: 07:00 A 13:00 | AG33: VIERNES 26 DE DICIEMBRE
A34: UNIFICADA | B34: NTGJQUI50 | D34: 26 | E34: QUISPE PALACIOS JOSELYN YADIRA | F34: =SUM(G34:AD34) -> 8 | T34: 1 | V34: 1 | W34: 1 | X34: 1 | Y34: 1 | Z34: 1 | AA34: 1 | AB34: 1 | AE34: =SUM(G34:AD34) -> 8 | AF34: 13:00 A 14:00 - 15:00 A 22:00 | AG34: VIERNES 26 DE DICIEMBRE
A35: UNIFICADA | B35: NTGEQUI6 | C35: 990489779 | D35: 27 | E35: QUISHPE SIERRA ESTEBAN IGNACIO | F35: =SUM(G35:AD35) -> 12 | M35: 1 | N35: 1 | O35: 1 | P35: 1 | Q35: 1 | R35: 1 | S35: 1 | U35: 1 | V35: 1 | W35: 1 | X35: 1 | Y35: 1 | AE35: =SUM(G35:AD35) -> 12 | AF35: 06:00 A 13:00 - 14:00 A 19:00 | AG35: VIERNES 26 DE DICIEMBRE
A36: UNIFICADA | B36: NTGRQUIV | C36: 981074073 | D36: 28 | E36: QUITIAQUEZ VELASCO RICHARD DAVID | F36: =SUM(G36:AD36) -> 11 | N36: 1 | O36: 1 | P36: 1 | Q36: 1 | R36: 1 | S36: 1 | T36: 1 | U36: 1 | W36: 1 | X36: 1 | Y36: 1 | AE36: =SUM(G36:AD36) -> 11 | AF36: 07:00 A 15:00 - 16:00 A 19:00 | AG36: VIERNES 26 DE DICIEMBRE
A37: UNIFICADA | B37: NTGCROMA | D37: 29 | E37: ROMERO CARRION CARLOS HUMBERTO | F37: =SUM(G37:AD37) -> 11 | M37: 1 | N37: 1 | O37: 1 | P37: 1 | Q37: 1 | R37: 1 | S37: 1 | U37: 1 | V37: 1 | W37: 1 | X37: 1 | AE37: =SUM(G37:AD37) -> 11 | AF37: 06:00 A 13:00 - 14:00 A 18:00 | AG37: VIERNES 26 DE DICIEMBRE
A38: UNIFICADA | B38: NTGKRUBB | D38: 30 | E38: RUBIO BOADA KAREN NICOLE | F38: =SUM(G38:AD38) -> 10 | N38: 1 | O38: 1 | P38: 1 | Q38: 1 | R38: 1 | S38: 1 | T38: 1 | V38: 1 | W38: 1 | X38: 1 | AE38: =SUM(G38:AD38) -> 10 | AF38: 07:00 A 14:00 - 15:00 A 18:00 | AG38: VIERNES 26 DE DICIEMBRE
A39: UNIFICADA | B39: NTGASAMU | C39: 962936744 | D39: 31 | E39: SAMPEDRO BUÑAY ANA MARIA | F39: =SUM(G39:AD39) -> 6 | G39: 1 | H39: 1 | I39: 1 | J39: 1 | K39: 1 | L39: 1 | AE39: =SUM(G39:AD39) -> 6 | AF39: 00:00 A 06:00 | AG39: VIERNES 26 DE DICIEMBRE
A40: UNIFICADA | B40: NTGDTUAA | D40: 32 | E40: TUAPANTA CHANATAXI DANILO JAVIER | F40: =SUM(G40:AD40) -> 10 | M40: 1 | N40: 1 | O40: 1 | P40: 1 | Q40: 1 | R40: 1 | S40: 1 | U40: 1 | V40: 1 | W40: 1 | AE40: =SUM(G40:AD40) -> 10 | AF40: 06:00 A 13:00 - 14:00 A 17:00 | AG40: VIERNES 26 DE DICIEMBRE
...

Sheet 27
A1: Nomenclatura
A2: ATRASO | B2: REPOSO
A3: FALTA | B3: PAGO POR SOPORTE O ADICIONAL | D3: SÁBADO
A4: VACACIONES | B4: CAPACITACIÓN | E4: DIMENSIONAMIENTO | G4: 4 | H4: 3 | I4: 3 | J4: 3 | K4: 3 | L4: 3 | M4: 9 | N4: 12 | O4: 17 | P4: 20 | Q4: 24 | R4: 24 | S4: 22 | T4: 21 | U4: 19 | V4: 16 | W4: 16 | X4: 16 | Y4: 14 | Z4: 12 | AA4: 13 | AB4: 10 | AC4: 6 | AD4: 4 | AE4: =SUM(G4:AD4) -> 294 | AF4: =AE4/9 -> 32.666667
E5: 27 | G5: 00:00 - 01:00 | H5: 01:00 - 02:00 | I5: 02:00 - 03:00 | J5: 03:00 - 04:00 | K5: 04:00 - 05:00 | L5: 05:00 - 06:00 | M5: 06:00 - 07:00 | N5: 07:00 - 08:00 | O5: 08:00 - 09:00 | P5: 09:00 - 10:00 | Q5: 10:00 - 11:00 | R5: 11:00 - 12:00 | S5: 12:00 - 13:00 | T5: 13:00 - 14:00 | U5: 14:00 - 15:00 | V5: 15:00 - 16:00 | W5: 16:00 - 17:00 | X5: 17:00 - 18:00 | Y5: 18:00 - 19:00 | Z5: 19:00 - 20:00 | AA5: 20:00 - 21:00 | AB5: 21:00 - 22:00 | AC5: 22:00 - 23:00 | AD5: 23:00 - 00:00
G6: =G7-G4 -> 0 | H6: =H7-H4 -> 0 | I6: =I7-I4 -> 0 | J6: =J7-J4 -> 0 | K6: =K7-K4 -> 0 | L6: =L7-L4 -> 0 | M6: =M7-M4 -> -1 | N6: =N7-N4 -> 0 | ... AD6: =AD7-AD4 -> -1 | AE6: =SUM(G6:AD6) -> -20
A7: GESTIÓN | B7: USUARIO | C7: CONTACTO | D7: N° | E7: ASESORES | F7: HT | G7: =SUM(G8:G54) -> 4 | H7: =SUM(H8:H54) -> 3 | I7: =SUM(I8:I54) -> 3 | J7: =SUM(J8:J54) -> 3 | K7: =SUM(K8:K54) -> 3 | L7: =SUM(L8:L54) -> 3 | M7: =SUM(M8:M54) -> 8 | N7: =SUM(N8:N54) -> 12 | ... AD7: =SUM(AD8:AD54) -> 3 | AE7: =SUM(G7:AD7) -> 274 | AF7: HORARIO ASISTENCIA | AG7: FECHA
A8: UNIFICADA | B8: NTGLQUIS | D8: 0 | E8: QUISHPE SIERRA JOSE LUIS | F8: =SUM(G8:AD8) -> 0 | AE8: =SUM(G8:AD8) -> 0 | AF8: LIBRE | AG8: SÁBADO 27 DE DICIEMBRE
A9: UNIFICADA | B9: NTGBACUC | C9: 999600729 | D9: 1 | E9: ACUÑA CAISAGUANO BYRON DANILO | F9: =SUM(G9:AD9) -> 12 | G9: 1 | H9: 1 | I9: 1 | J9: 1 | K9: 1 | L9: 1 | M9: 1 | Z9: 1 | AA9: 1 | AB9: 1 | AC9: 1 | AD9: 1 | AE9: =SUM(G9:AD9) -> 12 | AF9: 00:00 A 07:00 - 19:00 A 00:00 | AG9: SÁBADO 27 DE DICIEMBRE
A10: UNIFICADA | B10: NTGBALED | C10: 984098910 | D10: 2 | E10: ALENCASTRO DELGADO BRIGITTE SCARLET | F10: =SUM(G10:AD10) -> 7 | G10: 1 | H10: 1 | I10: 1 | J10: 1 | K10: 1 | L10: 1 | M10: 1 | AE10: =SUM(G10:AD10) -> 7 | AF10: 00:00 A 07:00 | AG10: SÁBADO 27 DE DICIEMBRE
A11: UNIFICADA | B11: NTGBALEE | C11: 987983128 | D11: 3 | E11: ALENCASTRO DELGADO BRITANY SAMANTA | F11: =SUM(G11:AD11) -> 11 | M11: 1 | N11: 1 | O11: 1 | P11: 1 | Q11: 1 | R11: 1 | S11: 1 | T11: 1 | U11: 1 | V11: 1 | W11: 1 | AE11: =SUM(G11:AD11) -> 11 | AF11: 06:00 A 17:00 | AG11: SÁBADO 27 DE DICIEMBRE
A12: UNIFICADA | B12: NTGOAQUO | D12: 4 | E12: AQUINO ORELLANA OTILDA FRANCISCA | F12: =SUM(G12:AD12) -> 13 | N12: 1 | O12: 1 | P12: 1 | Q12: 1 | R12: 1 | S12: 1 | T12: 1 | U12: 1 | W12: 1 | X12: 1 | Y12: 1 | Z12: 1 | AA12: 1 | AE12: =SUM(G12:AD12) -> 13 | AF12: 07:00 A 15:00 - 16:00 A 21:00 | AG12: SÁBADO 27 DE DICIEMBRE
A13: UNIFICADA | B13: NTGAARIF | C13: 998223732 | D13: 5 | E13: ARIAS FARINANGO ARIEL FERNANDO | F13: =SUM(G13:AD13) -> 11 | M13: 1 | N13: 1 | O13: 1 | P13: 1 | Q13: 1 | R13: 1 | S13: 1 | U13: 1 | V13: 1 | W13: 1 | X13: 1 | AE13: =SUM(G13:AD13) -> 11 | AF13: 06:00 A 13:00 - 14:00 A 18:00 | AG13: SÁBADO 27 DE DICIEMBRE
A14: UNIFICADA | B14: NTGIARIN | D14: 6 | E14: ARIAS NARVAEZ ISIS ESCARLETH | F14: =SUM(G14:AD14) -> 0 | G14: 0 | H14: 0 | I14: 0 | J14: 0 | K14: 0 | L14: 0 | M14: 0 | N14: 0 | O14: 0 | P14: 0 | Q14: 0 | R14: 0 | S14: 0 | T14: 0 | U14: 0 | V14: 0 | W14: 0 | X14: 0 | Y14: 0 | Z14: 0 | AA14: 0 | AB14: 0 | AC14: 0 | AD14: 0 | AE14: =SUM(G14:AD14) -> 0 | AF14: LIBRE | AG14: SÁBADO 27 DE DICIEMBRE
A15: UNIFICADA | B15: NTGJBELL | C15: 979044107 | D15: 7 | E15: BELTRAN VILLALBA JENNIFER MIGREY | F15: =SUM(G15:AD15) -> 0 | G15: 0 | H15: 0 | I15: 0 | J15: 0 | K15: 0 | L15: 0 | M15: 0 | N15: 0 | O15: 0 | P15: 0 | Q15: 0 | R15: 0 | S15: 0 | T15: 0 | U15: 0 | V15: 0 | W15: 0 | X15: 0 | Y15: 0 | Z15: 0 | AA15: 0 | AB15: 0 | AC15: 0 | AD15: 0 | AE15: =SUM(G15:AD15) -> 0 | AF15: LIBRE | AG15: SÁBADO 27 DE DICIEMBRE
A16: UNIFICADA | B16: NTGJBEND_1 | C16: 995545886 | D16: 8 | E16: BENALCAZAR DUARTE JEANNETH GISSELA | F16: =SUM(G16:AD16) -> 11 | N16: 1 | O16: 1 | P16: 1 | Q16: 1 | R16: 1 | S16: 1 | T16: 1 | U16: 1 | W16: 1 | X16: 1 | Y16: 1 | AE16: =SUM(G16:AD16) -> 11 | AF16: 07:00 A 15:00 - 16:00 A 19:00 | AG16: SÁBADO 27 DE DICIEMBRE
A17: UNIFICADA | B17: NTGJBERO | C17: 968594141 | D17: 9 | E17: BERMEJO MALDONADO JONATHAN MAURICIO | F17: =SUM(G17:AD17) -> 13 | N17: 1 | O17: 1 | P17: 1 | Q17: 1 | R17: 1 | S17: 1 | T17: 1 | U17: 1 | W17: 1 | X17: 1 | Y17: 1 | Z17: 1 | AA17: 1 | AE17: =SUM(G17:AD17) -> 13 | AF17: 07:00 A 15:00 - 16:00 A 21:00 | AG17: SÁBADO 27 DE DICIEMBRE
A18: UNIFICADA | B18: NTGMCABU | D18: 10 | E18: CABASCANGO BUSE MARITZA ELIZABETH | F18: =SUM(G18:AD18) -> 0 | G18: 0 | H18: 0 | I18: 0 | J18: 0 | K18: 0 | L18: 0 | M18: 0 | N18: 0 | O18: 0 | P18: 0 | Q18: 0 | R18: 0 | S18: 0 | T18: 0 | U18: 0 | V18: 0 | W18: 0 | X18: 0 | Y18: 0 | Z18: 0 | AA18: 0 | AB18: 0 | AC18: 0 | AD18: 0 | AE18: =SUM(G18:AD18) -> 0 | AF18: LIBRE | AG18: SÁBADO 27 DE DICIEMBRE
A19: UNIFICADA | B19: NTGMCAR9 | C19: 989533877 | D19: 11 | E19: CARVAJAL RENGEL MARIA BELEN | F19: =SUM(G19:AD19) -> 0 | G19: V | H19: V | I19: V | J19: V | K19: V | L19: V | M19: V | N19: V | O19: V | P19: V | Q19: V | R19: V | S19: V | T19: V | U19: V | V19: V | W19: V | X19: V | Y19: V | Z19: V | AA19: V | AB19: V | AC19: V | AD19: V | AE19: =SUM(G19:AD19) -> 0 | AF19: VACACIONES | AG19: SÁBADO 27 DE DICIEMBRE
A20: UNIFICADA | B20: NTGTCHII | C20: 997829699 | D20: 12 | E20: CHINGA PITIUR TATIANA LIZBETH | F20: =SUM(G20:AD20) -> 0 | G20: 0 | H20: 0 | I20: 0 | J20: 0 | K20: 0 | L20: 0 | M20: 0 | N20: 0 | O20: 0 | P20: 0 | Q20: 0 | R20: 0 | S20: 0 | T20: 0 | U20: 0 | V20: 0 | W20: 0 | X20: 0 | Y20: 0 | Z20: 0 | AA20: 0 | AB20: 0 | AC20: 0 | AD20: 0 | AE20: =SUM(G20:AD20) -> 0 | AF20: LIBRE | AG20: SÁBADO 27 DE DICIEMBRE
A21: UNIFICADA | B21: NTGCCOLT | D21: 13 | E21: COLCHA TOAPANTA CINTHYA VANESSA | F21: =SUM(G21:AD21) -> 9 | G21: 1 | H21: 1 | I21: 1 | J21: 1 | K21: 1 | L21: 1 | S21: 1 | T21: 1 | U21: 1 | V21: CLIENTES VIP | AE21: 17 | AF21: 00:00 A 06:00 A 12:00 A 23:00 | AG21: SÁBADO 27 DE DICIEMBRE
A22: UNIFICADA | B22: NTGADELN | C22: 996303208 | D22: 14 | E22: DEL CASTILLO MANCHENO ANDRES DARIO | F22: =SUM(G22:AD22) -> 11 | M22: 1 | N22: 1 | O22: 1 | P22: 1 | Q22: 1 | R22: 1 | S22: 1 | T22: 1 | U22: 1 | V22: 1 | W22: 1 | AE22: =SUM(G22:AD22) -> 11 | AF22: 06:00 A 17:00 | AG22: SÁBADO 27 DE DICIEMBRE
A23: UNIFICADA | B23: NTGYGOMR | C23: 991837641 | D23: 15 | E23: GOMEZ ROSALES YANINA BELEN | F23: =SUM(G23:AD23) -> 0 | G23: 0 | H23: 0 | I23: 0 | J23: 0 | K23: 0 | L23: 0 | M23: 0 | N23: 0 | O23: 0 | P23: 0 | Q23: 0 | R23: 0 | S23: 0 | T23: 0 | U23: 0 | V23: 0 | W23: 0 | X23: 0 | Y23: 0 | Z23: 0 | AA23: 0 | AB23: 0 | AC23: 0 | AD23: 0 | AE23: =SUM(G23:AD23) -> 0 | AF23: LIBRE | AG23: SÁBADO 27 DE DICIEMBRE
A24: UNIFICADA | B24: NTGCGUAH | C24: 985570860 | D24: 16 | E24: GUANOLUISA REMACHE CHRISTIAN ALEXANDER | F24: =SUM(G24:AD24) -> 0 | G24: 0 | H24: 0 | I24: 0 | J24: 0 | K24: 0 | L24: 0 | M24: 0 | N24: 0 | O24: 0 | P24: 0 | Q24: 0 | R24: 0 | S24: 0 | T24: 0 | U24: 0 | V24: 0 | W24: 0 | X24: 0 | Y24: 0 | Z24: 0 | AA24: 0 | AB24: 0 | AC24: 0 | AD24: 0 | AE24: =SUM(G24:AD24) -> 0 | AF24: LIBRE | AG24: SÁBADO 27 DE DICIEMBRE
A25: UNIFICADA | B25: NTGLJACC | C25: 961816449 | D25: 17 | E25: JACOME CAMACHO LUIS HUMBERTO | F25: =SUM(G25:AD25) -> 11 | M25: 1 | N25: 1 | O25: 1 | P25: 1 | Q25: 1 | R25: 1 | S25: 1 | T25: 1 | U25: 1 | V25: 1 | W25: 1 | AE25: =SUM(G25:AD25) -> 11 | AF25: 06:00 A 17:00 | AG25: SÁBADO 27 DE DICIEMBRE
A26: UNIFICADA | B26: NTGMJIM0 | C26: 989858490 | D26: 18 | E26: JIMENEZ SILVA MIRIAN PAMELA | F26: =SUM(G26:AD26) -> 4 | O26: 1 | P26: 1 | Q26: 1 | R26: 1 | AE26: =SUM(G26:AD26) -> 4 | AF26: 08:00 A 12:00 | AG26: SÁBADO 27 DE DICIEMBRE
A27: UNIFICADA | B27: NTGELECS | C27: 988957267 | D27: 19 | E27: LECHON SANDOVAL ERICK FERNANDO | F27: =SUM(G27:AD27) -> 13 | P27: 1 | Q27: 1 | R27: 1 | S27: 1 | T27: 1 | U27: 1 | V27: 1 | X27: 1 | Y27: 1 | Z27: 1 | AA27: 1 | AB27: 1 | AC27: 1 | AE27: =SUM(G27:AD27) -> 13 | AF27: 09:00 A 16:00 - 17:00 A 23:00 | AG27: SÁBADO 27 DE DICIEMBRE
A28: UNIFICADA | B28: NTGJMEN13 | D28: 20 | E28: MENDOZA PALACIOS JHON HENRY | F28: =SUM(G28:AD28) -> 11 | N28: 1 | O28: 1 | P28: 1 | Q28: 1 | R28: 1 | S28: 1 | T28: 1 | V28: 1 | W28: 1 | X28: 1 | Y28: 1 | AE28: =SUM(G28:AD28) -> 11 | AF28: 07:00 A 14:00 - 15:00 A 19:00 | AG28: SÁBADO 27 DE DICIEMBRE
A29: UNIFICADA | B29: NTGJMOR53 | D29: 21 | E29: MORALES MARTINEZ JOSUE JAVIER | F29: =SUM(G29:AD29) -> 10 | U29: 1 | V29: 1 | W29: 1 | X29: 1 | Y29: 1 | Z29: 1 | AA29: 1 | AB29: 1 | AC29: 1 | AD29: 1 | AE29: =SUM(G29:AD29) -> 10 | AF29: 14:00 A 00:00 | AG29: SÁBADO 27 DE DICIEMBRE
A30: UNIFICADA | B30: NTGJMOR48 | C30: 962757006 | D30: 22 | E30: MORENO NORIEGA JORGE OSVALDO | F30: =SUM(G30:AD30) -> 13 | O30: 1 | P30: 1 | Q30: 1 | R30: 1 | S30: 1 | T30: 1 | U30: 1 | V30: 1 | X30: 1 | Y30: 1 | Z30: 1 | AA30: 1 | AB30: 1 | AE30: =SUM(G30:AD30) -> 13 | AF30: 08:00 A 16:00 - 17:00 A 22:00 | AG30: SÁBADO 27 DE DICIEMBRE
A31: UNIFICADA | B31: NTGTMORC | D31: 23 | E31: MOROCHO CALDERON TANIA DENISSE | F31: =SUM(G31:AD31) -> 0 | G31: 0 | H31: 0 | I31: 0 | J31: 0 | K31: 0 | L31: 0 | M31: 0 | N31: 0 | O31: 0 | P31: 0 | Q31: 0 | R31: 0 | S31: 0 | T31: 0 | U31: 0 | V31: 0 | W31: 0 | X31: 0 | Y31: 0 | Z31: 0 | AA31: 0 | AB31: 0 | AC31: 0 | AD31: 0 | AE31: =SUM(G31:AD31) -> 0 | AF31: LIBRE | AG31: SÁBADO 27 DE DICIEMBRE
A32: UNIFICADA | B32: NTGKNARM | C32: 995055956 | D32: 24 | E32: NARVAEZ MALDONADO KARLA JULIET | F32: =SUM(G32:AD32) -> 10 | M32: FI | N32: 1 | O32: 1 | P32: 1 | Q32: 1 | R32: 1 | S32: 1 | U32: 1 | V32: 1 | W32: 1 | X32: 1 | AE32: =SUM(G32:AD32) -> 10 | AF32: 06:00 A 13:00 - 14:00 A 18:00 | AG32: SÁBADO 27 DE DICIEMBRE
A33: UNIFICADA | B33: NTGMPALR | D33: 25 | E33: PALOMO RAMIREZ MAYERLI RAQUEL | F33: =SUM(G33:AD33) -> 0 | G33: 0 | H33: 0 | I33: 0 | J33: 0 | K33: 0 | L33: 0 | M33: 0 | N33: 0 | O33: 0 | P33: 0 | Q33: 0 | R33: 0 | S33: 0 | T33: 0 | U33: 0 | V33: 0 | W33: 0 | X33: 0 | Y33: 0 | Z33: 0 | AA33: 0 | AB33: 0 | AC33: 0 | AD33: 0 | AE33: =SUM(G33:AD33) -> 0 | AF33: LIBRE | AG33: SÁBADO 27 DE DICIEMBRE
A34: UNIFICADA | B34: NTGJQUI50 | D34: 26 | E34: QUISPE PALACIOS JOSELYN YADIRA | F34: =SUM(G34:AD34) -> 13 | P34: 1 | Q34: 1 | R34: 1 | S34: 1 | T34: 1 | U34: 1 | V34: 1 | X34: 1 | Y34: 1 | Z34: 1 | AA34: 1 | AB34: 1 | AC34: 1 | AE34: =SUM(G34:AD34) -> 13 | AF34: 09:00 A 16:00 - 17:00 A 23:00 | AG34: SÁBADO 27 DE DICIEMBRE
A35: UNIFICADA | B35: NTGEQUI6 | C35: 990489779 | D35: 27 | E35: QUISHPE SIERRA ESTEBAN IGNACIO | F35: =SUM(G35:AD35) -> 0 | Y35: FI | Z35: FI | AA35: FI | AB35: FI | AC35: FI | AD35: FI | AE35: =SUM(G35:AD35) -> 0 | AF35: 18:00 A 00:00 | AG35: SÁBADO 27 DE DICIEMBRE
A36: UNIFICADA | B36: NTGRQUIV | C36: 981074073 | D36: 28 | E36: QUITIAQUEZ VELASCO RICHARD DAVID | F36: =SUM(G36:AD36) -> 12 | M36: 1 | N36: 1 | O36: 1 | P36: 1 | Q36: 1 | R36: 1 | S36: 1 | T36: 1 | U36: 1 | V36: 1 | W36: 1 | X36: 1 | AE36: =SUM(G36:AD36) -> 12 | AF36: 06:00 A 18:00 | AG36: SÁBADO 27 DE DICIEMBRE
A37: UNIFICADA | B37: NTGCROMA | D37: 29 | E37: ROMERO CARRION CARLOS HUMBERTO | F37: =SUM(G37:AD37) -> 11 | M37: 1 | N37: 1 | O37: 1 | P37: 1 | Q37: 1 | R37: 1 | T37: 1 | U37: 1 | V37: 1 | W37: 1 | X37: 1 | AE37: =SUM(G37:AD37) -> 11 | AF37: 06:00 A 12:00 - 13:00 A 18:00 | AG37: SÁBADO 27 DE DICIEMBRE
A38: UNIFICADA | B38: NTGKRUBB | D38: 30 | E38: RUBIO BOADA KAREN NICOLE | F38: =SUM(G38:AD38) -> 11 | N38: 1 | O38: 1 | P38: 1 | Q38: 1 | R38: 1 | S38: 1 | T38: 1 | U38: 1 | V38: 1 | W38: 1 | X38: 1 | AE38: =SUM(G38:AD38) -> 11 | AF38: 07:00 A 18:00 | AG38: SÁBADO 27 DE DICIEMBRE
A39: UNIFICADA | B39: NTGASAMU | C39: 962936744 | D39: 31 | E39: SAMPEDRO BUÑAY ANA MARIA | F39: =SUM(G39:AD39) -> 6 | Y39: 1 | Z39: 1 | AA39: 1 | AB39: 1 | AC39: 1 | AD39: 1 | AE39: =SUM(G39:AD39) -> 6 | AF39: 18:00 A 00:00 | AG39: SÁBADO 27 DE DICIEMBRE
A40: UNIFICADA | B40: NTGDTUAA | D40: 32 | E40: TUAPANTA CHANATAXI DANILO JAVIER | F40: =SUM(G40:AD40) -> 0 | G40: 0 | H40: 0 | I40: 0 | J40: 0 | K40: 0 | L40: 0 | M40: 0 | N40: 0 | O40: 0 | P40: 0 | Q40: 0 | R40: 0 | S40: 0 | T40: 0 | U40: 0 | V40: 0 | W40: 0 | X40: 0 | Y40: 0 | Z40: 0 | AA40: 0 | AB40: 0 | AC40: 0 | AD40: 0 | AE40: =SUM(G40:AD40) -> 0 | AF40: LIBRE | AG40: SÁBADO 27 DE DICIEMBRE
...

Sheet 28
A1: Nomenclatura
A2: ATRASO | B2: REPOSO
A3: FALTA | B3: PAGO POR SOPORTE O ADICIONAL | D3: DOMINGO
A4: VACACIONES | B4: CAPACITACIÓN | E4: DIMENSIONAMIENTO | G4: 4 | H4: 3 | I4: 3 | J4: 3 | K4: 3 | L4: 3 | M4: 7 | N4: 10 | O4: 15 | P4: 18 | Q4: 22 | R4: 22 | S4: 20 | T4: 19 | U4: 17 | V4: 14 | W4: 14 | X4: 14 | Y4: 12 | Z4: 10 | AA4: 11 | AB4: 8 | AC4: 5 | AD4: 4 | AE4: =SUM(G4:AD4) -> 261 | AF4: =AE4/9 -> 29
E5: 28 | G5: 00:00 - 01:00 | H5: 01:00 - 02:00 | I5: 02:00 - 03:00 | J5: 03:00 - 04:00 | K5: 04:00 - 05:00 | L5: 05:00 - 06:00 | M5: 06:00 - 07:00 | N5: 07:00 - 08:00 | O5: 08:00 - 09:00 | P5: 09:00 - 10:00 | Q5: 10:00 - 11:00 | R5: 11:00 - 12:00 | S5: 12:00 - 13:00 | T5: 13:00 - 14:00 | U5: 14:00 - 15:00 | V5: 15:00 - 16:00 | W5: 16:00 - 17:00 | X5: 17:00 - 18:00 | Y5: 18:00 - 19:00 | Z5: 19:00 - 20:00 | AA5: 20:00 - 21:00 | AB5: 21:00 - 22:00 | AC5: 22:00 - 23:00 | AD5: 23:00 - 00:00
G6: =G7-G4 -> -1 | H6: =H7-H4 -> 0 | I6: =I7-I4 -> 0 | J6: =J7-J4 -> 0 | K6: =K7-K4 -> 0 | L6: =L7-L4 -> 0 | M6: =M7-M4 -> 0 | N6: =N7-N4 -> 0 | ... AD6: =AD7-AD4 -> 0 | AE6: =SUM(G6:AD6) -> 15
A7: GESTIÓN | B7: USUARIO | C7: CONTACTO | D7: N° | E7: ASESORES | F7: HT | G7: =SUM(G8:G54) -> 3 | H7: =SUM(H8:H54) -> 3 | I7: =SUM(I8:I54) -> 3 | J7: =SUM(J8:J54) -> 3 | K7: =SUM(K8:K54) -> 3 | L7: =SUM(L8:L54) -> 3 | M7: =SUM(M8:M54) -> 7 | N7: =SUM(N8:N54) -> 10 | ... AD7: =SUM(AD8:AD54) -> 4 | AE7: =SUM(G7:AD7) -> 276 | AF7: HORARIO ASISTENCIA | AG7: FECHA
A8: UNIFICADA | B8: NTGLQUIS | D8: 0 | E8: QUISHPE SIERRA JOSE LUIS | F8: =SUM(G8:AD8) -> 0 | G8: 0 | H8: 0 | I8: 0 | J8: 0 | K8: 0 | L8: 0 | M8: 0 | N8: 0 | O8: 0 | P8: 0 | Q8: 0 | R8: 0 | S8: 0 | T8: 0 | U8: 0 | V8: 0 | W8: 0 | X8: 0 | Y8: 0 | Z8: 0 | AA8: 0 | AB8: 0 | AC8: 0 | AD8: 0 | AE8: =SUM(G8:AD8) -> 0 | AF8: LIBRE | AG8: DOMINGO 28 DE DICIEMBRE
A9: UNIFICADA | B9: NTGBACUC | C9: 999600729 | D9: 1 | E9: ACUÑA CAISAGUANO BYRON DANILO | F9: =SUM(G9:AD9) -> 6 | G9: 1 | H9: 1 | I9: 1 | J9: 1 | K9: 1 | L9: 1 | AE9: =SUM(G9:AD9) -> 6 | AF9: 00:00 - 06:00 | AG9: DOMINGO 28 DE DICIEMBRE
A10: UNIFICADA | B10: NTGBALED | C10: 984098910 | D10: 2 | E10: ALENCASTRO DELGADO BRIGITTE SCARLET | F10: =SUM(G10:AD10) -> 7 | X10: 1 | Y10: 1 | Z10: 1 | AA10: 1 | AB10: 1 | AC10: 1 | AD10: 1 | AE10: =SUM(G10:AD10) -> 7 | AF10: 17:00 A 00:00 | AG10: DOMINGO 28 DE DICIEMBRE
A11: UNIFICADA | B11: NTGBALEE | C11: 987983128 | D11: 3 | E11: ALENCASTRO DELGADO BRITANY SAMANTA | F11: =SUM(G11:AD11) -> 12 | P11: 1 | Q11: 1 | R11: 1 | S11: 1 | T11: 1 | U11: 1 | V11: 1 | W11: 1 | X11: 1 | Z11: 1 | AA11: 1 | AB11: 1 | AE11: =SUM(G11:AD11) -> 12 | AF11: 09:00 A 18:00 - 19:00 A 22:00 | AG11: DOMINGO 28 DE DICIEMBRE
A12: UNIFICADA | B12: NTGOAQUO | D12: 4 | E12: AQUINO ORELLANA OTILDA FRANCISCA | F12: =SUM(G12:AD12) -> 0 | G12: 0 | H12: 0 | I12: 0 | J12: 0 | K12: 0 | L12: 0 | M12: 0 | N12: 0 | O12: 0 | P12: 0 | Q12: 0 | R12: 0 | S12: 0 | T12: 0 | U12: 0 | V12: 0 | W12: 0 | X12: 0 | Y12: 0 | Z12: 0 | AA12: 0 | AB12: 0 | AC12: 0 | AD12: 0 | AE12: =SUM(G12:AD12) -> 0 | AF12: LIBRE | AG12: DOMINGO 28 DE DICIEMBRE
A13: UNIFICADA | B13: NTGAARIF | C13: 998223732 | D13: 5 | E13: ARIAS FARINANGO ARIEL FERNANDO | F13: =SUM(G13:AD13) -> 8 | Q13: 1 | R13: 1 | S13: 1 | T13: 1 | U13: 1 | V13: 1 | W13: 1 | X13: 1 | AE13: =SUM(G13:AD13) -> 8 | AF13: 10:00 A 18:00 | AG13: DOMINGO 28 DE DICIEMBRE
A14: UNIFICADA | B14: NTGIARIN | D14: 6 | E14: ARIAS NARVAEZ ISIS ESCARLETH | F14: =SUM(G14:AD14) -> 11 | O14: 1 | P14: 1 | Q14: 1 | R14: 1 | S14: 1 | T14: 1 | U14: 1 | V14: 1 | X14: 1 | Y14: 1 | Z14: 1 | AE14: =SUM(G14:AD14) -> 11 | AF14: 08:00 A 16:00 - 17:00 A 20:00 | AG14: DOMINGO 28 DE DICIEMBRE
A15: UNIFICADA | B15: NTGJBELL | C15: 979044107 | D15: 7 | E15: BELTRAN VILLALBA JENNIFER MIGREY | F15: =SUM(G15:AD15) -> 10 | M15: 1 | N15: 1 | O15: 1 | P15: 1 | Q15: 1 | R15: 1 | S15: 1 | T15: 1 | U15: 1 | V15: 1 | AE15: =SUM(G15:AD15) -> 10 | AF15: 06:00 A 16:00 | AG15: DOMINGO 28 DE DICIEMBRE
A16: UNIFICADA | B16: NTGJBEND_1 | C16: 995545886 | D16: 8 | E16: BENALCAZAR DUARTE JEANNETH GISSELA | F16: =SUM(G16:AD16) -> 0 | G16: 0 | H16: 0 | I16: 0 | J16: 0 | K16: 0 | L16: 0 | M16: 0 | N16: 0 | O16: 0 | P16: 0 | Q16: 0 | R16: 0 | S16: 0 | T16: 0 | U16: 0 | V16: 0 | W16: 0 | X16: 0 | Y16: 0 | Z16: 0 | AA16: 0 | AB16: 0 | AC16: 0 | AD16: 0 | AE16: =SUM(G16:AD16) -> 0 | AF16: LIBRE | AG16: DOMINGO 28 DE DICIEMBRE
A17: UNIFICADA | B17: NTGJBERO | C17: 968594141 | D17: 9 | E17: BERMEJO MALDONADO JONATHAN MAURICIO | F17: =SUM(G17:AD17) -> 12 | P17: 1 | Q17: 1 | R17: 1 | S17: 1 | T17: 1 | U17: 1 | V17: 1 | W17: 1 | X17: 1 | Y17: 1 | Z17: 1 | AA17: 1 | AE17: =SUM(G17:AD17) -> 12 | AF17: 09:00 A 21:00 | AG17: DOMINGO 28 DE DICIEMBRE
A18: UNIFICADA | B18: NTGMCABU | D18: 10 | E18: CABASCANGO BUSE MARITZA ELIZABETH | F18: =SUM(G18:AD18) -> 11 | M18: 1 | N18: 1 | O18: 1 | P18: 1 | Q18: 1 | R18: 1 | S18: 1 | T18: 1 | U18: 1 | V18: 1 | W18: 1 | AE18: =SUM(G18:AD18) -> 11 | AF18: 06:00 A 17:00 | AG18: DOMINGO 28 DE DICIEMBRE
A19: UNIFICADA | B19: NTGMCAR9 | C19: 989533877 | D19: 11 | E19: CARVAJAL RENGEL MARIA BELEN | F19: =SUM(G19:AD19) -> 0 | G19: V | H19: V | I19: V | J19: V | K19: V | L19: V | M19: V | N19: V | O19: V | P19: V | Q19: V | R19: V | S19: V | T19: V | U19: V | V19: V | W19: V | X19: V | Y19: V | Z19: V | AA19: V | AB19: V | AC19: V | AD19: V | AE19: =SUM(G19:AD19) -> 0 | AF19: VACACIONES | AG19: DOMINGO 28 DE DICIEMBRE
A20: UNIFICADA | B20: NTGTCHII | C20: 997829699 | D20: 12 | E20: CHINGA PITIUR TATIANA LIZBETH | F20: =SUM(G20:AD20) -> 12 | O20: 1 | P20: 1 | Q20: 1 | R20: 1 | S20: 1 | T20: 1 | U20: 1 | V20: 1 | W20: 1 | Y20: 1 | Z20: 1 | AA20: 1 | AE20: =SUM(G20:AD20) -> 12 | AF20: 08:00 A 17:00 - 18:00 A 21:00 | AG20: DOMINGO 28 DE DICIEMBRE
A21: UNIFICADA | B21: NTGCCOLT | D21: 13 | E21: COLCHA TOAPANTA CINTHYA VANESSA | F21: =SUM(G21:AD21) -> 0 | G21: 0 | H21: 0 | I21: 0 | J21: 0 | K21: 0 | L21: 0 | M21: 0 | N21: 0 | O21: 0 | P21: 0 | Q21: 0 | R21: 0 | S21: 0 | T21: 0 | U21: 0 | V21: 0 | W21: 0 | X21: 0 | Y21: 0 | Z21: 0 | AA21: 0 | AB21: 0 | AC21: 0 | AD21: 0 | AE21: =SUM(G21:AD21) -> 0 | AF21: LIBRE | AG21: DOMINGO 28 DE DICIEMBRE
A22: UNIFICADA | B22: NTGADELN | C22: 996303208 | D22: 14 | E22: DEL CASTILLO MANCHENO ANDRES DARIO | F22: =SUM(G22:AD22) -> 0 | G22: 0 | H22: 0 | I22: 0 | J22: 0 | K22: 0 | L22: 0 | M22: 0 | N22: 0 | O22: 0 | P22: 0 | Q22: 0 | R22: 0 | S22: 0 | T22: 0 | U22: 0 | V22: 0 | W22: 0 | X22: 0 | Y22: 0 | Z22: 0 | AA22: 0 | AB22: 0 | AC22: 0 | AD22: 0 | AE22: =SUM(G22:AD22) -> 0 | AF22: LIBRE | AG22: DOMINGO 28 DE DICIEMBRE
A23: UNIFICADA | B23: NTGYGOMR | C23: 991837641 | D23: 15 | E23: GOMEZ ROSALES YANINA BELEN | F23: =SUM(G23:AD23) -> 0 | G23: 0 | H23: 0 | I23: 0 | J23: 0 | K23: 0 | L23: 0 | M23: 0 | N23: 0 | O23: 0 | P23: 0 | Q23: 0 | R23: 0 | S23: 0 | T23: 0 | U23: 0 | V23: 0 | W23: 0 | X23: 0 | Y23: 0 | Z23: 0 | AA23: 0 | AB23: 0 | AC23: 0 | AD23: 0 | AE23: =SUM(G23:AD23) -> 0 | AF23: LIBRE | AG23: DOMINGO 28 DE DICIEMBRE
A24: UNIFICADA | B24: NTGCGUAH | C24: 985570860 | D24: 16 | E24: GUANOLUISA REMACHE CHRISTIAN ALEXANDER | F24: =SUM(G24:AD24) -> 11 | N24: 1 | O24: 1 | P24: 1 | Q24: 1 | R24: 1 | S24: 1 | T24: 1 | U24: 1 | W24: 1 | X24: 1 | Y24: 1 | AE24: =SUM(G24:AD24) -> 11 | AF24: 07:00 A 15:00 - 16:00 A 19:00 | AG24: DOMINGO 28 DE DICIEMBRE
A25: UNIFICADA | B25: NTGLJACC | C25: 961816449 | D25: 17 | E25: JACOME CAMACHO LUIS HUMBERTO | F25: =SUM(G25:AD25) -> 10 | M25: 1 | N25: 1 | O25: 1 | P25: 1 | Q25: 1 | R25: 1 | S25: 1 | T25: 1 | V25: 1 | W25: 1 | AE25: =SUM(G25:AD25) -> 10 | AF25: 06:00 A 14:00 - 15:00 A 17:00 | AG25: DOMINGO 28 DE DICIEMBRE
A26: UNIFICADA | B26: NTGMJIM0 | C26: 989858490 | D26: 18 | E26: JIMENEZ SILVA MIRIAN PAMELA | F26: =SUM(G26:AD26) -> 14 | M26: 1 | N26: 1 | O26: 1 | P26: 1 | Q26: 1 | R26: 1 | S26: 1 | T26: 1 | U26: 1 | W26: 1 | X26: 1 | Y26: 1 | Z26: 1 | AA26: 1 | AE26: =SUM(G26:AD26) -> 14 | AF26: 06:00 A 15:00 - 16:00 A 19:00 | AG26: DOMINGO 28 DE DICIEMBRE
A27: UNIFICADA | B27: NTGELECS | C27: 988957267 | D27: 19 | E27: LECHON SANDOVAL ERICK FERNANDO | F27: =SUM(G27:AD27) -> 0 | G27: 0 | H27: 0 | I27: 0 | J27: 0 | K27: 0 | L27: 0 | M27: 0 | N27: 0 | O27: 0 | P27: 0 | Q27: 0 | R27: 0 | S27: 0 | T27: 0 | U27: 0 | V27: 0 | W27: 0 | X27: 0 | Y27: 0 | Z27: 0 | AA27: 0 | AB27: 0 | AC27: 0 | AD27: 0 | AE27: =SUM(G27:AD27) -> 0 | AF27: LIBRE | AG27: DOMINGO 28 DE DICIEMBRE
A28: UNIFICADA | B28: NTGJMEN13 | D28: 20 | E28: MENDOZA PALACIOS JHON HENRY | F28: =SUM(G28:AD28) -> 12 | M28: 1 | N28: 1 | O28: 1 | P28: 1 | Q28: 1 | R28: 1 | S28: 1 | T28: 1 | U28: 1 | W28: 1 | X28: 1 | Y28: 1 | AE28: =SUM(G28:AD28) -> 12 | AF28: 06:00 A 15:00 - 16:00 A 19:00 | AG28: DOMINGO 28 DE DICIEMBRE
A29: UNIFICADA | B29: NTGJMOR53 | D29: 21 | E29: MORALES MARTINEZ JOSUE JAVIER | F29: =SUM(G29:AD29) -> 16 | G29: 1 | H29: 1 | I29: 1 | J29: 1 | K29: 1 | L29: 1 | Q29: 1 | R29: 1 | S29: 1 | T29: 1 | U29: 1 | W29: 1 | X29: 1 | Y29: 1 | Z29: 1 | AA29: 1 | AE29: =SUM(G29:AD29) -> 16 | AF29: 00:00 A 06:00 -10:00 A 15:00 - 16:00 A 21:00 | AG29: DOMINGO 28 DE DICIEMBRE
A30: UNIFICADA | B30: NTGJMOR48 | C30: 962757006 | D30: 22 | E30: MORENO NORIEGA JORGE OSVALDO | F30: =SUM(G30:AD30) -> 0 | G30: 0 | H30: 0 | I30: 0 | J30: 0 | K30: 0 | L30: 0 | M30: 0 | N30: 0 | O30: 0 | P30: 0 | Q30: 0 | R30: 0 | S30: 0 | T30: 0 | U30: 0 | V30: 0 | W30: 0 | X30: 0 | Y30: 0 | Z30: 0 | AA30: 0 | AB30: 0 | AC30: 0 | AD30: 0 | AE30: =SUM(G30:AD30) -> 0 | AF30: LIBRE | AG30: DOMINGO 28 DE DICIEMBRE
A31: UNIFICADA | B31: NTGTMORC | D31: 23 | E31: MOROCHO CALDERON TANIA DENISSE | F31: =SUM(G31:AD31) -> 11 | O31: 1 | P31: 1 | Q31: 1 | R31: 1 | S31: 1 | T31: 1 | U31: 1 | V31: 1 | X31: 1 | Y31: 1 | Z31: 1 | AE31: =SUM(G31:AD31) -> 11 | AF31: 08:00 A 16:00 - 17:00 A 20:00 | AG31: DOMINGO 28 DE DICIEMBRE
A32: UNIFICADA | B32: NTGKNARM | C32: 995055956 | D32: 24 | E32: NARVAEZ MALDONADO KARLA JULIET | F32: =SUM(G32:AD32) -> 10 | R32: 1 | S32: 1 | T32: 1 | V32: 1 | W32: 1 | X32: 1 | Y32: 1 | Z32: 1 | AA32: 1 | AB32: 1 | AE32: =SUM(G32:AD32) -> 10 | AF32: 11:00 A 14:00 - 15:00 A 22:00 | AG32: DOMINGO 28 DE DICIEMBRE
A33: UNIFICADA | B33: NTGMPALR | D33: 25 | E33: PALOMO RAMIREZ MAYERLI RAQUEL | F33: =SUM(G33:AD33) -> 0 | G33: 0 | H33: 0 | I33: 0 | J33: 0 | K33: 0 | L33: 0 | M33: 0 | N33: 0 | O33: 0 | P33: 0 | Q33: 0 | R33: 0 | S33: 0 | T33: 0 | U33: 0 | V33: 0 | W33: 0 | X33: 0 | Y33: 0 | Z33: 0 | AA33: 0 | AB33: 0 | AC33: 0 | AD33: 0 | AE33: =SUM(G33:AD33) -> 0 | AF33: LIBRE | AG33: DOMINGO 28 DE DICIEMBRE
A34: UNIFICADA | B34: NTGJQUI50 | D34: 26 | E34: QUISPE PALACIOS JOSELYN YADIRA | F34: =SUM(G34:AD34) -> 6 | Q34: 1 | R34: 1 | AA34: 1 | AB34: 1 | AC34: 1 | AD34: 1 | AE34: =SUM(G34:AD34) -> 6 | AF34: 10:00 A 12:00 - 20:00 A 00:00 | AG34: DOMINGO 28 DE DICIEMBRE
A35: UNIFICADA | B35: NTGEQUI6 | C35: 990489779 | D35: 27 | E35: QUISHPE SIERRA ESTEBAN IGNACIO | F35: =SUM(G35:AD35) -> 6 | Y35: 1 | Z35: 1 | AA35: 1 | AB35: 1 | AC35: 1 | AD35: 1 | AE35: =SUM(G35:AD35) -> 6 | AF35: 18:00 A 00:00 | AG35: DOMINGO 28 DE DICIEMBRE
A36: UNIFICADA | B36: NTGRQUIV | C36: 981074073 | D36: 28 | E36: QUITIAQUEZ VELASCO RICHARD DAVID | F36: =SUM(G36:AD36) -> 10 | N36: 1 | O36: 1 | P36: 1 | Q36: 1 | R36: 1 | S36: 1 | T36: 1 | U36: 1 | V36: 1 | W36: 1 | AE36: =SUM(G36:AD36) -> 10 | AF36: 07:00 A 17:00 | AG36: DOMINGO 28 DE DICIEMBRE
A37: UNIFICADA | B37: NTGCROMA | D37: 29 | E37: ROMERO CARRION CARLOS HUMBERTO | F37: =SUM(G37:AD37) -> 10 | M37: 1 | N37: 1 | O37: 1 | P37: 1 | Q37: 1 | R37: 1 | S37: 1 | T37: 1 | V37: 1 | W37: 1 | AE37: =SUM(G37:AD37) -> 10 | AF37: 06:00 A 14:00 - 15:00 A 17:00 | AG37: DOMINGO 28 DE DICIEMBRE
A38: UNIFICADA | B38: NTGKRUBB | D38: 30 | E38: RUBIO BOADA KAREN NICOLE | F38: =SUM(G38:AD38) -> 0 | G38: 0 | H38: 0 | I38: 0 | J38: 0 | K38: 0 | L38: 0 | M38: 0 | N38: 0 | O38: 0 | P38: 0 | Q38: 0 | R38: 0 | S38: 0 | T38: 0 | U38: 0 | V38: 0 | W38: 0 | X38: 0 | Y38: 0 | Z38: 0 | AA38: 0 | AB38: 0 | AC38: 0 | AD38: 0 | AE38: =SUM(G38:AD38) -> 0 | AF38: LIBRE | AG38: DOMINGO 28 DE DICIEMBRE
A39: UNIFICADA | B39: NTGASAMU | C39: 962936744 | D39: 31 | E39: SAMPEDRO BUÑAY ANA MARIA | F39: =SUM(G39:AD39) -> 11 | G39: 1 | H39: 1 | I39: 1 | J39: 1 | K39: 1 | L39: 1 | M39: 1 | AA39: 1 | AB39: 1 | AC39: 1 | AD39: 1 | AE39: =SUM(G39:AD39) -> 11 | AF39: 00:00 A 07:00 - 20:00 A 00:00 | AG39: DOMINGO 28 DE DICIEMBRE
A40: UNIFICADA | B40: NTGDTUAA | D40: 32 | E40: TUAPANTA CHANATAXI DANILO JAVIER | F40: =SUM(G40:AD40) -> 11 | O40: 1 | P40: 1 | Q40: 1 | R40: 1 | S40: 1 | T40: 1 | U40: 1 | V40: 1 | W40: 1 | Y40: 1 | Z40: 1 | AE40: =SUM(G40:AD40) -> 11 | AF40: 08:00 A 17:00 - 18:00 A 20:00 | AG40: DOMINGO 28 DE DICIEMBRE
...

Sheet 29
A1: Nomenclatura
A2: ATRASO | B2: REPOSO
A3: FALTA | B3: PAGO POR SOPORTE O ADICIONAL | D3: LUNES
A4: VACACIONES | B4: CAPACITACIÓN | E4: DIMENSIONAMIENTO | G4: 4 | H4: 3 | I4: 3 | J4: 3 | K4: 3 | L4: 3 | M4: 10 | N4: 20 | O4: 27 | P4: 29 | Q4: 30 | R4: 30 | S4: 30 | T4: 20 | U4: 23 | V4: 28 | W4: 28 | X4: 33 | Y4: 26 | Z4: 18 | AA4: 11 | AB4: 8 | AC4: 6 | AD4: 4 | AE4: =SUM(G4:AD4) -> 400 | AF4: =AE4/9 -> 44.444444
E5: 29 | G5: 00:00 - 01:00 | H5: 01:00 - 02:00 | I5: 02:00 - 03:00 | J5: 03:00 - 04:00 | K5: 04:00 - 05:00 | L5: 05:00 - 06:00 | M5: 06:00 - 07:00 | N5: 07:00 - 08:00 | O5: 08:00 - 09:00 | P5: 09:00 - 10:00 | Q5: 10:00 - 11:00 | R5: 11:00 - 12:00 | S5: 12:00 - 13:00 | T5: 13:00 - 14:00 | U5: 14:00 - 15:00 | V5: 15:00 - 16:00 | W5: 16:00 - 17:00 | X5: 17:00 - 18:00 | Y5: 18:00 - 19:00 | Z5: 19:00 - 20:00 | AA5: 20:00 - 21:00 | AB5: 21:00 - 22:00 | AC5: 22:00 - 23:00 | AD5: 23:00 - 00:00
G6: =G7-G4 -> -1 | H6: =H7-H4 -> 0 | I6: =I7-I4 -> 0 | J6: =J7-J4 -> 0 | K6: =K7-K4 -> 0 | L6: =L7-L4 -> 0 | M6: =M7-M4 -> 0 | N6: =N7-N4 -> 0 | ... AD6: =AD7-AD4 -> 1 | AE6: =SUM(G6:AD6) -> -2
A7: GESTIÓN | B7: USUARIO | C7: CONTACTO | D7: N° | E7: ASESORES | F7: HT | G7: =SUM(G8:G54) -> 3 | H7: =SUM(H8:H54) -> 3 | I7: =SUM(I8:I54) -> 3 | J7: =SUM(J8:J54) -> 3 | K7: =SUM(K8:K54) -> 3 | L7: =SUM(L8:L54) -> 3 | M7: =SUM(M8:M54) -> 10 | N7: =SUM(N8:N54) -> 20 | ... AD7: =SUM(AD8:AD54) -> 5 | AE7: =SUM(G7:AD7) -> 398 | AF7: HORARIO ASISTENCIA | AG7: FECHA
A8: UNIFICADA | B8: NTGLQUIS | D8: 0 | E8: QUISHPE SIERRA JOSE LUIS | F8: =SUM(G8:AD8) -> 4 | Y8: 1 | Z8: 1 | AA8: 1 | AB8: 1 | AE8: =SUM(G8:AD8) -> 4 | AF8: 18:00 A 22:00 | AG8: LUNES 29 DE DICIEMBRE
A9: UNIFICADA | B9: NTGBACUC | C9: 999600729 | D9: 1 | E9: ACUÑA CAISAGUANO BYRON DANILO | F9: =SUM(G9:AD9) -> 12 | Q9: 1 | R9: 1 | S9: 1 | U9: 1 | V9: 1 | W9: 1 | X9: 1 | Y9: 1 | Z9: 1 | AA9: 1 | AB9: 1 | AC9: 1 | AE9: =SUM(G9:AD9) -> 12 | AF9: 10:00 A 13:00 - 14:00 A 23:00 | AG9: LUNES 29 DE DICIEMBRE
A10: UNIFICADA | B10: NTGBALED | C10: 984098910 | D10: 2 | E10: ALENCASTRO DELGADO BRIGITTE SCARLET | F10: =SUM(G10:AD10) -> 13 | G10: 1 | H10: 1 | I10: 1 | J10: 1 | K10: 1 | L10: 1 | M10: 1 | Y10: 1 | Z10: 1 | AA10: 1 | AB10: 1 | AC10: 1 | AD10: 1 | AE10: =SUM(G10:AD10) -> 13 | AF10: 00:00 A 06:00 - 18:00 A 00:00 | AG10: LUNES 29 DE DICIEMBRE
A11: UNIFICADA | B11: NTGBALEE | C11: 987983128 | D11: 3 | E11: ALENCASTRO DELGADO BRITANY SAMANTA | F11: =SUM(G11:AD11) -> 11 | O11: 1 | P11: 1 | Q11: 1 | R11: 1 | S11: 1 | T11: 1 | V11: 1 | W11: 1 | X11: 1 | Y11: 1 | Z11: 1 | AE11: =SUM(G11:AD11) -> 11 | AF11: 08:00 A 14:00 - 15:00 A 20:00 | AG11: LUNES 29 DE DICIEMBRE
A12: UNIFICADA | B12: NTGOAQUO | D12: 4 | E12: AQUINO ORELLANA OTILDA FRANCISCA | F12: =SUM(G12:AD12) -> 12 | N12: 1 | O12: 1 | P12: 1 | Q12: 1 | R12: 1 | S12: 1 | T12: 1 | U12: 1 | V12: 1 | W12: 1 | X12: 1 | Y12: 1 | AE12: =SUM(G12:AD12) -> 12 | AF12: 07:00 A 19:00 | AG12: LUNES 29 DE DICIEMBRE
A13: UNIFICADA | B13: NTGAARIF | C13: 998223732 | D13: 5 | E13: ARIAS FARINANGO ARIEL FERNANDO | F13: =SUM(G13:AD13) -> 10 | M13: 1 | N13: 1 | O13: 1 | P13: 1 | Q13: 1 | R13: 1 | S13: C | U13: 1 | V13: 1 | W13: 1 | X13: 1 | AE13: =SUM(G13:AD13) -> 10 | AF13: 06:00 A 13:00 - 14:00 A 18:00 | AG13: LUNES 29 DE DICIEMBRE
A14: UNIFICADA | B14: NTGIARIN | D14: 6 | E14: ARIAS NARVAEZ ISIS ESCARLETH | F14: =SUM(G14:AD14) -> 11 | M14: 1 | N14: 1 | O14: 1 | P14: 1 | Q14: 1 | R14: 1 | S14: C | T14: 1 | U14: 1 | V14: 1 | W14: 1 | X14: 1 | AE14: =SUM(G14:AD14) -> 11 | AF14: 06:00 A 18:00 | AG14: LUNES 29 DE DICIEMBRE
A15: UNIFICADA | B15: NTGJBELL | C15: 979044107 | D15: 7 | E15: BELTRAN VILLALBA JENNIFER MIGREY | F15: =SUM(G15:AD15) -> 10 | N15: 1 | O15: 1 | P15: 1 | Q15: 1 | R15: 1 | S15: C | T15: 1 | U15: 1 | V15: 1 | W15: 1 | X15: 1 | AE15: =SUM(G15:AD15) -> 10 | AF15: 07:00 A 18:00 | AG15: LUNES 29 DE DICIEMBRE
A16: UNIFICADA | B16: NTGJBEND_1 | C16: 995545886 | D16: 8 | E16: BENALCAZAR DUARTE JEANNETH GISSELA | F16: =SUM(G16:AD16) -> 11 | O16: 1 | P16: 1 | Q16: 1 | R16: 1 | S16: 1 | T16: 1 | U16: 1 | V16: C | W16: 1 | X16: 1 | Y16: 1 | Z16: 1 | AE16: =SUM(G16:AD16) -> 11 | AF16: 08:00 A 20:00 | AG16: LUNES 29 DE DICIEMBRE
A17: UNIFICADA | B17: NTGJBERO | C17: 968594141 | D17: 9 | E17: BERMEJO MALDONADO JONATHAN MAURICIO | F17: =SUM(G17:AD17) -> 11 | N17: 1 | O17: 1 | P17: 1 | Q17: 1 | R17: 1 | S17: 1 | T17: 1 | U17: 1 | V17: C | W17: 1 | X17: 1 | Y17: 1 | AE17: =SUM(G17:AD17) -> 11 | AF17: 07:00 A 19:00 | AG17: LUNES 29 DE DICIEMBRE
A18: UNIFICADA | B18: NTGMCABU | D18: 10 | E18: CABASCANGO BUSE MARITZA ELIZABETH | F18: =SUM(G18:AD18) -> 10 | N18: 1 | O18: 1 | P18: 1 | Q18: 1 | R18: 1 | S18: C | T18: 1 | U18: 1 | V18: 1 | W18: 1 | X18: 1 | AE18: =SUM(G18:AD18) -> 10 | AF18: 07:00 A 18:00 | AG18: LUNES 29 DE DICIEMBRE
A19: UNIFICADA | B19: NTGMCAR9 | C19: 989533877 | D19: 11 | E19: CARVAJAL RENGEL MARIA BELEN | F19: =SUM(G19:AD19) -> 0 | G19: V | H19: V | I19: V | J19: V | K19: V | L19: V | M19: V | N19: V | O19: V | P19: V | Q19: V | R19: V | S19: V | T19: V | U19: V | V19: V | W19: V | X19: V | Y19: V | Z19: V | AA19: V | AB19: V | AC19: V | AD19: V | AE19: =SUM(G19:AD19) -> 0 | AF19: VACACIONES | AG19: LUNES 29 DE DICIEMBRE
A20: UNIFICADA | B20: NTGTCHII | C20: 997829699 | D20: 12 | E20: CHINGA PITIUR TATIANA LIZBETH | F20: =SUM(G20:AD20) -> 10 | N20: 1 | O20: 1 | P20: 1 | Q20: 1 | R20: 1 | S20: 1 | U20: 1 | V20: 1 | W20: 1 | X20: 1 | AE20: =SUM(G20:AD20) -> 10 | AF20: 07:00 A 13:00 - 14:00 A 18:00 | AG20: LUNES 29 DE DICIEMBRE
A21: UNIFICADA | B21: NTGCCOLT | D21: 13 | E21: COLCHA TOAPANTA CINTHYA VANESSA | F21: =SUM(G21:AD21) -> 10 | U21: 1 | V21: 1 | W21: 1 | X21: 1 | Y21: 1 | Z21: 1 | AA21: 1 | AB21: 1 | AC21: 1 | AD21: 1 | AE21: =SUM(G21:AD21) -> 10 | AF21: 14:00 A 00:00 | AG21: LUNES 29 DE DICIEMBRE
A22: UNIFICADA | B22: NTGADELN | C22: 996303208 | D22: 14 | E22: DEL CASTILLO MANCHENO ANDRES DARIO | F22: =SUM(G22:AD22) -> 12 | M22: 1 | N22: 1 | O22: 1 | P22: 1 | Q22: 1 | R22: 1 | S22: 1 | U22: 1 | V22: 1 | W22: 1 | X22: 1 | Y22: 1 | AE22: =SUM(G22:AD22) -> 12 | AF22: 06:00 A 13:00 - 14:00 A 19:00 | AG22: LUNES 29 DE DICIEMBRE
A23: UNIFICADA | B23: NTGYGOMR | C23: 991837641 | D23: 15 | E23: GOMEZ ROSALES YANINA BELEN | F23: =SUM(G23:AD23) -> 6 | N23: 1 | O23: 1 | P23: 1 | Q23: 1 | R23: 1 | S23: C | T23: 1 | AE23: =SUM(G23:AD23) -> 6 | AF23: 07:00 A 14:00 | AG23: LUNES 29 DE DICIEMBRE
A24: UNIFICADA | B24: NTGCGUAH | C24: 985570860 | D24: 16 | E24: GUANOLUISA REMACHE CHRISTIAN ALEXANDER | F24: =SUM(G24:AD24) -> 11 | O24: 1 | P24: 1 | Q24: 1 | R24: 1 | S24: 1 | T24: 1 | U24: 1 | V24: 1 | X24: 1 | Y24: 1 | Z24: 1 | AE24: =SUM(G24:AD24) -> 11 | AF24: 08:00 A 16:00 - 17:00 A 20:00 | AG24: LUNES 29 DE DICIEMBRE
A25: UNIFICADA | B25: NTGLJACC | C25: 961816449 | D25: 17 | E25: JACOME CAMACHO LUIS HUMBERTO | F25: =SUM(G25:AD25) -> 11 | M25: 1 | N25: 1 | O25: 1 | P25: 1 | Q25: 1 | R25: 1 | S25: 1 | U25: 1 | V25: 1 | W25: 1 | X25: 1 | AE25: =SUM(G25:AD25) -> 11 | AF25: 06:00 A 13:00 - 14:00 A 18:00 | AG25: LUNES 29 DE DICIEMBRE
A26: UNIFICADA | B26: NTGMJIM0 | C26: 989858490 | D26: 18 | E26: JIMENEZ SILVA MIRIAN PAMELA | F26: =SUM(G26:AD26) -> 12 | M26: 1 | N26: 1 | O26: 1 | P26: 1 | Q26: 1 | R26: 1 | S26: 1 | U26: 1 | V26: 1 | W26: 1 | X26: 1 | Y26: 1 | AE26: =SUM(G26:AD26) -> 12 | AF26: 06:00 A 13:00 - 14:00 A 19:00 | AG26: LUNES 29 DE DICIEMBRE
A27: UNIFICADA | B27: NTGELECS | C27: 988957267 | D27: 19 | E27: LECHON SANDOVAL ERICK FERNANDO | F27: =SUM(G27:AD27) -> 12 | O27: 1 | P27: 1 | Q27: 1 | R27: 1 | S27: 1 | U27: 1 | V27: 1 | W27: 1 | X27: 1 | Y27: 1 | Z27: 1 | AA27: 1 | AE27: =SUM(G27:AD27) -> 12 | AF27: 07:00 A 16:00 - 17:00 A 20:00 | AG27: LUNES 29 DE DICIEMBRE
A28: UNIFICADA | B28: NTGJMEN13 | D28: 20 | E28: MENDOZA PALACIOS JHON HENRY | F28: =SUM(G28:AD28) -> 11 | O28: 1 | P28: 1 | Q28: 1 | R28: 1 | S28: 1 | T28: 1 | U28: C | V28: 1 | W28: 1 | X28: 1 | Y28: 1 | Z28: 1 | AE28: =SUM(G28:AD28) -> 11 | AF28: 08:00 A 20:00 | AG28: LUNES 29 DE DICIEMBRE
A29: UNIFICADA | B29: NTGJMOR53 | D29: 21 | E29: MORALES MARTINEZ JOSUE JAVIER | F29: =SUM(G29:AD29) -> 7 | U29: C | V29: 1 | W29: 1 | X29: 1 | Y29: 1 | Z29: 1 | AA29: 1 | AB29: 1 | AE29: =SUM(G29:AD29) -> 7 | AF29: 14:00 A 22:00 | AG29: LUNES 29 DE DICIEMBRE
A30: UNIFICADA | B30: NTGJMOR48 | C30: 962757006 | D30: 22 | E30: MORENO NORIEGA JORGE OSVALDO | F30: =SUM(G30:AD30) -> 11 | O30: 1 | P30: 1 | Q30: 1 | R30: 1 | S30: 1 | U30: 1 | V30: 1 | W30: C | X30: 1 | Y30: 1 | Z30: 1 | AA30: 1 | AE30: =SUM(G30:AD30) -> 11 | AF30: 08:00 A 13:00 - 14:00 A 21:00 | AG30: LUNES 29 DE DICIEMBRE
A31: UNIFICADA | B31: NTGTMORC | D31: 23 | E31: MOROCHO CALDERON TANIA DENISSE | F31: =SUM(G31:AD31) -> 11 | O31: 1 | P31: 1 | Q31: 1 | R31: 1 | S31: 1 | T31: 1 | U31: 1 | V31: C | W31: 1 | X31: 1 | Y31: 1 | Z31: 1 | AE31: =SUM(G31:AD31) -> 11 | AF31: 08:00 A 20:00 | AG31: LUNES 29 DE DICIEMBRE
A32: UNIFICADA | B32: NTGKNARM | C32: 995055956 | D32: 24 | E32: NARVAEZ MALDONADO KARLA JULIET | F32: =SUM(G32:AD32) -> 11 | M32: 1 | N32: 1 | O32: 1 | P32: 1 | Q32: 1 | R32: 1 | S32: 1 | U32: 1 | V32: 1 | W32: 1 | X32: 1 | AE32: =SUM(G32:AD32) -> 11 | AF32: 06:00 A 13:00 - 14:00 A 18:00 | AG32: LUNES 29 DE DICIEMBRE
A33: UNIFICADA | B33: NTGMPALR | D33: 25 | E33: PALOMO RAMIREZ MAYERLI RAQUEL | F33: =SUM(G33:AD33) -> 6 | N33: 1 | O33: 1 | P33: 1 | Q33: 1 | R33: 1 | S33: 1 | AE33: =SUM(G33:AD33) -> 6 | AF33: 07:00 A 13:00 | AG33: LUNES 29 DE DICIEMBRE
A34: UNIFICADA | B34: NTGEQUI6 | C34: 990489779 | D34: 27 | E34: QUISHPE SIERRA ESTEBAN IGNACIO | F34: =SUM(G34:AD34) -> 12 | N34: 1 | O34: 1 | P34: 1 | Q34: 1 | R34: 1 | S34: 1 | T34: 1 | U34: 1 | V34: 1 | X34: 1 | Y34: 1 | Z34: 1 | AE34: =SUM(G34:AD34) -> 12 | AF34: 07:00 A 16:00 - 17:00 A 20:00 | AG34: LUNES 29 DE DICIEMBRE
A35: UNIFICADA | B35: NTGJQUI50 | D35: 26 | E35: QUISPE PALACIOS JOSELYN YADIRA | F35: =SUM(G35:AD35) -> 12 | G35: 1 | H35: 1 | I35: 1 | J35: 1 | K35: 1 | L35: 1 | M35: 1 | Z35: 1 | AA35: 1 | AB35: 1 | AC35: 1 | AD35: 1 | AE35: =SUM(G35:AD35) -> 12 | AF35: 00:00 A 06:00 - 19:00 A 00:00 | AG35: LUNES 29 DE DICIEMBRE
A36: UNIFICADA | B36: NTGRQUIV | C36: 981074073 | D36: 28 | E36: QUITIAQUEZ VELASCO RICHARD DAVID | F36: =SUM(G36:AD36) -> 11 | N36: 1 | O36: 1 | P36: 1 | Q36: 1 | R36: 1 | S36: 1 | U36: C | V36: 1 | W36: 1 | X36: 1 | Y36: 1 | Z36: 1 | AE36: =SUM(G36:AD36) -> 11 | AF36: 07:00 A 13:00 - 14:00 A 20:00 | AG36: LUNES 29 DE DICIEMBRE
A37: UNIFICADA | B37: NTGCROMA | D37: 29 | E37: ROMERO CARRION CARLOS HUMBERTO | F37: =SUM(G37:AD37) -> 11 | N37: 1 | O37: 1 | P37: 1 | Q37: 1 | R37: 1 | S37: 1 | U37: 1 | V37: 1 | W37: 1 | X37: 1 | Y37: 1 | AE37: =SUM(G37:AD37) -> 11 | AF37: 07:00 A 13:00 - 14:00 A 19:00 | AG37: LUNES 29 DE DICIEMBRE
A38: UNIFICADA | B38: NTGKRUBB | D38: 30 | E38: RUBIO BOADA KAREN NICOLE | F38: =SUM(G38:AD38) -> 11 | N38: 1 | O38: 1 | P38: 1 | Q38: 1 | R38: 1 | S38: 1 | U38: C | V38: 1 | W38: 1 | X38: 1 | Y38: 1 | Z38: 1 | AE38: =SUM(G38:AD38) -> 11 | AF38: 07:00 A 13:00 - 14:00 A 20:00 | AG38: LUNES 29 DE DICIEMBRE
A39: UNIFICADA | B39: NTGASAMU | C39: 962936744 | D39: 31 | E39: SAMPEDRO BUÑAY ANA MARIA | F39: =SUM(G39:AD39) -> 13 | G39: 1 | H39: 1 | I39: 1 | J39: 1 | K39: 1 | L39: 1 | M39: 1 | Y39: 1 | Z39: 1 | AA39: 1 | AB39: 1 | AC39: 1 | AD39: 1 | AE39: =SUM(G39:AD39) -> 13 | AF39: 00:00 A 06:00 - 18:00 A 00:00 | AG39: LUNES 29 DE DICIEMBRE
A40: UNIFICADA | B40: NTGDTUAA | D40: 32 | E40: TUAPANTA CHANATAXI DANILO JAVIER | F40: =SUM(G40:AD40) -> 11 | M40: 1 | N40: 1 | O40: 1 | P40: 1 | Q40: 1 | R40: 1 | S40: C | U40: 1 | V40: 1 | W40: 1 | X40: 1 | Y40: 1 | AE40: =SUM(G40:AD40) -> 11 | AF40: 06:00 A 13:00 - 14:00 A 19:00 | AG40: LUNES 29 DE DICIEMBRE
...

Sheet 30
A1: Nomenclatura
A2: ATRASO | B2: REPOSO
A3: FALTA | B3: PAGO POR SOPORTE O ADICIONAL | D3: MARTES
A4: VACACIONES | B4: CAPACITACIÓN | E4: DIMENSIONAMIENTO | G4: 4 | H4: 3 | I4: 3 | J4: 3 | K4: 3 | L4: 3 | M4: 10 | N4: 20 | O4: 27 | P4: 29 | Q4: 30 | R4: 30 | S4: 30 | T4: 20 | U4: 23 | V4: 28 | W4: 28 | X4: 33 | Y4: 26 | Z4: 18 | AA4: 11 | AB4: 8 | AC4: 6 | AD4: 4 | AE4: =SUM(G4:AD4) -> 400 | AF4: =AE4/9 -> 44.444444
E5: 30 | G5: 00:00 - 01:00 | H5: 01:00 - 02:00 | I5: 02:00 - 03:00 | J5: 03:00 - 04:00 | K5: 04:00 - 05:00 | L5: 05:00 - 06:00 | M5: 06:00 - 07:00 | N5: 07:00 - 08:00 | O5: 08:00 - 09:00 | P5: 09:00 - 10:00 | Q5: 10:00 - 11:00 | R5: 11:00 - 12:00 | S5: 12:00 - 13:00 | T5: 13:00 - 14:00 | U5: 14:00 - 15:00 | V5: 15:00 - 16:00 | W5: 16:00 - 17:00 | X5: 17:00 - 18:00 | Y5: 18:00 - 19:00 | Z5: 19:00 - 20:00 | AA5: 20:00 - 21:00 | AB5: 21:00 - 22:00 | AC5: 22:00 - 23:00 | AD5: 23:00 - 00:00
G6: =G7-G4 -> 0 | H6: =H7-H4 -> 0 | I6: =I7-I4 -> 0 | J6: =J7-J4 -> 0 | K6: =K7-K4 -> 0 | L6: =L7-L4 -> 0 | M6: =M7-M4 -> 0 | N6: =N7-N4 -> -1 | ... AD6: =AD7-AD4 -> 0 | AE6: =SUM(G6:AD6) -> -7
A7: GESTIÓN | B7: USUARIO | C7: CONTACTO | D7: N° | E7: ASESORES | F7: HT | G7: =SUM(G8:G54) -> 4 | H7: =SUM(H8:H54) -> 3 | I7: =SUM(I8:I54) -> 3 | J7: =SUM(J8:J54) -> 3 | K7: =SUM(K8:K54) -> 3 | L7: =SUM(L8:L54) -> 3 | M7: =SUM(M8:M54) -> 10 | N7: =SUM(N8:N54) -> 19 | ... AD7: =SUM(AD8:AD54) -> 4 | AE7: =SUM(G7:AD7) -> 393 | AF7: HORARIO ASISTENCIA | AG7: FECHA
A8: UNIFICADA | B8: NTGLQUIS | D8: 0 | E8: QUISHPE SIERRA JOSE LUIS | F8: =SUM(G8:AD8) -> 4 | Y8: 1 | Z8: 1 | AA8: 1 | AB8: 1 | AE8: =SUM(G8:AD8) -> 4 | AF8: 18:00 A 22:00 | AG8: MARTES 30 DE DICIEMBRE
A9: UNIFICADA | B9: NTGBACUC | C9: 999600729 | D9: 1 | E9: ACUÑA CAISAGUANO BYRON DANILO | F9: =SUM(G9:AD9) -> 12 | O9: 1 | P9: 1 | Q9: 1 | R9: 1 | S9: 1 | U9: 1 | V9: 1 | W9: 1 | X9: 1 | Y9: 1 | Z9: 1 | AA9: 1 | AE9: =SUM(G9:AD9) -> 12 | AF9: 08:00 A 13:00 - 14:00 A 21:00 | AG9: MARTES 30 DE DICIEMBRE
A10: UNIFICADA | B10: NTGBALED | C10: 984098910 | D10: 2 | E10: ALENCASTRO DELGADO BRIGITTE SCARLET | F10: =SUM(G10:AD10) -> 12 | G10: 1 | H10: 1 | I10: 1 | J10: 1 | K10: 1 | L10: 1 | Y10: 1 | Z10: 1 | AA10: 1 | AB10: 1 | AC10: 1 | AD10: 1 | AE10: =SUM(G10:AD10) -> 12 | AF10: 00:00 A 06:00 - 18:00 A 00:00 | AG10: MARTES 30 DE DICIEMBRE
A11: UNIFICADA | B11: NTGBALEE | C11: 987983128 | D11: 3 | E11: ALENCASTRO DELGADO BRITANY SAMANTA | F11: =SUM(G11:AD11) -> 11 | N11: 1 | O11: 1 | P11: 1 | Q11: 1 | R11: 1 | S11: 1 | U11: 1 | V11: 1 | W11: 1 | X11: 1 | Y11: 1 | AE11: =SUM(G11:AD11) -> 11 | AF11: 07:00 A 13:00 - 14:00 A 19:00 | AG11: MARTES 30 DE DICIEMBRE
A12: UNIFICADA | B12: NTGOAQUO | D12: 4 | E12: AQUINO ORELLANA OTILDA FRANCISCA | F12: =SUM(G12:AD12) -> 11 | N12: 1 | O12: 1 | P12: 1 | Q12: 1 | R12: 1 | S12: 1 | T12: 1 | V12: 1 | W12: 1 | X12: 1 | Y12: 1 | AE12: =SUM(G12:AD12) -> 11 | AF12: 07:00 A 14:00 - 15:00 A 19:00 | AG12: MARTES 30 DE DICIEMBRE
A13: UNIFICADA | B13: NTGAARIF | C13: 998223732 | D13: 5 | E13: ARIAS FARINANGO ARIEL FERNANDO | F13: =SUM(G13:AD13) -> 11 | N13: 1 | O13: 1 | P13: 1 | Q13: 1 | R13: 1 | S13: 1 | U13: 1 | V13: 1 | W13: 1 | X13: 1 | Y13: 1 | AE13: =SUM(G13:AD13) -> 11 | AF13: 07:00 A 13:00 - 14:00 A 19:00 | AG13: MARTES 30 DE DICIEMBRE
A14: UNIFICADA | B14: NTGIARIN | D14: 6 | E14: ARIAS NARVAEZ ISIS ESCARLETH | F14: =SUM(G14:AD14) -> 12 | M14: 1 | N14: 1 | O14: 1 | P14: 1 | Q14: 1 | R14: 1 | S14: 1 | T14: 1 | V14: 1 | W14: 1 | X14: 1 | Y14: 1 | AE14: =SUM(G14:AD14) -> 12 | AF14: 06:00 A 14:00 - 15:00 A 19:00 | AG14: MARTES 30 DE DICIEMBRE
A15: UNIFICADA | B15: NTGJBELL | C15: 979044107 | D15: 7 | E15: BELTRAN VILLALBA JENNIFER MIGREY | F15: =SUM(G15:AD15) -> 11 | M15: 1 | N15: 1 | O15: 1 | P15: 1 | R15: 1 | S15: 1 | T15: 1 | U15: 1 | V15: 1 | W15: 1 | X15: 1 | AE15: =SUM(G15:AD15) -> 11 | AF15: 06:00 A 10:00 - 11:00 A 18:00 | AG15: MARTES 30 DE DICIEMBRE
A16: UNIFICADA | B16: NTGJBEND_1 | C16: 995545886 | D16: 8 | E16: BENALCAZAR DUARTE JEANNETH GISSELA | F16: =SUM(G16:AD16) -> 11 | N16: 1 | O16: 1 | P16: 1 | Q16: 1 | R16: 1 | S16: 1 | T16: 1 | V16: 1 | W16: 1 | X16: 1 | Y16: 1 | AE16: =SUM(G16:AD16) -> 11 | AF16: 07:00 A 14:00 - 15:00 A 19:00 | AG16: MARTES 30 DE DICIEMBRE
A17: UNIFICADA | B17: NTGJBERO | C17: 968594141 | D17: 9 | E17: BERMEJO MALDONADO JONATHAN MAURICIO | F17: =SUM(G17:AD17) -> 12 | N17: 1 | O17: 1 | P17: 1 | Q17: 1 | S17: 1 | T17: 1 | U17: 1 | V17: 1 | W17: 1 | X17: 1 | Y17: 1 | Z17: 1 | AE17: =SUM(G17:AD17) -> 12 | AF17: 07:00 A 11:00 - 12:00 A 20:00 | AG17: MARTES 30 DE DICIEMBRE
A18: UNIFICADA | B18: NTGMCABU | D18: 10 | E18: CABASCANGO BUSE MARITZA ELIZABETH | F18: =SUM(G18:AD18) -> 11 | M18: 1 | N18: 1 | O18: 1 | P18: 1 | Q18: 1 | R18: 1 | S18: 1 | U18: 1 | V18: 1 | W18: 1 | X18: 1 | AE18: =SUM(G18:AD18) -> 11 | AF18: 06:00 A 13:00 - 14:00 A 18:00 | AG18: MARTES 30 DE DICIEMBRE
A19: UNIFICADA | B19: NTGMCAR9 | C19: 989533877 | D19: 11 | E19: CARVAJAL RENGEL MARIA BELEN | F19: =SUM(G19:AD19) -> 0 | G19: V | H19: V | I19: V | J19: V | K19: V | L19: V | M19: V | N19: V | O19: V | P19: V | Q19: V | R19: V | S19: V | T19: V | U19: V | V19: V | W19: V | X19: V | Y19: V | Z19: V | AA19: V | AB19: V | AC19: V | AD19: V | AE19: =SUM(G19:AD19) -> 0 | AF19: VACACIONES | AG19: MARTES 30 DE DICIEMBRE
A20: UNIFICADA | B20: NTGTCHII | C20: 997829699 | D20: 12 | E20: CHINGA PITIUR TATIANA LIZBETH | F20: =SUM(G20:AD20) -> 11 | N20: 1 | O20: 1 | P20: 1 | Q20: 1 | R20: 1 | S20: 1 | U20: 1 | V20: 1 | W20: 1 | X20: 1 | Y20: 1 | AE20: =SUM(G20:AD20) -> 11 | AF20: 07:00 A 13:00 - 14:00 A 19:00 | AG20: MARTES 30 DE DICIEMBRE
A21: UNIFICADA | B21: NTGCCOLT | D21: 13 | E21: COLCHA TOAPANTA CINTHYA VANESSA | F21: =SUM(G21:AD21) -> 12 | G21: 1 | P21: 1 | Q21: 1 | R21: 1 | S21: 1 | T21: 1 | V21: 1 | W21: 1 | X21: 1 | Y21: 1 | Z21: 1 | AA21: 1 | AE21: =SUM(G21:AD21) -> 12 | AF21: 00:00 A 01:00 - 09:00 A 14:00 - 15:00 A 21:00 | AG21: MARTES 30 DE DICIEMBRE
A22: UNIFICADA | B22: NTGADELN | C22: 996303208 | D22: 14 | E22: DEL CASTILLO MANCHENO ANDRES DARIO | F22: =SUM(G22:AD22) -> 12 | M22: 1 | N22: 1 | O22: 1 | P22: 1 | Q22: 1 | R22: 1 | S22: 1 | U22: 1 | V22: 1 | W22: 1 | X22: 1 | Y22: 1 | AE22: =SUM(G22:AD22) -> 12 | AF22: 06:00 A 13:00 - 14:00 A 19:00 | AG22: MARTES 30 DE DICIEMBRE
A23: UNIFICADA | B23: NTGYGOMR | C23: 991837641 | D23: 15 | E23: GOMEZ ROSALES YANINA BELEN | F23: =SUM(G23:AD23) -> 6 | O23: 1 | P23: 1 | Q23: 1 | R23: 1 | S23: 1 | T23: 1 | AE23: =SUM(G23:AD23) -> 6 | AF23: 08:00 A 14:00 | AG23: MARTES 30 DE DICIEMBRE
A24: UNIFICADA | B24: NTGCGUAH | C24: 985570860 | D24: 16 | E24: GUANOLUISA REMACHE CHRISTIAN ALEXANDER | F24: =SUM(G24:AD24) -> 12 | N24: 1 | O24: 1 | P24: 1 | Q24: 1 | R24: 1 | S24: 1 | U24: 1 | V24: 1 | W24: 1 | X24: 1 | Y24: 1 | Z24: 1 | AE24: =SUM(G24:AD24) -> 12 | AF24: 07:00 A 13:00 - 14:00 A 20:00 | AG24: MARTES 30 DE DICIEMBRE
A25: UNIFICADA | B25: NTGLJACC | C25: 961816449 | D25: 17 | E25: JACOME CAMACHO LUIS HUMBERTO | F25: =SUM(G25:AD25) -> 12 | M25: 1 | N25: 1 | O25: 1 | P25: 1 | Q25: 1 | R25: 1 | S25: 1 | T25: 1 | U25: 1 | V25: 1 | W25: 1 | X25: 1 | AE25: =SUM(G25:AD25) -> 12 | AF25: 06:00 A 18:00 | AG25: MARTES 30 DE DICIEMBRE
A26: UNIFICADA | B26: NTGMJIM0 | C26: 989858490 | D26: 18 | E26: JIMENEZ SILVA MIRIAN PAMELA | F26: =SUM(G26:AD26) -> 13 | M26: 1 | N26: 1 | O26: 1 | P26: 1 | Q26: 1 | R26: 1 | S26: 1 | T26: 1 | U26: 1 | V26: 1 | W26: 1 | X26: 1 | Y26: 1 | AE26: =SUM(G26:AD26) -> 13 | AF26: 06:00 A 11:00 - 12:00 A 19:00 | AG26: MARTES 30 DE DICIEMBRE
A27: UNIFICADA | B27: NTGELECS | C27: 988957267 | D27: 19 | E27: LECHON SANDOVAL ERICK FERNANDO | F27: =SUM(G27:AD27) -> 11 | O27: 1 | P27: 1 | Q27: 1 | R27: 1 | S27: 1 | T27: 1 | V27: 1 | W27: 1 | X27: 1 | Y27: 1 | Z27: 1 | AE27: =SUM(G27:AD27) -> 11 | AF27: 08:00 A 14:00 - 15:00 A 20:00 | AG27: MARTES 30 DE DICIEMBRE
A28: UNIFICADA | B28: NTGJMEN13 | D28: 20 | E28: MENDOZA PALACIOS JHON HENRY | F28: =SUM(G28:AD28) -> 11 | O28: 1 | P28: 1 | Q28: 1 | R28: 1 | S28: 1 | T28: 1 | V28: 1 | W28: 1 | X28: 1 | Y28: 1 | Z28: 1 | AE28: =SUM(G28:AD28) -> 11 | AF28: 08:00 A 14:00 - 15:00 A 20:00 | AG28: MARTES 30 DE DICIEMBRE
A29: UNIFICADA | B29: NTGJMOR53 | D29: 21 | E29: MORALES MARTINEZ JOSUE JAVIER | F29: =SUM(G29:AD29) -> 6 | W29: 1 | X29: 1 | Y29: 1 | Z29: 1 | AA29: 1 | AB29: 1 | AE29: =SUM(G29:AD29) -> 6 | AF29: 16:00 A 22:00 | AG29: MARTES 30 DE DICIEMBRE
A30: UNIFICADA | B30: NTGJMOR48 | C30: 962757006 | D30: 22 | E30: MORENO NORIEGA JORGE OSVALDO | F30: =SUM(G30:AD30) -> 11 | O30: 1 | P30: 1 | Q30: 1 | R30: 1 | S30: 1 | T30: 1 | U30: 1 | V30: 1 | X30: 1 | Y30: 1 | Z30: 1 | AE30: =SUM(G30:AD30) -> 11 | AF30: 08:00 A 16:00 - 17:00 A 20:00 | AG30: MARTES 30 DE DICIEMBRE
A31: UNIFICADA | B31: NTGTMORC | D31: 23 | E31: MOROCHO CALDERON TANIA DENISSE | F31: =SUM(G31:AD31) -> 12 | O31: 1 | P31: 1 | Q31: 1 | R31: 1 | S31: 1 | T31: 1 | U31: 1 | V31: 1 | W31: 1 | X31: 1 | Y31: 1 | Z31: 1 | AE31: =SUM(G31:AD31) -> 12 | AF31: 08:00 A 20:00 | AG31: MARTES 30 DE DICIEMBRE
A32: UNIFICADA | B32: NTGKNARM | C32: 995055956 | D32: 24 | E32: NARVAEZ MALDONADO KARLA JULIET | F32: =SUM(G32:AD32) -> 11 | O32: 1 | P32: 1 | Q32: 1 | R32: 1 | S32: 1 | U32: 1 | V32: 1 | W32: 1 | X32: 1 | Y32: 1 | Z32: 1 | AE32: =SUM(G32:AD32) -> 11 | AF32: 08:00 A 13:00 - 14:00 A 20:00 | AG32: MARTES 30 DE DICIEMBRE
A33: UNIFICADA | B33: NTGMPALR | D33: 25 | E33: PALOMO RAMIREZ MAYERLI RAQUEL | F33: =SUM(G33:AD33) -> 6 | N33: 1 | O33: 1 | P33: 1 | Q33: 1 | R33: 1 | S33: 1 | AE33: =SUM(G33:AD33) -> 6 | AF33: 07:00 A 13:00 | AG33: MARTES 30 DE DICIEMBRE
A34: UNIFICADA | B34: NTGEQUI6 | C34: 990489779 | D34: 27 | E34: QUISHPE SIERRA ESTEBAN IGNACIO | F34: =SUM(G34:AD34) -> 11 | M34: 1 | N34: 1 | O34: 1 | P34: 1 | Q34: 1 | R34: 1 | S34: 1 | U34: 1 | V34: 1 | W34: 1 | X34: 1 | AE34: =SUM(G34:AD34) -> 11 | AF34: 06:00 A 13:00 - 14:00 A 18:00 | AG34: MARTES 30 DE DICIEMBRE
A35: UNIFICADA | B35: NTGJQUI50 | D35: 26 | E35: QUISPE PALACIOS JOSELYN YADIRA | F35: =SUM(G35:AD35) -> 11 | G35: 1 | H35: 1 | I35: 1 | J35: 1 | K35: 1 | L35: 1 | Z35: 1 | AA35: 1 | AB35: 1 | AC35: 1 | AD35: 1 | AE35: =SUM(G35:AD35) -> 11 | AF35: 00:00 A 06:00 - 19:00 A 00:00 | AG35: MARTES 30 DE DICIEMBRE
A36: UNIFICADA | B36: NTGRQUIV | C36: 981074073 | D36: 28 | E36: QUITIAQUEZ VELASCO RICHARD DAVID | F36: =SUM(G36:AD36) -> 11 | M36: 1 | N36: 1 | O36: 1 | P36: 1 | Q36: 1 | R36: 1 | S36: 1 | U36: 1 | V36: 1 | W36: 1 | X36: 1 | AE36: =SUM(G36:AD36) -> 11 | AF36: 06:00 A 13:00 - 14:00 A 18:00 | AG36: MARTES 30 DE DICIEMBRE
A37: UNIFICADA | B37: NTGCROMA | D37: 29 | E37: ROMERO CARRION CARLOS HUMBERTO | F37: =SUM(G37:AD37) -> 11 | M37: 1 | N37: 1 | O37: 1 | P37: 1 | Q37: 1 | R37: 1 | S37: 1 | T37: 1 | V37: 1 | W37: 1 | X37: 1 | AE37: =SUM(G37:AD37) -> 11 | AF37: 06:00 A 14:00 - 15:00 A 18:00 | AG37: MARTES 30 DE DICIEMBRE
A38: UNIFICADA | B38: NTGKRUBB | D38: 30 | E38: RUBIO BOADA KAREN NICOLE | F38: =SUM(G38:AD38) -> 0 | N38: FI | O38: FI | P38: FI | Q38: FI | R38: FI | S38: FI | T38: FI | V38: FI | W38: FI | X38: FI | Y38: FI | AE38: =SUM(G38:AD38) -> 0 | AF38: 07:00 A 14:00 - 15:00 A 19:00 | AG38: MARTES 30 DE DICIEMBRE
A39: UNIFICADA | B39: NTGASAMU | C39: 962936744 | D39: 31 | E39: SAMPEDRO BUÑAY ANA MARIA | F39: =SUM(G39:AD39) -> 12 | G39: 1 | H39: 1 | I39: 1 | J39: 1 | K39: 1 | L39: 1 | Y39: 1 | Z39: 1 | AA39: 1 | AB39: 1 | AC39: 1 | AD39: 1 | AE39: =SUM(G39:AD39) -> 12 | AF39: 00:00 A 06:00 - 18:00 A 00:00 | AG39: MARTES 30 DE DICIEMBRE
